<?xml version="1.0" ?>
<!-- =================================================================================== -->
<!-- |    This document was autogenerated by xacro from /home/hao/Ubuntu_3/Private/simulator/ros2_ws/src/gazebo_simulator/urdf/omni_robot.urdf.xacro | -->
<!-- |    EDITING THIS FILE BY HAND IS NOT RECOMMENDED                                 | -->
<!-- =================================================================================== -->
<robot name="omni_robot">
  <material name="gray">
    <color rgba="0.8 0.8 0.8 1.0"/>
  </material>
  <material name="black">
    <color rgba="0 0 0 1.0"/>
  </material>
  <material name="white">
    <color rgba="1.0 1.0 1.0 1.0"/>
  </material>
  <material name="red">
    <color rgba="1.0 0 0 1.0"/>
  </material>
  <material name="light_red">
    <color rgba="1.0 0.5 0.5 1.0"/>
  </material>
  <material name="yellow">
    <color rgba="0 1.0 1.0 1.0"/>
  </material>
  <link name="base_link"/>
  <joint name="body_joint" type="fixed">
    <parent link="base_link"/>
    <child link="body_link"/>
    <origin rpy="0 0 0" xyz="0 0 0.05"/>
  </joint>
  <link name="body_link">
    <visual>
      <geometry>
        <box size="0.14 0.08 0.02"/>
      </geometry>
      <material name="gray"/>
    </visual>
    <collision>
      <geometry>
        <box size="0.14 0.08 0.02"/>
      </geometry>
    </collision>
    <inertial>
      <mass value="2.0"/>
      <inertia ixx="0.01" ixy="0" ixz="0" iyy="0.01" iyz="0" izz="0.01"/>
    </inertial>
  </link>
  <joint name="wheel0_attach_joint" type="fixed">
    <parent link="base_link"/>
    <child link="wheel0_attach_link"/>
    <origin rpy="0 0 1.5707963267948966" xyz="4.286263797015737e-18 0.07 0.019"/>
  </joint>
  <link name="wheel0_attach_link"/>
  <joint name="wheel0_base_joint" type="fixed">
    <parent link="wheel0_attach_link"/>
    <child link="wheel0_base_link"/>
    <origin rpy="0 0 0" xyz="0 0 0"/>
  </joint>
  <link name="wheel0_base_link"/>
  <joint name="wheel0_motor_joint" type="fixed">
    <parent link="wheel0_base_link"/>
    <child link="wheel0_motor_body_link"/>
  </joint>
  <link name="wheel0_motor_body_link">
    <visual>
      <geometry>
        <mesh filename="model://omni_robot/meshes/ga25_body.stl"/>
      </geometry>
      <material name="gray"/>
    </visual>
    <collision>
      <origin rpy="0 1.5707963267948966 0" xyz="-0.025 0 0"/>
      <geometry>
        <cylinder length="0.05" radius="0.012"/>
      </geometry>
    </collision>
    <inertial>
      <mass value="0.150"/>
      <inertia ixx="0.0001" ixy="0" ixz="0" iyy="0.0001" iyz="0" izz="0.0001"/>
    </inertial>
  </link>
  <gazebo reference="wheel0_motor_body_link">
    <material>Gazebo/Gray</material>
  </gazebo>
  <joint name="wheel0_motor_shaft_joint" type="continuous">
    <parent link="wheel0_motor_body_link"/>
    <child link="wheel0_motor_shaft_link"/>
    <origin rpy="0 0 0" xyz="0.012 0 0"/>
    <axis xyz="1 0 0"/>
    <limit effort="3.0" velocity="40.0"/>
    <dynamics damping="0.01" friction="0.0"/>
  </joint>
  <transmission name="wheel0_motor_shaft_trans">
    <type>transmission_interface/SimpleTransmission</type>
    <joint name="wheel0_motor_shaft_joint">
      <hardwareInterface>hardware_interface/EffortJointInterface</hardwareInterface>
    </joint>
    <actuator name="wheel0_motor_shaft_motor">
      <hardwareInterface>hardware_interface/EffortJointInterface</hardwareInterface>
      <mechanicalReduction>1</mechanicalReduction>
    </actuator>
  </transmission>
  <link name="wheel0_motor_shaft_link">
    <visual>
      <geometry>
        <mesh filename="model://omni_robot/meshes/ga25_shaft.stl"/>
      </geometry>
      <material name="gray"/>
    </visual>
    <inertial>
      <mass value="0.010"/>
      <inertia ixx="0.0000005" ixy="0" ixz="0" iyy="0.000001" iyz="0" izz="0.000001"/>
    </inertial>
  </link>
  <gazebo reference="wheel0_motor_shaft_link">
    <material>Gazebo/Gray</material>
  </gazebo>
  <joint name="wheel0_housind_joint" type="fixed">
    <parent link="wheel0_motor_shaft_link"/>
    <child link="wheel0_housing_link"/>
    <origin rpy="0 1.5707963267948966 0" xyz="0.012 0 0"/>
  </joint>
  <link name="wheel0_housing_link">
    <visual>
      <geometry>
        <mesh filename="model://omni_robot/meshes/omni_housing.stl"/>
      </geometry>
      <origin rpy="0 0 0" xyz="0 0 0"/>
      <material name="gray"/>
    </visual>
    <inertial>
      <mass value="0.025"/>
      <inertia ixx="0.0001" ixy="0" ixz="0" iyy="0.0001" iyz="0" izz="0.0001"/>
    </inertial>
  </link>
  <gazebo reference="wheel0_housing_link">
    <material>Gazebo/Gray</material>
  </gazebo>
  <joint name="wheel0_housing_s_joint" type="fixed">
    <parent link="wheel0_housing_link"/>
    <child link="wheel0_housing_s_link"/>
    <origin rpy="0 3.141592653589793 0.7853981633974483" xyz="0 0 0"/>
  </joint>
  <link name="wheel0_housing_s_link">
    <inertial>
      <mass value="0.025"/>
      <inertia ixx="0.0001" ixy="0" ixz="0" iyy="0.0001" iyz="0" izz="0.0001"/>
    </inertial>
  </link>
  <joint name="wheel0_barrel_1_joint" type="continuous">
    <!-- continuous -->
    <parent link="wheel0_housing_link"/>
    <child link="wheel0_barrel_1_link"/>
    <origin rpy="1.5707963267948966 0 0" xyz="0.014 0.0 0.006"/>
    <axis xyz="0 0 1"/>
    <dynamics damping="0.001"/>
  </joint>
  <transmission name="wheel0_barrel_1_trans">
    <type>transmission_interface/SimpleTransmission</type>
    <joint name="wheel0_barrel_1_joint">
      <hardwareInterface>hardware_interface/EffortJointInterface</hardwareInterface>
    </joint>
    <actuator name="wheel0_barrel_1_motor">
      <hardwareInterface>hardware_interface/EffortJointInterface</hardwareInterface>
      <mechanicalReduction>1</mechanicalReduction>
    </actuator>
  </transmission>
  <link name="wheel0_barrel_1_link">
    <visual>
      <geometry>
        <mesh filename="model://omni_robot/meshes/omni_barrel.stl"/>
      </geometry>
      <material name="black"/>
    </visual>
    <collision>
      <geometry>
        <mesh filename="model://omni_robot/meshes/omni_barrel.stl"/>
      </geometry>
    </collision>
    <inertial>
      <mass value="0.002"/>
      <inertia ixx="0.000001" ixy="0" ixz="0" iyy="0.000001" iyz="0" izz="0.000001"/>
    </inertial>
  </link>
  <gazebo reference="wheel0_barrel_1_link">
    <mu1 value="2.5"/>
    <mu2 value="2.5"/>
    <kp value="5000"/>
    <kd value="10"/>
    <material>Gazebo/Black</material>
  </gazebo>
  <joint name="wheel0_barrel_1_mark_joint" type="fixed">
    <parent link="wheel0_barrel_1_link"/>
    <child link="wheel0_barrel_1_mark_link"/>
    <origin rpy="0 0 0" xyz="0.005 0 0"/>
  </joint>
  <link name="wheel0_barrel_1_mark_link">
    <visual>
      <geometry>
        <box size="0.005 0.005 0.005"/>
      </geometry>
      <material name="white"/>
    </visual>
  </link>
  <gazebo reference="wheel0_barrel_1_mark_link">
    <material>Gazebo/White</material>
  </gazebo>
  <joint name="wheel0_barrel_2_joint" type="continuous">
    <!-- continuous -->
    <parent link="wheel0_housing_link"/>
    <child link="wheel0_barrel_2_link"/>
    <origin rpy="1.5707963267948966 0 1.5707963267948966" xyz="8.572527594031473e-19 0.014 0.006"/>
    <axis xyz="0 0 1"/>
    <dynamics damping="0.001"/>
  </joint>
  <transmission name="wheel0_barrel_2_trans">
    <type>transmission_interface/SimpleTransmission</type>
    <joint name="wheel0_barrel_2_joint">
      <hardwareInterface>hardware_interface/EffortJointInterface</hardwareInterface>
    </joint>
    <actuator name="wheel0_barrel_2_motor">
      <hardwareInterface>hardware_interface/EffortJointInterface</hardwareInterface>
      <mechanicalReduction>1</mechanicalReduction>
    </actuator>
  </transmission>
  <link name="wheel0_barrel_2_link">
    <visual>
      <geometry>
        <mesh filename="model://omni_robot/meshes/omni_barrel.stl"/>
      </geometry>
      <material name="black"/>
    </visual>
    <collision>
      <geometry>
        <mesh filename="model://omni_robot/meshes/omni_barrel.stl"/>
      </geometry>
    </collision>
    <inertial>
      <mass value="0.002"/>
      <inertia ixx="0.000001" ixy="0" ixz="0" iyy="0.000001" iyz="0" izz="0.000001"/>
    </inertial>
  </link>
  <gazebo reference="wheel0_barrel_2_link">
    <mu1 value="2.5"/>
    <mu2 value="2.5"/>
    <kp value="5000"/>
    <kd value="10"/>
    <material>Gazebo/Black</material>
  </gazebo>
  <joint name="wheel0_barrel_2_mark_joint" type="fixed">
    <parent link="wheel0_barrel_2_link"/>
    <child link="wheel0_barrel_2_mark_link"/>
    <origin rpy="0 0 0" xyz="0.005 0 0"/>
  </joint>
  <link name="wheel0_barrel_2_mark_link">
    <visual>
      <geometry>
        <box size="0.005 0.005 0.005"/>
      </geometry>
      <material name="white"/>
    </visual>
  </link>
  <gazebo reference="wheel0_barrel_2_mark_link">
    <material>Gazebo/White</material>
  </gazebo>
  <joint name="wheel0_barrel_3_joint" type="continuous">
    <!-- continuous -->
    <parent link="wheel0_housing_link"/>
    <child link="wheel0_barrel_3_link"/>
    <origin rpy="1.5707963267948966 0 3.141592653589793" xyz="-0.014 1.7145055188062945e-18 0.006"/>
    <axis xyz="0 0 1"/>
    <dynamics damping="0.001"/>
  </joint>
  <transmission name="wheel0_barrel_3_trans">
    <type>transmission_interface/SimpleTransmission</type>
    <joint name="wheel0_barrel_3_joint">
      <hardwareInterface>hardware_interface/EffortJointInterface</hardwareInterface>
    </joint>
    <actuator name="wheel0_barrel_3_motor">
      <hardwareInterface>hardware_interface/EffortJointInterface</hardwareInterface>
      <mechanicalReduction>1</mechanicalReduction>
    </actuator>
  </transmission>
  <link name="wheel0_barrel_3_link">
    <visual>
      <geometry>
        <mesh filename="model://omni_robot/meshes/omni_barrel.stl"/>
      </geometry>
      <material name="black"/>
    </visual>
    <collision>
      <geometry>
        <mesh filename="model://omni_robot/meshes/omni_barrel.stl"/>
      </geometry>
    </collision>
    <inertial>
      <mass value="0.002"/>
      <inertia ixx="0.000001" ixy="0" ixz="0" iyy="0.000001" iyz="0" izz="0.000001"/>
    </inertial>
  </link>
  <gazebo reference="wheel0_barrel_3_link">
    <mu1 value="2.5"/>
    <mu2 value="2.5"/>
    <kp value="5000"/>
    <kd value="10"/>
    <material>Gazebo/Black</material>
  </gazebo>
  <joint name="wheel0_barrel_3_mark_joint" type="fixed">
    <parent link="wheel0_barrel_3_link"/>
    <child link="wheel0_barrel_3_mark_link"/>
    <origin rpy="0 0 0" xyz="0.005 0 0"/>
  </joint>
  <link name="wheel0_barrel_3_mark_link">
    <visual>
      <geometry>
        <box size="0.005 0.005 0.005"/>
      </geometry>
      <material name="white"/>
    </visual>
  </link>
  <gazebo reference="wheel0_barrel_3_mark_link">
    <material>Gazebo/White</material>
  </gazebo>
  <joint name="wheel0_barrel_4_joint" type="continuous">
    <!-- continuous -->
    <parent link="wheel0_housing_link"/>
    <child link="wheel0_barrel_4_link"/>
    <origin rpy="1.5707963267948966 0 -1.5707963267948966" xyz="8.572527594031473e-19 -0.014 0.006"/>
    <axis xyz="0 0 1"/>
    <dynamics damping="0.001"/>
  </joint>
  <transmission name="wheel0_barrel_4_trans">
    <type>transmission_interface/SimpleTransmission</type>
    <joint name="wheel0_barrel_4_joint">
      <hardwareInterface>hardware_interface/EffortJointInterface</hardwareInterface>
    </joint>
    <actuator name="wheel0_barrel_4_motor">
      <hardwareInterface>hardware_interface/EffortJointInterface</hardwareInterface>
      <mechanicalReduction>1</mechanicalReduction>
    </actuator>
  </transmission>
  <link name="wheel0_barrel_4_link">
    <visual>
      <geometry>
        <mesh filename="model://omni_robot/meshes/omni_barrel.stl"/>
      </geometry>
      <material name="black"/>
    </visual>
    <collision>
      <geometry>
        <mesh filename="model://omni_robot/meshes/omni_barrel.stl"/>
      </geometry>
    </collision>
    <inertial>
      <mass value="0.002"/>
      <inertia ixx="0.000001" ixy="0" ixz="0" iyy="0.000001" iyz="0" izz="0.000001"/>
    </inertial>
  </link>
  <gazebo reference="wheel0_barrel_4_link">
    <mu1 value="2.5"/>
    <mu2 value="2.5"/>
    <kp value="5000"/>
    <kd value="10"/>
    <material>Gazebo/Black</material>
  </gazebo>
  <joint name="wheel0_barrel_4_mark_joint" type="fixed">
    <parent link="wheel0_barrel_4_link"/>
    <child link="wheel0_barrel_4_mark_link"/>
    <origin rpy="0 0 0" xyz="0.005 0 0"/>
  </joint>
  <link name="wheel0_barrel_4_mark_link">
    <visual>
      <geometry>
        <box size="0.005 0.005 0.005"/>
      </geometry>
      <material name="white"/>
    </visual>
  </link>
  <gazebo reference="wheel0_barrel_4_mark_link">
    <material>Gazebo/White</material>
  </gazebo>
  <joint name="wheel0_barrel_5_joint" type="continuous">
    <!-- continuous -->
    <parent link="wheel0_housing_s_link"/>
    <child link="wheel0_barrel_5_link"/>
    <origin rpy="1.5707963267948966 0 0" xyz="0.014 0.0 0.006"/>
    <axis xyz="0 0 1"/>
    <dynamics damping="0.001"/>
  </joint>
  <transmission name="wheel0_barrel_5_trans">
    <type>transmission_interface/SimpleTransmission</type>
    <joint name="wheel0_barrel_5_joint">
      <hardwareInterface>hardware_interface/EffortJointInterface</hardwareInterface>
    </joint>
    <actuator name="wheel0_barrel_5_motor">
      <hardwareInterface>hardware_interface/EffortJointInterface</hardwareInterface>
      <mechanicalReduction>1</mechanicalReduction>
    </actuator>
  </transmission>
  <link name="wheel0_barrel_5_link">
    <visual>
      <geometry>
        <mesh filename="model://omni_robot/meshes/omni_barrel.stl"/>
      </geometry>
      <material name="black"/>
    </visual>
    <collision>
      <geometry>
        <mesh filename="model://omni_robot/meshes/omni_barrel.stl"/>
      </geometry>
    </collision>
    <inertial>
      <mass value="0.002"/>
      <inertia ixx="0.000001" ixy="0" ixz="0" iyy="0.000001" iyz="0" izz="0.000001"/>
    </inertial>
  </link>
  <gazebo reference="wheel0_barrel_5_link">
    <mu1 value="2.5"/>
    <mu2 value="2.5"/>
    <kp value="5000"/>
    <kd value="10"/>
    <material>Gazebo/Black</material>
  </gazebo>
  <joint name="wheel0_barrel_5_mark_joint" type="fixed">
    <parent link="wheel0_barrel_5_link"/>
    <child link="wheel0_barrel_5_mark_link"/>
    <origin rpy="0 0 0" xyz="0.005 0 0"/>
  </joint>
  <link name="wheel0_barrel_5_mark_link">
    <visual>
      <geometry>
        <box size="0.005 0.005 0.005"/>
      </geometry>
      <material name="white"/>
    </visual>
  </link>
  <gazebo reference="wheel0_barrel_5_mark_link">
    <material>Gazebo/White</material>
  </gazebo>
  <joint name="wheel0_barrel_6_joint" type="continuous">
    <!-- continuous -->
    <parent link="wheel0_housing_s_link"/>
    <child link="wheel0_barrel_6_link"/>
    <origin rpy="1.5707963267948966 0 1.5707963267948966" xyz="8.572527594031473e-19 0.014 0.006"/>
    <axis xyz="0 0 1"/>
    <dynamics damping="0.001"/>
  </joint>
  <transmission name="wheel0_barrel_6_trans">
    <type>transmission_interface/SimpleTransmission</type>
    <joint name="wheel0_barrel_6_joint">
      <hardwareInterface>hardware_interface/EffortJointInterface</hardwareInterface>
    </joint>
    <actuator name="wheel0_barrel_6_motor">
      <hardwareInterface>hardware_interface/EffortJointInterface</hardwareInterface>
      <mechanicalReduction>1</mechanicalReduction>
    </actuator>
  </transmission>
  <link name="wheel0_barrel_6_link">
    <visual>
      <geometry>
        <mesh filename="model://omni_robot/meshes/omni_barrel.stl"/>
      </geometry>
      <material name="black"/>
    </visual>
    <collision>
      <geometry>
        <mesh filename="model://omni_robot/meshes/omni_barrel.stl"/>
      </geometry>
    </collision>
    <inertial>
      <mass value="0.002"/>
      <inertia ixx="0.000001" ixy="0" ixz="0" iyy="0.000001" iyz="0" izz="0.000001"/>
    </inertial>
  </link>
  <gazebo reference="wheel0_barrel_6_link">
    <mu1 value="2.5"/>
    <mu2 value="2.5"/>
    <kp value="5000"/>
    <kd value="10"/>
    <material>Gazebo/Black</material>
  </gazebo>
  <joint name="wheel0_barrel_6_mark_joint" type="fixed">
    <parent link="wheel0_barrel_6_link"/>
    <child link="wheel0_barrel_6_mark_link"/>
    <origin rpy="0 0 0" xyz="0.005 0 0"/>
  </joint>
  <link name="wheel0_barrel_6_mark_link">
    <visual>
      <geometry>
        <box size="0.005 0.005 0.005"/>
      </geometry>
      <material name="white"/>
    </visual>
  </link>
  <gazebo reference="wheel0_barrel_6_mark_link">
    <material>Gazebo/White</material>
  </gazebo>
  <joint name="wheel0_barrel_7_joint" type="continuous">
    <!-- continuous -->
    <parent link="wheel0_housing_s_link"/>
    <child link="wheel0_barrel_7_link"/>
    <origin rpy="1.5707963267948966 0 3.141592653589793" xyz="-0.014 1.7145055188062945e-18 0.006"/>
    <axis xyz="0 0 1"/>
    <dynamics damping="0.001"/>
  </joint>
  <transmission name="wheel0_barrel_7_trans">
    <type>transmission_interface/SimpleTransmission</type>
    <joint name="wheel0_barrel_7_joint">
      <hardwareInterface>hardware_interface/EffortJointInterface</hardwareInterface>
    </joint>
    <actuator name="wheel0_barrel_7_motor">
      <hardwareInterface>hardware_interface/EffortJointInterface</hardwareInterface>
      <mechanicalReduction>1</mechanicalReduction>
    </actuator>
  </transmission>
  <link name="wheel0_barrel_7_link">
    <visual>
      <geometry>
        <mesh filename="model://omni_robot/meshes/omni_barrel.stl"/>
      </geometry>
      <material name="black"/>
    </visual>
    <collision>
      <geometry>
        <mesh filename="model://omni_robot/meshes/omni_barrel.stl"/>
      </geometry>
    </collision>
    <inertial>
      <mass value="0.002"/>
      <inertia ixx="0.000001" ixy="0" ixz="0" iyy="0.000001" iyz="0" izz="0.000001"/>
    </inertial>
  </link>
  <gazebo reference="wheel0_barrel_7_link">
    <mu1 value="2.5"/>
    <mu2 value="2.5"/>
    <kp value="5000"/>
    <kd value="10"/>
    <material>Gazebo/Black</material>
  </gazebo>
  <joint name="wheel0_barrel_7_mark_joint" type="fixed">
    <parent link="wheel0_barrel_7_link"/>
    <child link="wheel0_barrel_7_mark_link"/>
    <origin rpy="0 0 0" xyz="0.005 0 0"/>
  </joint>
  <link name="wheel0_barrel_7_mark_link">
    <visual>
      <geometry>
        <box size="0.005 0.005 0.005"/>
      </geometry>
      <material name="white"/>
    </visual>
  </link>
  <gazebo reference="wheel0_barrel_7_mark_link">
    <material>Gazebo/White</material>
  </gazebo>
  <joint name="wheel0_barrel_8_joint" type="continuous">
    <!-- continuous -->
    <parent link="wheel0_housing_s_link"/>
    <child link="wheel0_barrel_8_link"/>
    <origin rpy="1.5707963267948966 0 -1.5707963267948966" xyz="8.572527594031473e-19 -0.014 0.006"/>
    <axis xyz="0 0 1"/>
    <dynamics damping="0.001"/>
  </joint>
  <transmission name="wheel0_barrel_8_trans">
    <type>transmission_interface/SimpleTransmission</type>
    <joint name="wheel0_barrel_8_joint">
      <hardwareInterface>hardware_interface/EffortJointInterface</hardwareInterface>
    </joint>
    <actuator name="wheel0_barrel_8_motor">
      <hardwareInterface>hardware_interface/EffortJointInterface</hardwareInterface>
      <mechanicalReduction>1</mechanicalReduction>
    </actuator>
  </transmission>
  <link name="wheel0_barrel_8_link">
    <visual>
      <geometry>
        <mesh filename="model://omni_robot/meshes/omni_barrel.stl"/>
      </geometry>
      <material name="black"/>
    </visual>
    <collision>
      <geometry>
        <mesh filename="model://omni_robot/meshes/omni_barrel.stl"/>
      </geometry>
    </collision>
    <inertial>
      <mass value="0.002"/>
      <inertia ixx="0.000001" ixy="0" ixz="0" iyy="0.000001" iyz="0" izz="0.000001"/>
    </inertial>
  </link>
  <gazebo reference="wheel0_barrel_8_link">
    <mu1 value="2.5"/>
    <mu2 value="2.5"/>
    <kp value="5000"/>
    <kd value="10"/>
    <material>Gazebo/Black</material>
  </gazebo>
  <joint name="wheel0_barrel_8_mark_joint" type="fixed">
    <parent link="wheel0_barrel_8_link"/>
    <child link="wheel0_barrel_8_mark_link"/>
    <origin rpy="0 0 0" xyz="0.005 0 0"/>
  </joint>
  <link name="wheel0_barrel_8_mark_link">
    <visual>
      <geometry>
        <box size="0.005 0.005 0.005"/>
      </geometry>
      <material name="white"/>
    </visual>
  </link>
  <gazebo reference="wheel0_barrel_8_mark_link">
    <material>Gazebo/White</material>
  </gazebo>
  <joint name="wheel1_attach_joint" type="fixed">
    <parent link="base_link"/>
    <child link="wheel1_attach_link"/>
    <origin rpy="0 0 3.141592653589793" xyz="-0.07 8.572527594031473e-18 0.019"/>
  </joint>
  <link name="wheel1_attach_link"/>
  <joint name="wheel1_base_joint" type="fixed">
    <parent link="wheel1_attach_link"/>
    <child link="wheel1_base_link"/>
    <origin rpy="0 0 0" xyz="0 0 0"/>
  </joint>
  <link name="wheel1_base_link"/>
  <joint name="wheel1_motor_joint" type="fixed">
    <parent link="wheel1_base_link"/>
    <child link="wheel1_motor_body_link"/>
  </joint>
  <link name="wheel1_motor_body_link">
    <visual>
      <geometry>
        <mesh filename="model://omni_robot/meshes/ga25_body.stl"/>
      </geometry>
      <material name="gray"/>
    </visual>
    <collision>
      <origin rpy="0 1.5707963267948966 0" xyz="-0.025 0 0"/>
      <geometry>
        <cylinder length="0.05" radius="0.012"/>
      </geometry>
    </collision>
    <inertial>
      <mass value="0.150"/>
      <inertia ixx="0.0001" ixy="0" ixz="0" iyy="0.0001" iyz="0" izz="0.0001"/>
    </inertial>
  </link>
  <gazebo reference="wheel1_motor_body_link">
    <material>Gazebo/Gray</material>
  </gazebo>
  <joint name="wheel1_motor_shaft_joint" type="continuous">
    <parent link="wheel1_motor_body_link"/>
    <child link="wheel1_motor_shaft_link"/>
    <origin rpy="0 0 0" xyz="0.012 0 0"/>
    <axis xyz="1 0 0"/>
    <limit effort="3.0" velocity="40.0"/>
    <dynamics damping="0.01" friction="0.0"/>
  </joint>
  <transmission name="wheel1_motor_shaft_trans">
    <type>transmission_interface/SimpleTransmission</type>
    <joint name="wheel1_motor_shaft_joint">
      <hardwareInterface>hardware_interface/EffortJointInterface</hardwareInterface>
    </joint>
    <actuator name="wheel1_motor_shaft_motor">
      <hardwareInterface>hardware_interface/EffortJointInterface</hardwareInterface>
      <mechanicalReduction>1</mechanicalReduction>
    </actuator>
  </transmission>
  <link name="wheel1_motor_shaft_link">
    <visual>
      <geometry>
        <mesh filename="model://omni_robot/meshes/ga25_shaft.stl"/>
      </geometry>
      <material name="gray"/>
    </visual>
    <inertial>
      <mass value="0.010"/>
      <inertia ixx="0.0000005" ixy="0" ixz="0" iyy="0.000001" iyz="0" izz="0.000001"/>
    </inertial>
  </link>
  <gazebo reference="wheel1_motor_shaft_link">
    <material>Gazebo/Gray</material>
  </gazebo>
  <joint name="wheel1_housind_joint" type="fixed">
    <parent link="wheel1_motor_shaft_link"/>
    <child link="wheel1_housing_link"/>
    <origin rpy="0 1.5707963267948966 0" xyz="0.012 0 0"/>
  </joint>
  <link name="wheel1_housing_link">
    <visual>
      <geometry>
        <mesh filename="model://omni_robot/meshes/omni_housing.stl"/>
      </geometry>
      <origin rpy="0 0 0" xyz="0 0 0"/>
      <material name="gray"/>
    </visual>
    <inertial>
      <mass value="0.025"/>
      <inertia ixx="0.0001" ixy="0" ixz="0" iyy="0.0001" iyz="0" izz="0.0001"/>
    </inertial>
  </link>
  <gazebo reference="wheel1_housing_link">
    <material>Gazebo/Gray</material>
  </gazebo>
  <joint name="wheel1_housing_s_joint" type="fixed">
    <parent link="wheel1_housing_link"/>
    <child link="wheel1_housing_s_link"/>
    <origin rpy="0 3.141592653589793 0.7853981633974483" xyz="0 0 0"/>
  </joint>
  <link name="wheel1_housing_s_link">
    <inertial>
      <mass value="0.025"/>
      <inertia ixx="0.0001" ixy="0" ixz="0" iyy="0.0001" iyz="0" izz="0.0001"/>
    </inertial>
  </link>
  <joint name="wheel1_barrel_1_joint" type="continuous">
    <!-- continuous -->
    <parent link="wheel1_housing_link"/>
    <child link="wheel1_barrel_1_link"/>
    <origin rpy="1.5707963267948966 0 0" xyz="0.014 0.0 0.006"/>
    <axis xyz="0 0 1"/>
    <dynamics damping="0.001"/>
  </joint>
  <transmission name="wheel1_barrel_1_trans">
    <type>transmission_interface/SimpleTransmission</type>
    <joint name="wheel1_barrel_1_joint">
      <hardwareInterface>hardware_interface/EffortJointInterface</hardwareInterface>
    </joint>
    <actuator name="wheel1_barrel_1_motor">
      <hardwareInterface>hardware_interface/EffortJointInterface</hardwareInterface>
      <mechanicalReduction>1</mechanicalReduction>
    </actuator>
  </transmission>
  <link name="wheel1_barrel_1_link">
    <visual>
      <geometry>
        <mesh filename="model://omni_robot/meshes/omni_barrel.stl"/>
      </geometry>
      <material name="black"/>
    </visual>
    <collision>
      <geometry>
        <mesh filename="model://omni_robot/meshes/omni_barrel.stl"/>
      </geometry>
    </collision>
    <inertial>
      <mass value="0.002"/>
      <inertia ixx="0.000001" ixy="0" ixz="0" iyy="0.000001" iyz="0" izz="0.000001"/>
    </inertial>
  </link>
  <gazebo reference="wheel1_barrel_1_link">
    <mu1 value="2.5"/>
    <mu2 value="2.5"/>
    <kp value="5000"/>
    <kd value="10"/>
    <material>Gazebo/Black</material>
  </gazebo>
  <joint name="wheel1_barrel_1_mark_joint" type="fixed">
    <parent link="wheel1_barrel_1_link"/>
    <child link="wheel1_barrel_1_mark_link"/>
    <origin rpy="0 0 0" xyz="0.005 0 0"/>
  </joint>
  <link name="wheel1_barrel_1_mark_link">
    <visual>
      <geometry>
        <box size="0.005 0.005 0.005"/>
      </geometry>
      <material name="white"/>
    </visual>
  </link>
  <gazebo reference="wheel1_barrel_1_mark_link">
    <material>Gazebo/White</material>
  </gazebo>
  <joint name="wheel1_barrel_2_joint" type="continuous">
    <!-- continuous -->
    <parent link="wheel1_housing_link"/>
    <child link="wheel1_barrel_2_link"/>
    <origin rpy="1.5707963267948966 0 1.5707963267948966" xyz="8.572527594031473e-19 0.014 0.006"/>
    <axis xyz="0 0 1"/>
    <dynamics damping="0.001"/>
  </joint>
  <transmission name="wheel1_barrel_2_trans">
    <type>transmission_interface/SimpleTransmission</type>
    <joint name="wheel1_barrel_2_joint">
      <hardwareInterface>hardware_interface/EffortJointInterface</hardwareInterface>
    </joint>
    <actuator name="wheel1_barrel_2_motor">
      <hardwareInterface>hardware_interface/EffortJointInterface</hardwareInterface>
      <mechanicalReduction>1</mechanicalReduction>
    </actuator>
  </transmission>
  <link name="wheel1_barrel_2_link">
    <visual>
      <geometry>
        <mesh filename="model://omni_robot/meshes/omni_barrel.stl"/>
      </geometry>
      <material name="black"/>
    </visual>
    <collision>
      <geometry>
        <mesh filename="model://omni_robot/meshes/omni_barrel.stl"/>
      </geometry>
    </collision>
    <inertial>
      <mass value="0.002"/>
      <inertia ixx="0.000001" ixy="0" ixz="0" iyy="0.000001" iyz="0" izz="0.000001"/>
    </inertial>
  </link>
  <gazebo reference="wheel1_barrel_2_link">
    <mu1 value="2.5"/>
    <mu2 value="2.5"/>
    <kp value="5000"/>
    <kd value="10"/>
    <material>Gazebo/Black</material>
  </gazebo>
  <joint name="wheel1_barrel_2_mark_joint" type="fixed">
    <parent link="wheel1_barrel_2_link"/>
    <child link="wheel1_barrel_2_mark_link"/>
    <origin rpy="0 0 0" xyz="0.005 0 0"/>
  </joint>
  <link name="wheel1_barrel_2_mark_link">
    <visual>
      <geometry>
        <box size="0.005 0.005 0.005"/>
      </geometry>
      <material name="white"/>
    </visual>
  </link>
  <gazebo reference="wheel1_barrel_2_mark_link">
    <material>Gazebo/White</material>
  </gazebo>
  <joint name="wheel1_barrel_3_joint" type="continuous">
    <!-- continuous -->
    <parent link="wheel1_housing_link"/>
    <child link="wheel1_barrel_3_link"/>
    <origin rpy="1.5707963267948966 0 3.141592653589793" xyz="-0.014 1.7145055188062945e-18 0.006"/>
    <axis xyz="0 0 1"/>
    <dynamics damping="0.001"/>
  </joint>
  <transmission name="wheel1_barrel_3_trans">
    <type>transmission_interface/SimpleTransmission</type>
    <joint name="wheel1_barrel_3_joint">
      <hardwareInterface>hardware_interface/EffortJointInterface</hardwareInterface>
    </joint>
    <actuator name="wheel1_barrel_3_motor">
      <hardwareInterface>hardware_interface/EffortJointInterface</hardwareInterface>
      <mechanicalReduction>1</mechanicalReduction>
    </actuator>
  </transmission>
  <link name="wheel1_barrel_3_link">
    <visual>
      <geometry>
        <mesh filename="model://omni_robot/meshes/omni_barrel.stl"/>
      </geometry>
      <material name="black"/>
    </visual>
    <collision>
      <geometry>
        <mesh filename="model://omni_robot/meshes/omni_barrel.stl"/>
      </geometry>
    </collision>
    <inertial>
      <mass value="0.002"/>
      <inertia ixx="0.000001" ixy="0" ixz="0" iyy="0.000001" iyz="0" izz="0.000001"/>
    </inertial>
  </link>
  <gazebo reference="wheel1_barrel_3_link">
    <mu1 value="2.5"/>
    <mu2 value="2.5"/>
    <kp value="5000"/>
    <kd value="10"/>
    <material>Gazebo/Black</material>
  </gazebo>
  <joint name="wheel1_barrel_3_mark_joint" type="fixed">
    <parent link="wheel1_barrel_3_link"/>
    <child link="wheel1_barrel_3_mark_link"/>
    <origin rpy="0 0 0" xyz="0.005 0 0"/>
  </joint>
  <link name="wheel1_barrel_3_mark_link">
    <visual>
      <geometry>
        <box size="0.005 0.005 0.005"/>
      </geometry>
      <material name="white"/>
    </visual>
  </link>
  <gazebo reference="wheel1_barrel_3_mark_link">
    <material>Gazebo/White</material>
  </gazebo>
  <joint name="wheel1_barrel_4_joint" type="continuous">
    <!-- continuous -->
    <parent link="wheel1_housing_link"/>
    <child link="wheel1_barrel_4_link"/>
    <origin rpy="1.5707963267948966 0 -1.5707963267948966" xyz="8.572527594031473e-19 -0.014 0.006"/>
    <axis xyz="0 0 1"/>
    <dynamics damping="0.001"/>
  </joint>
  <transmission name="wheel1_barrel_4_trans">
    <type>transmission_interface/SimpleTransmission</type>
    <joint name="wheel1_barrel_4_joint">
      <hardwareInterface>hardware_interface/EffortJointInterface</hardwareInterface>
    </joint>
    <actuator name="wheel1_barrel_4_motor">
      <hardwareInterface>hardware_interface/EffortJointInterface</hardwareInterface>
      <mechanicalReduction>1</mechanicalReduction>
    </actuator>
  </transmission>
  <link name="wheel1_barrel_4_link">
    <visual>
      <geometry>
        <mesh filename="model://omni_robot/meshes/omni_barrel.stl"/>
      </geometry>
      <material name="black"/>
    </visual>
    <collision>
      <geometry>
        <mesh filename="model://omni_robot/meshes/omni_barrel.stl"/>
      </geometry>
    </collision>
    <inertial>
      <mass value="0.002"/>
      <inertia ixx="0.000001" ixy="0" ixz="0" iyy="0.000001" iyz="0" izz="0.000001"/>
    </inertial>
  </link>
  <gazebo reference="wheel1_barrel_4_link">
    <mu1 value="2.5"/>
    <mu2 value="2.5"/>
    <kp value="5000"/>
    <kd value="10"/>
    <material>Gazebo/Black</material>
  </gazebo>
  <joint name="wheel1_barrel_4_mark_joint" type="fixed">
    <parent link="wheel1_barrel_4_link"/>
    <child link="wheel1_barrel_4_mark_link"/>
    <origin rpy="0 0 0" xyz="0.005 0 0"/>
  </joint>
  <link name="wheel1_barrel_4_mark_link">
    <visual>
      <geometry>
        <box size="0.005 0.005 0.005"/>
      </geometry>
      <material name="white"/>
    </visual>
  </link>
  <gazebo reference="wheel1_barrel_4_mark_link">
    <material>Gazebo/White</material>
  </gazebo>
  <joint name="wheel1_barrel_5_joint" type="continuous">
    <!-- continuous -->
    <parent link="wheel1_housing_s_link"/>
    <child link="wheel1_barrel_5_link"/>
    <origin rpy="1.5707963267948966 0 0" xyz="0.014 0.0 0.006"/>
    <axis xyz="0 0 1"/>
    <dynamics damping="0.001"/>
  </joint>
  <transmission name="wheel1_barrel_5_trans">
    <type>transmission_interface/SimpleTransmission</type>
    <joint name="wheel1_barrel_5_joint">
      <hardwareInterface>hardware_interface/EffortJointInterface</hardwareInterface>
    </joint>
    <actuator name="wheel1_barrel_5_motor">
      <hardwareInterface>hardware_interface/EffortJointInterface</hardwareInterface>
      <mechanicalReduction>1</mechanicalReduction>
    </actuator>
  </transmission>
  <link name="wheel1_barrel_5_link">
    <visual>
      <geometry>
        <mesh filename="model://omni_robot/meshes/omni_barrel.stl"/>
      </geometry>
      <material name="black"/>
    </visual>
    <collision>
      <geometry>
        <mesh filename="model://omni_robot/meshes/omni_barrel.stl"/>
      </geometry>
    </collision>
    <inertial>
      <mass value="0.002"/>
      <inertia ixx="0.000001" ixy="0" ixz="0" iyy="0.000001" iyz="0" izz="0.000001"/>
    </inertial>
  </link>
  <gazebo reference="wheel1_barrel_5_link">
    <mu1 value="2.5"/>
    <mu2 value="2.5"/>
    <kp value="5000"/>
    <kd value="10"/>
    <material>Gazebo/Black</material>
  </gazebo>
  <joint name="wheel1_barrel_5_mark_joint" type="fixed">
    <parent link="wheel1_barrel_5_link"/>
    <child link="wheel1_barrel_5_mark_link"/>
    <origin rpy="0 0 0" xyz="0.005 0 0"/>
  </joint>
  <link name="wheel1_barrel_5_mark_link">
    <visual>
      <geometry>
        <box size="0.005 0.005 0.005"/>
      </geometry>
      <material name="white"/>
    </visual>
  </link>
  <gazebo reference="wheel1_barrel_5_mark_link">
    <material>Gazebo/White</material>
  </gazebo>
  <joint name="wheel1_barrel_6_joint" type="continuous">
    <!-- continuous -->
    <parent link="wheel1_housing_s_link"/>
    <child link="wheel1_barrel_6_link"/>
    <origin rpy="1.5707963267948966 0 1.5707963267948966" xyz="8.572527594031473e-19 0.014 0.006"/>
    <axis xyz="0 0 1"/>
    <dynamics damping="0.001"/>
  </joint>
  <transmission name="wheel1_barrel_6_trans">
    <type>transmission_interface/SimpleTransmission</type>
    <joint name="wheel1_barrel_6_joint">
      <hardwareInterface>hardware_interface/EffortJointInterface</hardwareInterface>
    </joint>
    <actuator name="wheel1_barrel_6_motor">
      <hardwareInterface>hardware_interface/EffortJointInterface</hardwareInterface>
      <mechanicalReduction>1</mechanicalReduction>
    </actuator>
  </transmission>
  <link name="wheel1_barrel_6_link">
    <visual>
      <geometry>
        <mesh filename="model://omni_robot/meshes/omni_barrel.stl"/>
      </geometry>
      <material name="black"/>
    </visual>
    <collision>
      <geometry>
        <mesh filename="model://omni_robot/meshes/omni_barrel.stl"/>
      </geometry>
    </collision>
    <inertial>
      <mass value="0.002"/>
      <inertia ixx="0.000001" ixy="0" ixz="0" iyy="0.000001" iyz="0" izz="0.000001"/>
    </inertial>
  </link>
  <gazebo reference="wheel1_barrel_6_link">
    <mu1 value="2.5"/>
    <mu2 value="2.5"/>
    <kp value="5000"/>
    <kd value="10"/>
    <material>Gazebo/Black</material>
  </gazebo>
  <joint name="wheel1_barrel_6_mark_joint" type="fixed">
    <parent link="wheel1_barrel_6_link"/>
    <child link="wheel1_barrel_6_mark_link"/>
    <origin rpy="0 0 0" xyz="0.005 0 0"/>
  </joint>
  <link name="wheel1_barrel_6_mark_link">
    <visual>
      <geometry>
        <box size="0.005 0.005 0.005"/>
      </geometry>
      <material name="white"/>
    </visual>
  </link>
  <gazebo reference="wheel1_barrel_6_mark_link">
    <material>Gazebo/White</material>
  </gazebo>
  <joint name="wheel1_barrel_7_joint" type="continuous">
    <!-- continuous -->
    <parent link="wheel1_housing_s_link"/>
    <child link="wheel1_barrel_7_link"/>
    <origin rpy="1.5707963267948966 0 3.141592653589793" xyz="-0.014 1.7145055188062945e-18 0.006"/>
    <axis xyz="0 0 1"/>
    <dynamics damping="0.001"/>
  </joint>
  <transmission name="wheel1_barrel_7_trans">
    <type>transmission_interface/SimpleTransmission</type>
    <joint name="wheel1_barrel_7_joint">
      <hardwareInterface>hardware_interface/EffortJointInterface</hardwareInterface>
    </joint>
    <actuator name="wheel1_barrel_7_motor">
      <hardwareInterface>hardware_interface/EffortJointInterface</hardwareInterface>
      <mechanicalReduction>1</mechanicalReduction>
    </actuator>
  </transmission>
  <link name="wheel1_barrel_7_link">
    <visual>
      <geometry>
        <mesh filename="model://omni_robot/meshes/omni_barrel.stl"/>
      </geometry>
      <material name="black"/>
    </visual>
    <collision>
      <geometry>
        <mesh filename="model://omni_robot/meshes/omni_barrel.stl"/>
      </geometry>
    </collision>
    <inertial>
      <mass value="0.002"/>
      <inertia ixx="0.000001" ixy="0" ixz="0" iyy="0.000001" iyz="0" izz="0.000001"/>
    </inertial>
  </link>
  <gazebo reference="wheel1_barrel_7_link">
    <mu1 value="2.5"/>
    <mu2 value="2.5"/>
    <kp value="5000"/>
    <kd value="10"/>
    <material>Gazebo/Black</material>
  </gazebo>
  <joint name="wheel1_barrel_7_mark_joint" type="fixed">
    <parent link="wheel1_barrel_7_link"/>
    <child link="wheel1_barrel_7_mark_link"/>
    <origin rpy="0 0 0" xyz="0.005 0 0"/>
  </joint>
  <link name="wheel1_barrel_7_mark_link">
    <visual>
      <geometry>
        <box size="0.005 0.005 0.005"/>
      </geometry>
      <material name="white"/>
    </visual>
  </link>
  <gazebo reference="wheel1_barrel_7_mark_link">
    <material>Gazebo/White</material>
  </gazebo>
  <joint name="wheel1_barrel_8_joint" type="continuous">
    <!-- continuous -->
    <parent link="wheel1_housing_s_link"/>
    <child link="wheel1_barrel_8_link"/>
    <origin rpy="1.5707963267948966 0 -1.5707963267948966" xyz="8.572527594031473e-19 -0.014 0.006"/>
    <axis xyz="0 0 1"/>
    <dynamics damping="0.001"/>
  </joint>
  <transmission name="wheel1_barrel_8_trans">
    <type>transmission_interface/SimpleTransmission</type>
    <joint name="wheel1_barrel_8_joint">
      <hardwareInterface>hardware_interface/EffortJointInterface</hardwareInterface>
    </joint>
    <actuator name="wheel1_barrel_8_motor">
      <hardwareInterface>hardware_interface/EffortJointInterface</hardwareInterface>
      <mechanicalReduction>1</mechanicalReduction>
    </actuator>
  </transmission>
  <link name="wheel1_barrel_8_link">
    <visual>
      <geometry>
        <mesh filename="model://omni_robot/meshes/omni_barrel.stl"/>
      </geometry>
      <material name="black"/>
    </visual>
    <collision>
      <geometry>
        <mesh filename="model://omni_robot/meshes/omni_barrel.stl"/>
      </geometry>
    </collision>
    <inertial>
      <mass value="0.002"/>
      <inertia ixx="0.000001" ixy="0" ixz="0" iyy="0.000001" iyz="0" izz="0.000001"/>
    </inertial>
  </link>
  <gazebo reference="wheel1_barrel_8_link">
    <mu1 value="2.5"/>
    <mu2 value="2.5"/>
    <kp value="5000"/>
    <kd value="10"/>
    <material>Gazebo/Black</material>
  </gazebo>
  <joint name="wheel1_barrel_8_mark_joint" type="fixed">
    <parent link="wheel1_barrel_8_link"/>
    <child link="wheel1_barrel_8_mark_link"/>
    <origin rpy="0 0 0" xyz="0.005 0 0"/>
  </joint>
  <link name="wheel1_barrel_8_mark_link">
    <visual>
      <geometry>
        <box size="0.005 0.005 0.005"/>
      </geometry>
      <material name="white"/>
    </visual>
  </link>
  <gazebo reference="wheel1_barrel_8_mark_link">
    <material>Gazebo/White</material>
  </gazebo>
  <joint name="wheel2_attach_joint" type="fixed">
    <parent link="base_link"/>
    <child link="wheel2_attach_link"/>
    <origin rpy="0 0 4.71238898038469" xyz="-1.285879139104721e-17 -0.07 0.019"/>
  </joint>
  <link name="wheel2_attach_link"/>
  <joint name="wheel2_base_joint" type="fixed">
    <parent link="wheel2_attach_link"/>
    <child link="wheel2_base_link"/>
    <origin rpy="0 0 0" xyz="0 0 0"/>
  </joint>
  <link name="wheel2_base_link"/>
  <joint name="wheel2_motor_joint" type="fixed">
    <parent link="wheel2_base_link"/>
    <child link="wheel2_motor_body_link"/>
  </joint>
  <link name="wheel2_motor_body_link">
    <visual>
      <geometry>
        <mesh filename="model://omni_robot/meshes/ga25_body.stl"/>
      </geometry>
      <material name="gray"/>
    </visual>
    <collision>
      <origin rpy="0 1.5707963267948966 0" xyz="-0.025 0 0"/>
      <geometry>
        <cylinder length="0.05" radius="0.012"/>
      </geometry>
    </collision>
    <inertial>
      <mass value="0.150"/>
      <inertia ixx="0.0001" ixy="0" ixz="0" iyy="0.0001" iyz="0" izz="0.0001"/>
    </inertial>
  </link>
  <gazebo reference="wheel2_motor_body_link">
    <material>Gazebo/Gray</material>
  </gazebo>
  <joint name="wheel2_motor_shaft_joint" type="continuous">
    <parent link="wheel2_motor_body_link"/>
    <child link="wheel2_motor_shaft_link"/>
    <origin rpy="0 0 0" xyz="0.012 0 0"/>
    <axis xyz="1 0 0"/>
    <limit effort="3.0" velocity="40.0"/>
    <dynamics damping="0.01" friction="0.0"/>
  </joint>
  <transmission name="wheel2_motor_shaft_trans">
    <type>transmission_interface/SimpleTransmission</type>
    <joint name="wheel2_motor_shaft_joint">
      <hardwareInterface>hardware_interface/EffortJointInterface</hardwareInterface>
    </joint>
    <actuator name="wheel2_motor_shaft_motor">
      <hardwareInterface>hardware_interface/EffortJointInterface</hardwareInterface>
      <mechanicalReduction>1</mechanicalReduction>
    </actuator>
  </transmission>
  <link name="wheel2_motor_shaft_link">
    <visual>
      <geometry>
        <mesh filename="model://omni_robot/meshes/ga25_shaft.stl"/>
      </geometry>
      <material name="gray"/>
    </visual>
    <inertial>
      <mass value="0.010"/>
      <inertia ixx="0.0000005" ixy="0" ixz="0" iyy="0.000001" iyz="0" izz="0.000001"/>
    </inertial>
  </link>
  <gazebo reference="wheel2_motor_shaft_link">
    <material>Gazebo/Gray</material>
  </gazebo>
  <joint name="wheel2_housind_joint" type="fixed">
    <parent link="wheel2_motor_shaft_link"/>
    <child link="wheel2_housing_link"/>
    <origin rpy="0 1.5707963267948966 0" xyz="0.012 0 0"/>
  </joint>
  <link name="wheel2_housing_link">
    <visual>
      <geometry>
        <mesh filename="model://omni_robot/meshes/omni_housing.stl"/>
      </geometry>
      <origin rpy="0 0 0" xyz="0 0 0"/>
      <material name="gray"/>
    </visual>
    <inertial>
      <mass value="0.025"/>
      <inertia ixx="0.0001" ixy="0" ixz="0" iyy="0.0001" iyz="0" izz="0.0001"/>
    </inertial>
  </link>
  <gazebo reference="wheel2_housing_link">
    <material>Gazebo/Gray</material>
  </gazebo>
  <joint name="wheel2_housing_s_joint" type="fixed">
    <parent link="wheel2_housing_link"/>
    <child link="wheel2_housing_s_link"/>
    <origin rpy="0 3.141592653589793 0.7853981633974483" xyz="0 0 0"/>
  </joint>
  <link name="wheel2_housing_s_link">
    <inertial>
      <mass value="0.025"/>
      <inertia ixx="0.0001" ixy="0" ixz="0" iyy="0.0001" iyz="0" izz="0.0001"/>
    </inertial>
  </link>
  <joint name="wheel2_barrel_1_joint" type="continuous">
    <!-- continuous -->
    <parent link="wheel2_housing_link"/>
    <child link="wheel2_barrel_1_link"/>
    <origin rpy="1.5707963267948966 0 0" xyz="0.014 0.0 0.006"/>
    <axis xyz="0 0 1"/>
    <dynamics damping="0.001"/>
  </joint>
  <transmission name="wheel2_barrel_1_trans">
    <type>transmission_interface/SimpleTransmission</type>
    <joint name="wheel2_barrel_1_joint">
      <hardwareInterface>hardware_interface/EffortJointInterface</hardwareInterface>
    </joint>
    <actuator name="wheel2_barrel_1_motor">
      <hardwareInterface>hardware_interface/EffortJointInterface</hardwareInterface>
      <mechanicalReduction>1</mechanicalReduction>
    </actuator>
  </transmission>
  <link name="wheel2_barrel_1_link">
    <visual>
      <geometry>
        <mesh filename="model://omni_robot/meshes/omni_barrel.stl"/>
      </geometry>
      <material name="black"/>
    </visual>
    <collision>
      <geometry>
        <mesh filename="model://omni_robot/meshes/omni_barrel.stl"/>
      </geometry>
    </collision>
    <inertial>
      <mass value="0.002"/>
      <inertia ixx="0.000001" ixy="0" ixz="0" iyy="0.000001" iyz="0" izz="0.000001"/>
    </inertial>
  </link>
  <gazebo reference="wheel2_barrel_1_link">
    <mu1 value="2.5"/>
    <mu2 value="2.5"/>
    <kp value="5000"/>
    <kd value="10"/>
    <material>Gazebo/Black</material>
  </gazebo>
  <joint name="wheel2_barrel_1_mark_joint" type="fixed">
    <parent link="wheel2_barrel_1_link"/>
    <child link="wheel2_barrel_1_mark_link"/>
    <origin rpy="0 0 0" xyz="0.005 0 0"/>
  </joint>
  <link name="wheel2_barrel_1_mark_link">
    <visual>
      <geometry>
        <box size="0.005 0.005 0.005"/>
      </geometry>
      <material name="white"/>
    </visual>
  </link>
  <gazebo reference="wheel2_barrel_1_mark_link">
    <material>Gazebo/White</material>
  </gazebo>
  <joint name="wheel2_barrel_2_joint" type="continuous">
    <!-- continuous -->
    <parent link="wheel2_housing_link"/>
    <child link="wheel2_barrel_2_link"/>
    <origin rpy="1.5707963267948966 0 1.5707963267948966" xyz="8.572527594031473e-19 0.014 0.006"/>
    <axis xyz="0 0 1"/>
    <dynamics damping="0.001"/>
  </joint>
  <transmission name="wheel2_barrel_2_trans">
    <type>transmission_interface/SimpleTransmission</type>
    <joint name="wheel2_barrel_2_joint">
      <hardwareInterface>hardware_interface/EffortJointInterface</hardwareInterface>
    </joint>
    <actuator name="wheel2_barrel_2_motor">
      <hardwareInterface>hardware_interface/EffortJointInterface</hardwareInterface>
      <mechanicalReduction>1</mechanicalReduction>
    </actuator>
  </transmission>
  <link name="wheel2_barrel_2_link">
    <visual>
      <geometry>
        <mesh filename="model://omni_robot/meshes/omni_barrel.stl"/>
      </geometry>
      <material name="black"/>
    </visual>
    <collision>
      <geometry>
        <mesh filename="model://omni_robot/meshes/omni_barrel.stl"/>
      </geometry>
    </collision>
    <inertial>
      <mass value="0.002"/>
      <inertia ixx="0.000001" ixy="0" ixz="0" iyy="0.000001" iyz="0" izz="0.000001"/>
    </inertial>
  </link>
  <gazebo reference="wheel2_barrel_2_link">
    <mu1 value="2.5"/>
    <mu2 value="2.5"/>
    <kp value="5000"/>
    <kd value="10"/>
    <material>Gazebo/Black</material>
  </gazebo>
  <joint name="wheel2_barrel_2_mark_joint" type="fixed">
    <parent link="wheel2_barrel_2_link"/>
    <child link="wheel2_barrel_2_mark_link"/>
    <origin rpy="0 0 0" xyz="0.005 0 0"/>
  </joint>
  <link name="wheel2_barrel_2_mark_link">
    <visual>
      <geometry>
        <box size="0.005 0.005 0.005"/>
      </geometry>
      <material name="white"/>
    </visual>
  </link>
  <gazebo reference="wheel2_barrel_2_mark_link">
    <material>Gazebo/White</material>
  </gazebo>
  <joint name="wheel2_barrel_3_joint" type="continuous">
    <!-- continuous -->
    <parent link="wheel2_housing_link"/>
    <child link="wheel2_barrel_3_link"/>
    <origin rpy="1.5707963267948966 0 3.141592653589793" xyz="-0.014 1.7145055188062945e-18 0.006"/>
    <axis xyz="0 0 1"/>
    <dynamics damping="0.001"/>
  </joint>
  <transmission name="wheel2_barrel_3_trans">
    <type>transmission_interface/SimpleTransmission</type>
    <joint name="wheel2_barrel_3_joint">
      <hardwareInterface>hardware_interface/EffortJointInterface</hardwareInterface>
    </joint>
    <actuator name="wheel2_barrel_3_motor">
      <hardwareInterface>hardware_interface/EffortJointInterface</hardwareInterface>
      <mechanicalReduction>1</mechanicalReduction>
    </actuator>
  </transmission>
  <link name="wheel2_barrel_3_link">
    <visual>
      <geometry>
        <mesh filename="model://omni_robot/meshes/omni_barrel.stl"/>
      </geometry>
      <material name="black"/>
    </visual>
    <collision>
      <geometry>
        <mesh filename="model://omni_robot/meshes/omni_barrel.stl"/>
      </geometry>
    </collision>
    <inertial>
      <mass value="0.002"/>
      <inertia ixx="0.000001" ixy="0" ixz="0" iyy="0.000001" iyz="0" izz="0.000001"/>
    </inertial>
  </link>
  <gazebo reference="wheel2_barrel_3_link">
    <mu1 value="2.5"/>
    <mu2 value="2.5"/>
    <kp value="5000"/>
    <kd value="10"/>
    <material>Gazebo/Black</material>
  </gazebo>
  <joint name="wheel2_barrel_3_mark_joint" type="fixed">
    <parent link="wheel2_barrel_3_link"/>
    <child link="wheel2_barrel_3_mark_link"/>
    <origin rpy="0 0 0" xyz="0.005 0 0"/>
  </joint>
  <link name="wheel2_barrel_3_mark_link">
    <visual>
      <geometry>
        <box size="0.005 0.005 0.005"/>
      </geometry>
      <material name="white"/>
    </visual>
  </link>
  <gazebo reference="wheel2_barrel_3_mark_link">
    <material>Gazebo/White</material>
  </gazebo>
  <joint name="wheel2_barrel_4_joint" type="continuous">
    <!-- continuous -->
    <parent link="wheel2_housing_link"/>
    <child link="wheel2_barrel_4_link"/>
    <origin rpy="1.5707963267948966 0 -1.5707963267948966" xyz="8.572527594031473e-19 -0.014 0.006"/>
    <axis xyz="0 0 1"/>
    <dynamics damping="0.001"/>
  </joint>
  <transmission name="wheel2_barrel_4_trans">
    <type>transmission_interface/SimpleTransmission</type>
    <joint name="wheel2_barrel_4_joint">
      <hardwareInterface>hardware_interface/EffortJointInterface</hardwareInterface>
    </joint>
    <actuator name="wheel2_barrel_4_motor">
      <hardwareInterface>hardware_interface/EffortJointInterface</hardwareInterface>
      <mechanicalReduction>1</mechanicalReduction>
    </actuator>
  </transmission>
  <link name="wheel2_barrel_4_link">
    <visual>
      <geometry>
        <mesh filename="model://omni_robot/meshes/omni_barrel.stl"/>
      </geometry>
      <material name="black"/>
    </visual>
    <collision>
      <geometry>
        <mesh filename="model://omni_robot/meshes/omni_barrel.stl"/>
      </geometry>
    </collision>
    <inertial>
      <mass value="0.002"/>
      <inertia ixx="0.000001" ixy="0" ixz="0" iyy="0.000001" iyz="0" izz="0.000001"/>
    </inertial>
  </link>
  <gazebo reference="wheel2_barrel_4_link">
    <mu1 value="2.5"/>
    <mu2 value="2.5"/>
    <kp value="5000"/>
    <kd value="10"/>
    <material>Gazebo/Black</material>
  </gazebo>
  <joint name="wheel2_barrel_4_mark_joint" type="fixed">
    <parent link="wheel2_barrel_4_link"/>
    <child link="wheel2_barrel_4_mark_link"/>
    <origin rpy="0 0 0" xyz="0.005 0 0"/>
  </joint>
  <link name="wheel2_barrel_4_mark_link">
    <visual>
      <geometry>
        <box size="0.005 0.005 0.005"/>
      </geometry>
      <material name="white"/>
    </visual>
  </link>
  <gazebo reference="wheel2_barrel_4_mark_link">
    <material>Gazebo/White</material>
  </gazebo>
  <joint name="wheel2_barrel_5_joint" type="continuous">
    <!-- continuous -->
    <parent link="wheel2_housing_s_link"/>
    <child link="wheel2_barrel_5_link"/>
    <origin rpy="1.5707963267948966 0 0" xyz="0.014 0.0 0.006"/>
    <axis xyz="0 0 1"/>
    <dynamics damping="0.001"/>
  </joint>
  <transmission name="wheel2_barrel_5_trans">
    <type>transmission_interface/SimpleTransmission</type>
    <joint name="wheel2_barrel_5_joint">
      <hardwareInterface>hardware_interface/EffortJointInterface</hardwareInterface>
    </joint>
    <actuator name="wheel2_barrel_5_motor">
      <hardwareInterface>hardware_interface/EffortJointInterface</hardwareInterface>
      <mechanicalReduction>1</mechanicalReduction>
    </actuator>
  </transmission>
  <link name="wheel2_barrel_5_link">
    <visual>
      <geometry>
        <mesh filename="model://omni_robot/meshes/omni_barrel.stl"/>
      </geometry>
      <material name="black"/>
    </visual>
    <collision>
      <geometry>
        <mesh filename="model://omni_robot/meshes/omni_barrel.stl"/>
      </geometry>
    </collision>
    <inertial>
      <mass value="0.002"/>
      <inertia ixx="0.000001" ixy="0" ixz="0" iyy="0.000001" iyz="0" izz="0.000001"/>
    </inertial>
  </link>
  <gazebo reference="wheel2_barrel_5_link">
    <mu1 value="2.5"/>
    <mu2 value="2.5"/>
    <kp value="5000"/>
    <kd value="10"/>
    <material>Gazebo/Black</material>
  </gazebo>
  <joint name="wheel2_barrel_5_mark_joint" type="fixed">
    <parent link="wheel2_barrel_5_link"/>
    <child link="wheel2_barrel_5_mark_link"/>
    <origin rpy="0 0 0" xyz="0.005 0 0"/>
  </joint>
  <link name="wheel2_barrel_5_mark_link">
    <visual>
      <geometry>
        <box size="0.005 0.005 0.005"/>
      </geometry>
      <material name="white"/>
    </visual>
  </link>
  <gazebo reference="wheel2_barrel_5_mark_link">
    <material>Gazebo/White</material>
  </gazebo>
  <joint name="wheel2_barrel_6_joint" type="continuous">
    <!-- continuous -->
    <parent link="wheel2_housing_s_link"/>
    <child link="wheel2_barrel_6_link"/>
    <origin rpy="1.5707963267948966 0 1.5707963267948966" xyz="8.572527594031473e-19 0.014 0.006"/>
    <axis xyz="0 0 1"/>
    <dynamics damping="0.001"/>
  </joint>
  <transmission name="wheel2_barrel_6_trans">
    <type>transmission_interface/SimpleTransmission</type>
    <joint name="wheel2_barrel_6_joint">
      <hardwareInterface>hardware_interface/EffortJointInterface</hardwareInterface>
    </joint>
    <actuator name="wheel2_barrel_6_motor">
      <hardwareInterface>hardware_interface/EffortJointInterface</hardwareInterface>
      <mechanicalReduction>1</mechanicalReduction>
    </actuator>
  </transmission>
  <link name="wheel2_barrel_6_link">
    <visual>
      <geometry>
        <mesh filename="model://omni_robot/meshes/omni_barrel.stl"/>
      </geometry>
      <material name="black"/>
    </visual>
    <collision>
      <geometry>
        <mesh filename="model://omni_robot/meshes/omni_barrel.stl"/>
      </geometry>
    </collision>
    <inertial>
      <mass value="0.002"/>
      <inertia ixx="0.000001" ixy="0" ixz="0" iyy="0.000001" iyz="0" izz="0.000001"/>
    </inertial>
  </link>
  <gazebo reference="wheel2_barrel_6_link">
    <mu1 value="2.5"/>
    <mu2 value="2.5"/>
    <kp value="5000"/>
    <kd value="10"/>
    <material>Gazebo/Black</material>
  </gazebo>
  <joint name="wheel2_barrel_6_mark_joint" type="fixed">
    <parent link="wheel2_barrel_6_link"/>
    <child link="wheel2_barrel_6_mark_link"/>
    <origin rpy="0 0 0" xyz="0.005 0 0"/>
  </joint>
  <link name="wheel2_barrel_6_mark_link">
    <visual>
      <geometry>
        <box size="0.005 0.005 0.005"/>
      </geometry>
      <material name="white"/>
    </visual>
  </link>
  <gazebo reference="wheel2_barrel_6_mark_link">
    <material>Gazebo/White</material>
  </gazebo>
  <joint name="wheel2_barrel_7_joint" type="continuous">
    <!-- continuous -->
    <parent link="wheel2_housing_s_link"/>
    <child link="wheel2_barrel_7_link"/>
    <origin rpy="1.5707963267948966 0 3.141592653589793" xyz="-0.014 1.7145055188062945e-18 0.006"/>
    <axis xyz="0 0 1"/>
    <dynamics damping="0.001"/>
  </joint>
  <transmission name="wheel2_barrel_7_trans">
    <type>transmission_interface/SimpleTransmission</type>
    <joint name="wheel2_barrel_7_joint">
      <hardwareInterface>hardware_interface/EffortJointInterface</hardwareInterface>
    </joint>
    <actuator name="wheel2_barrel_7_motor">
      <hardwareInterface>hardware_interface/EffortJointInterface</hardwareInterface>
      <mechanicalReduction>1</mechanicalReduction>
    </actuator>
  </transmission>
  <link name="wheel2_barrel_7_link">
    <visual>
      <geometry>
        <mesh filename="model://omni_robot/meshes/omni_barrel.stl"/>
      </geometry>
      <material name="black"/>
    </visual>
    <collision>
      <geometry>
        <mesh filename="model://omni_robot/meshes/omni_barrel.stl"/>
      </geometry>
    </collision>
    <inertial>
      <mass value="0.002"/>
      <inertia ixx="0.000001" ixy="0" ixz="0" iyy="0.000001" iyz="0" izz="0.000001"/>
    </inertial>
  </link>
  <gazebo reference="wheel2_barrel_7_link">
    <mu1 value="2.5"/>
    <mu2 value="2.5"/>
    <kp value="5000"/>
    <kd value="10"/>
    <material>Gazebo/Black</material>
  </gazebo>
  <joint name="wheel2_barrel_7_mark_joint" type="fixed">
    <parent link="wheel2_barrel_7_link"/>
    <child link="wheel2_barrel_7_mark_link"/>
    <origin rpy="0 0 0" xyz="0.005 0 0"/>
  </joint>
  <link name="wheel2_barrel_7_mark_link">
    <visual>
      <geometry>
        <box size="0.005 0.005 0.005"/>
      </geometry>
      <material name="white"/>
    </visual>
  </link>
  <gazebo reference="wheel2_barrel_7_mark_link">
    <material>Gazebo/White</material>
  </gazebo>
  <joint name="wheel2_barrel_8_joint" type="continuous">
    <!-- continuous -->
    <parent link="wheel2_housing_s_link"/>
    <child link="wheel2_barrel_8_link"/>
    <origin rpy="1.5707963267948966 0 -1.5707963267948966" xyz="8.572527594031473e-19 -0.014 0.006"/>
    <axis xyz="0 0 1"/>
    <dynamics damping="0.001"/>
  </joint>
  <transmission name="wheel2_barrel_8_trans">
    <type>transmission_interface/SimpleTransmission</type>
    <joint name="wheel2_barrel_8_joint">
      <hardwareInterface>hardware_interface/EffortJointInterface</hardwareInterface>
    </joint>
    <actuator name="wheel2_barrel_8_motor">
      <hardwareInterface>hardware_interface/EffortJointInterface</hardwareInterface>
      <mechanicalReduction>1</mechanicalReduction>
    </actuator>
  </transmission>
  <link name="wheel2_barrel_8_link">
    <visual>
      <geometry>
        <mesh filename="model://omni_robot/meshes/omni_barrel.stl"/>
      </geometry>
      <material name="black"/>
    </visual>
    <collision>
      <geometry>
        <mesh filename="model://omni_robot/meshes/omni_barrel.stl"/>
      </geometry>
    </collision>
    <inertial>
      <mass value="0.002"/>
      <inertia ixx="0.000001" ixy="0" ixz="0" iyy="0.000001" iyz="0" izz="0.000001"/>
    </inertial>
  </link>
  <gazebo reference="wheel2_barrel_8_link">
    <mu1 value="2.5"/>
    <mu2 value="2.5"/>
    <kp value="5000"/>
    <kd value="10"/>
    <material>Gazebo/Black</material>
  </gazebo>
  <joint name="wheel2_barrel_8_mark_joint" type="fixed">
    <parent link="wheel2_barrel_8_link"/>
    <child link="wheel2_barrel_8_mark_link"/>
    <origin rpy="0 0 0" xyz="0.005 0 0"/>
  </joint>
  <link name="wheel2_barrel_8_mark_link">
    <visual>
      <geometry>
        <box size="0.005 0.005 0.005"/>
      </geometry>
      <material name="white"/>
    </visual>
  </link>
  <gazebo reference="wheel2_barrel_8_mark_link">
    <material>Gazebo/White</material>
  </gazebo>
  <joint name="wheel3_attach_joint" type="fixed">
    <parent link="base_link"/>
    <child link="wheel3_attach_link"/>
    <origin rpy="0 0 6.283185307179586" xyz="0.07 -1.7145055188062947e-17 0.019"/>
  </joint>
  <link name="wheel3_attach_link"/>
  <joint name="wheel3_base_joint" type="fixed">
    <parent link="wheel3_attach_link"/>
    <child link="wheel3_base_link"/>
    <origin rpy="0 0 0" xyz="0 0 0"/>
  </joint>
  <link name="wheel3_base_link"/>
  <joint name="wheel3_motor_joint" type="fixed">
    <parent link="wheel3_base_link"/>
    <child link="wheel3_motor_body_link"/>
  </joint>
  <link name="wheel3_motor_body_link">
    <visual>
      <geometry>
        <mesh filename="model://omni_robot/meshes/ga25_body.stl"/>
      </geometry>
      <material name="gray"/>
    </visual>
    <collision>
      <origin rpy="0 1.5707963267948966 0" xyz="-0.025 0 0"/>
      <geometry>
        <cylinder length="0.05" radius="0.012"/>
      </geometry>
    </collision>
    <inertial>
      <mass value="0.150"/>
      <inertia ixx="0.0001" ixy="0" ixz="0" iyy="0.0001" iyz="0" izz="0.0001"/>
    </inertial>
  </link>
  <gazebo reference="wheel3_motor_body_link">
    <material>Gazebo/Gray</material>
  </gazebo>
  <joint name="wheel3_motor_shaft_joint" type="continuous">
    <parent link="wheel3_motor_body_link"/>
    <child link="wheel3_motor_shaft_link"/>
    <origin rpy="0 0 0" xyz="0.012 0 0"/>
    <axis xyz="1 0 0"/>
    <limit effort="3.0" velocity="40.0"/>
    <dynamics damping="0.01" friction="0.0"/>
  </joint>
  <transmission name="wheel3_motor_shaft_trans">
    <type>transmission_interface/SimpleTransmission</type>
    <joint name="wheel3_motor_shaft_joint">
      <hardwareInterface>hardware_interface/EffortJointInterface</hardwareInterface>
    </joint>
    <actuator name="wheel3_motor_shaft_motor">
      <hardwareInterface>hardware_interface/EffortJointInterface</hardwareInterface>
      <mechanicalReduction>1</mechanicalReduction>
    </actuator>
  </transmission>
  <link name="wheel3_motor_shaft_link">
    <visual>
      <geometry>
        <mesh filename="model://omni_robot/meshes/ga25_shaft.stl"/>
      </geometry>
      <material name="gray"/>
    </visual>
    <inertial>
      <mass value="0.010"/>
      <inertia ixx="0.0000005" ixy="0" ixz="0" iyy="0.000001" iyz="0" izz="0.000001"/>
    </inertial>
  </link>
  <gazebo reference="wheel3_motor_shaft_link">
    <material>Gazebo/Gray</material>
  </gazebo>
  <joint name="wheel3_housind_joint" type="fixed">
    <parent link="wheel3_motor_shaft_link"/>
    <child link="wheel3_housing_link"/>
    <origin rpy="0 1.5707963267948966 0" xyz="0.012 0 0"/>
  </joint>
  <link name="wheel3_housing_link">
    <visual>
      <geometry>
        <mesh filename="model://omni_robot/meshes/omni_housing.stl"/>
      </geometry>
      <origin rpy="0 0 0" xyz="0 0 0"/>
      <material name="gray"/>
    </visual>
    <inertial>
      <mass value="0.025"/>
      <inertia ixx="0.0001" ixy="0" ixz="0" iyy="0.0001" iyz="0" izz="0.0001"/>
    </inertial>
  </link>
  <gazebo reference="wheel3_housing_link">
    <material>Gazebo/Gray</material>
  </gazebo>
  <joint name="wheel3_housing_s_joint" type="fixed">
    <parent link="wheel3_housing_link"/>
    <child link="wheel3_housing_s_link"/>
    <origin rpy="0 3.141592653589793 0.7853981633974483" xyz="0 0 0"/>
  </joint>
  <link name="wheel3_housing_s_link">
    <inertial>
      <mass value="0.025"/>
      <inertia ixx="0.0001" ixy="0" ixz="0" iyy="0.0001" iyz="0" izz="0.0001"/>
    </inertial>
  </link>
  <joint name="wheel3_barrel_1_joint" type="continuous">
    <!-- continuous -->
    <parent link="wheel3_housing_link"/>
    <child link="wheel3_barrel_1_link"/>
    <origin rpy="1.5707963267948966 0 0" xyz="0.014 0.0 0.006"/>
    <axis xyz="0 0 1"/>
    <dynamics damping="0.001"/>
  </joint>
  <transmission name="wheel3_barrel_1_trans">
    <type>transmission_interface/SimpleTransmission</type>
    <joint name="wheel3_barrel_1_joint">
      <hardwareInterface>hardware_interface/EffortJointInterface</hardwareInterface>
    </joint>
    <actuator name="wheel3_barrel_1_motor">
      <hardwareInterface>hardware_interface/EffortJointInterface</hardwareInterface>
      <mechanicalReduction>1</mechanicalReduction>
    </actuator>
  </transmission>
  <link name="wheel3_barrel_1_link">
    <visual>
      <geometry>
        <mesh filename="model://omni_robot/meshes/omni_barrel.stl"/>
      </geometry>
      <material name="black"/>
    </visual>
    <collision>
      <geometry>
        <mesh filename="model://omni_robot/meshes/omni_barrel.stl"/>
      </geometry>
    </collision>
    <inertial>
      <mass value="0.002"/>
      <inertia ixx="0.000001" ixy="0" ixz="0" iyy="0.000001" iyz="0" izz="0.000001"/>
    </inertial>
  </link>
  <gazebo reference="wheel3_barrel_1_link">
    <mu1 value="2.5"/>
    <mu2 value="2.5"/>
    <kp value="5000"/>
    <kd value="10"/>
    <material>Gazebo/Black</material>
  </gazebo>
  <joint name="wheel3_barrel_1_mark_joint" type="fixed">
    <parent link="wheel3_barrel_1_link"/>
    <child link="wheel3_barrel_1_mark_link"/>
    <origin rpy="0 0 0" xyz="0.005 0 0"/>
  </joint>
  <link name="wheel3_barrel_1_mark_link">
    <visual>
      <geometry>
        <box size="0.005 0.005 0.005"/>
      </geometry>
      <material name="white"/>
    </visual>
  </link>
  <gazebo reference="wheel3_barrel_1_mark_link">
    <material>Gazebo/White</material>
  </gazebo>
  <joint name="wheel3_barrel_2_joint" type="continuous">
    <!-- continuous -->
    <parent link="wheel3_housing_link"/>
    <child link="wheel3_barrel_2_link"/>
    <origin rpy="1.5707963267948966 0 1.5707963267948966" xyz="8.572527594031473e-19 0.014 0.006"/>
    <axis xyz="0 0 1"/>
    <dynamics damping="0.001"/>
  </joint>
  <transmission name="wheel3_barrel_2_trans">
    <type>transmission_interface/SimpleTransmission</type>
    <joint name="wheel3_barrel_2_joint">
      <hardwareInterface>hardware_interface/EffortJointInterface</hardwareInterface>
    </joint>
    <actuator name="wheel3_barrel_2_motor">
      <hardwareInterface>hardware_interface/EffortJointInterface</hardwareInterface>
      <mechanicalReduction>1</mechanicalReduction>
    </actuator>
  </transmission>
  <link name="wheel3_barrel_2_link">
    <visual>
      <geometry>
        <mesh filename="model://omni_robot/meshes/omni_barrel.stl"/>
      </geometry>
      <material name="black"/>
    </visual>
    <collision>
      <geometry>
        <mesh filename="model://omni_robot/meshes/omni_barrel.stl"/>
      </geometry>
    </collision>
    <inertial>
      <mass value="0.002"/>
      <inertia ixx="0.000001" ixy="0" ixz="0" iyy="0.000001" iyz="0" izz="0.000001"/>
    </inertial>
  </link>
  <gazebo reference="wheel3_barrel_2_link">
    <mu1 value="2.5"/>
    <mu2 value="2.5"/>
    <kp value="5000"/>
    <kd value="10"/>
    <material>Gazebo/Black</material>
  </gazebo>
  <joint name="wheel3_barrel_2_mark_joint" type="fixed">
    <parent link="wheel3_barrel_2_link"/>
    <child link="wheel3_barrel_2_mark_link"/>
    <origin rpy="0 0 0" xyz="0.005 0 0"/>
  </joint>
  <link name="wheel3_barrel_2_mark_link">
    <visual>
      <geometry>
        <box size="0.005 0.005 0.005"/>
      </geometry>
      <material name="white"/>
    </visual>
  </link>
  <gazebo reference="wheel3_barrel_2_mark_link">
    <material>Gazebo/White</material>
  </gazebo>
  <joint name="wheel3_barrel_3_joint" type="continuous">
    <!-- continuous -->
    <parent link="wheel3_housing_link"/>
    <child link="wheel3_barrel_3_link"/>
    <origin rpy="1.5707963267948966 0 3.141592653589793" xyz="-0.014 1.7145055188062945e-18 0.006"/>
    <axis xyz="0 0 1"/>
    <dynamics damping="0.001"/>
  </joint>
  <transmission name="wheel3_barrel_3_trans">
    <type>transmission_interface/SimpleTransmission</type>
    <joint name="wheel3_barrel_3_joint">
      <hardwareInterface>hardware_interface/EffortJointInterface</hardwareInterface>
    </joint>
    <actuator name="wheel3_barrel_3_motor">
      <hardwareInterface>hardware_interface/EffortJointInterface</hardwareInterface>
      <mechanicalReduction>1</mechanicalReduction>
    </actuator>
  </transmission>
  <link name="wheel3_barrel_3_link">
    <visual>
      <geometry>
        <mesh filename="model://omni_robot/meshes/omni_barrel.stl"/>
      </geometry>
      <material name="black"/>
    </visual>
    <collision>
      <geometry>
        <mesh filename="model://omni_robot/meshes/omni_barrel.stl"/>
      </geometry>
    </collision>
    <inertial>
      <mass value="0.002"/>
      <inertia ixx="0.000001" ixy="0" ixz="0" iyy="0.000001" iyz="0" izz="0.000001"/>
    </inertial>
  </link>
  <gazebo reference="wheel3_barrel_3_link">
    <mu1 value="2.5"/>
    <mu2 value="2.5"/>
    <kp value="5000"/>
    <kd value="10"/>
    <material>Gazebo/Black</material>
  </gazebo>
  <joint name="wheel3_barrel_3_mark_joint" type="fixed">
    <parent link="wheel3_barrel_3_link"/>
    <child link="wheel3_barrel_3_mark_link"/>
    <origin rpy="0 0 0" xyz="0.005 0 0"/>
  </joint>
  <link name="wheel3_barrel_3_mark_link">
    <visual>
      <geometry>
        <box size="0.005 0.005 0.005"/>
      </geometry>
      <material name="white"/>
    </visual>
  </link>
  <gazebo reference="wheel3_barrel_3_mark_link">
    <material>Gazebo/White</material>
  </gazebo>
  <joint name="wheel3_barrel_4_joint" type="continuous">
    <!-- continuous -->
    <parent link="wheel3_housing_link"/>
    <child link="wheel3_barrel_4_link"/>
    <origin rpy="1.5707963267948966 0 -1.5707963267948966" xyz="8.572527594031473e-19 -0.014 0.006"/>
    <axis xyz="0 0 1"/>
    <dynamics damping="0.001"/>
  </joint>
  <transmission name="wheel3_barrel_4_trans">
    <type>transmission_interface/SimpleTransmission</type>
    <joint name="wheel3_barrel_4_joint">
      <hardwareInterface>hardware_interface/EffortJointInterface</hardwareInterface>
    </joint>
    <actuator name="wheel3_barrel_4_motor">
      <hardwareInterface>hardware_interface/EffortJointInterface</hardwareInterface>
      <mechanicalReduction>1</mechanicalReduction>
    </actuator>
  </transmission>
  <link name="wheel3_barrel_4_link">
    <visual>
      <geometry>
        <mesh filename="model://omni_robot/meshes/omni_barrel.stl"/>
      </geometry>
      <material name="black"/>
    </visual>
    <collision>
      <geometry>
        <mesh filename="model://omni_robot/meshes/omni_barrel.stl"/>
      </geometry>
    </collision>
    <inertial>
      <mass value="0.002"/>
      <inertia ixx="0.000001" ixy="0" ixz="0" iyy="0.000001" iyz="0" izz="0.000001"/>
    </inertial>
  </link>
  <gazebo reference="wheel3_barrel_4_link">
    <mu1 value="2.5"/>
    <mu2 value="2.5"/>
    <kp value="5000"/>
    <kd value="10"/>
    <material>Gazebo/Black</material>
  </gazebo>
  <joint name="wheel3_barrel_4_mark_joint" type="fixed">
    <parent link="wheel3_barrel_4_link"/>
    <child link="wheel3_barrel_4_mark_link"/>
    <origin rpy="0 0 0" xyz="0.005 0 0"/>
  </joint>
  <link name="wheel3_barrel_4_mark_link">
    <visual>
      <geometry>
        <box size="0.005 0.005 0.005"/>
      </geometry>
      <material name="white"/>
    </visual>
  </link>
  <gazebo reference="wheel3_barrel_4_mark_link">
    <material>Gazebo/White</material>
  </gazebo>
  <joint name="wheel3_barrel_5_joint" type="continuous">
    <!-- continuous -->
    <parent link="wheel3_housing_s_link"/>
    <child link="wheel3_barrel_5_link"/>
    <origin rpy="1.5707963267948966 0 0" xyz="0.014 0.0 0.006"/>
    <axis xyz="0 0 1"/>
    <dynamics damping="0.001"/>
  </joint>
  <transmission name="wheel3_barrel_5_trans">
    <type>transmission_interface/SimpleTransmission</type>
    <joint name="wheel3_barrel_5_joint">
      <hardwareInterface>hardware_interface/EffortJointInterface</hardwareInterface>
    </joint>
    <actuator name="wheel3_barrel_5_motor">
      <hardwareInterface>hardware_interface/EffortJointInterface</hardwareInterface>
      <mechanicalReduction>1</mechanicalReduction>
    </actuator>
  </transmission>
  <link name="wheel3_barrel_5_link">
    <visual>
      <geometry>
        <mesh filename="model://omni_robot/meshes/omni_barrel.stl"/>
      </geometry>
      <material name="black"/>
    </visual>
    <collision>
      <geometry>
        <mesh filename="model://omni_robot/meshes/omni_barrel.stl"/>
      </geometry>
    </collision>
    <inertial>
      <mass value="0.002"/>
      <inertia ixx="0.000001" ixy="0" ixz="0" iyy="0.000001" iyz="0" izz="0.000001"/>
    </inertial>
  </link>
  <gazebo reference="wheel3_barrel_5_link">
    <mu1 value="2.5"/>
    <mu2 value="2.5"/>
    <kp value="5000"/>
    <kd value="10"/>
    <material>Gazebo/Black</material>
  </gazebo>
  <joint name="wheel3_barrel_5_mark_joint" type="fixed">
    <parent link="wheel3_barrel_5_link"/>
    <child link="wheel3_barrel_5_mark_link"/>
    <origin rpy="0 0 0" xyz="0.005 0 0"/>
  </joint>
  <link name="wheel3_barrel_5_mark_link">
    <visual>
      <geometry>
        <box size="0.005 0.005 0.005"/>
      </geometry>
      <material name="white"/>
    </visual>
  </link>
  <gazebo reference="wheel3_barrel_5_mark_link">
    <material>Gazebo/White</material>
  </gazebo>
  <joint name="wheel3_barrel_6_joint" type="continuous">
    <!-- continuous -->
    <parent link="wheel3_housing_s_link"/>
    <child link="wheel3_barrel_6_link"/>
    <origin rpy="1.5707963267948966 0 1.5707963267948966" xyz="8.572527594031473e-19 0.014 0.006"/>
    <axis xyz="0 0 1"/>
    <dynamics damping="0.001"/>
  </joint>
  <transmission name="wheel3_barrel_6_trans">
    <type>transmission_interface/SimpleTransmission</type>
    <joint name="wheel3_barrel_6_joint">
      <hardwareInterface>hardware_interface/EffortJointInterface</hardwareInterface>
    </joint>
    <actuator name="wheel3_barrel_6_motor">
      <hardwareInterface>hardware_interface/EffortJointInterface</hardwareInterface>
      <mechanicalReduction>1</mechanicalReduction>
    </actuator>
  </transmission>
  <link name="wheel3_barrel_6_link">
    <visual>
      <geometry>
        <mesh filename="model://omni_robot/meshes/omni_barrel.stl"/>
      </geometry>
      <material name="black"/>
    </visual>
    <collision>
      <geometry>
        <mesh filename="model://omni_robot/meshes/omni_barrel.stl"/>
      </geometry>
    </collision>
    <inertial>
      <mass value="0.002"/>
      <inertia ixx="0.000001" ixy="0" ixz="0" iyy="0.000001" iyz="0" izz="0.000001"/>
    </inertial>
  </link>
  <gazebo reference="wheel3_barrel_6_link">
    <mu1 value="2.5"/>
    <mu2 value="2.5"/>
    <kp value="5000"/>
    <kd value="10"/>
    <material>Gazebo/Black</material>
  </gazebo>
  <joint name="wheel3_barrel_6_mark_joint" type="fixed">
    <parent link="wheel3_barrel_6_link"/>
    <child link="wheel3_barrel_6_mark_link"/>
    <origin rpy="0 0 0" xyz="0.005 0 0"/>
  </joint>
  <link name="wheel3_barrel_6_mark_link">
    <visual>
      <geometry>
        <box size="0.005 0.005 0.005"/>
      </geometry>
      <material name="white"/>
    </visual>
  </link>
  <gazebo reference="wheel3_barrel_6_mark_link">
    <material>Gazebo/White</material>
  </gazebo>
  <joint name="wheel3_barrel_7_joint" type="continuous">
    <!-- continuous -->
    <parent link="wheel3_housing_s_link"/>
    <child link="wheel3_barrel_7_link"/>
    <origin rpy="1.5707963267948966 0 3.141592653589793" xyz="-0.014 1.7145055188062945e-18 0.006"/>
    <axis xyz="0 0 1"/>
    <dynamics damping="0.001"/>
  </joint>
  <transmission name="wheel3_barrel_7_trans">
    <type>transmission_interface/SimpleTransmission</type>
    <joint name="wheel3_barrel_7_joint">
      <hardwareInterface>hardware_interface/EffortJointInterface</hardwareInterface>
    </joint>
    <actuator name="wheel3_barrel_7_motor">
      <hardwareInterface>hardware_interface/EffortJointInterface</hardwareInterface>
      <mechanicalReduction>1</mechanicalReduction>
    </actuator>
  </transmission>
  <link name="wheel3_barrel_7_link">
    <visual>
      <geometry>
        <mesh filename="model://omni_robot/meshes/omni_barrel.stl"/>
      </geometry>
      <material name="black"/>
    </visual>
    <collision>
      <geometry>
        <mesh filename="model://omni_robot/meshes/omni_barrel.stl"/>
      </geometry>
    </collision>
    <inertial>
      <mass value="0.002"/>
      <inertia ixx="0.000001" ixy="0" ixz="0" iyy="0.000001" iyz="0" izz="0.000001"/>
    </inertial>
  </link>
  <gazebo reference="wheel3_barrel_7_link">
    <mu1 value="2.5"/>
    <mu2 value="2.5"/>
    <kp value="5000"/>
    <kd value="10"/>
    <material>Gazebo/Black</material>
  </gazebo>
  <joint name="wheel3_barrel_7_mark_joint" type="fixed">
    <parent link="wheel3_barrel_7_link"/>
    <child link="wheel3_barrel_7_mark_link"/>
    <origin rpy="0 0 0" xyz="0.005 0 0"/>
  </joint>
  <link name="wheel3_barrel_7_mark_link">
    <visual>
      <geometry>
        <box size="0.005 0.005 0.005"/>
      </geometry>
      <material name="white"/>
    </visual>
  </link>
  <gazebo reference="wheel3_barrel_7_mark_link">
    <material>Gazebo/White</material>
  </gazebo>
  <joint name="wheel3_barrel_8_joint" type="continuous">
    <!-- continuous -->
    <parent link="wheel3_housing_s_link"/>
    <child link="wheel3_barrel_8_link"/>
    <origin rpy="1.5707963267948966 0 -1.5707963267948966" xyz="8.572527594031473e-19 -0.014 0.006"/>
    <axis xyz="0 0 1"/>
    <dynamics damping="0.001"/>
  </joint>
  <transmission name="wheel3_barrel_8_trans">
    <type>transmission_interface/SimpleTransmission</type>
    <joint name="wheel3_barrel_8_joint">
      <hardwareInterface>hardware_interface/EffortJointInterface</hardwareInterface>
    </joint>
    <actuator name="wheel3_barrel_8_motor">
      <hardwareInterface>hardware_interface/EffortJointInterface</hardwareInterface>
      <mechanicalReduction>1</mechanicalReduction>
    </actuator>
  </transmission>
  <link name="wheel3_barrel_8_link">
    <visual>
      <geometry>
        <mesh filename="model://omni_robot/meshes/omni_barrel.stl"/>
      </geometry>
      <material name="black"/>
    </visual>
    <collision>
      <geometry>
        <mesh filename="model://omni_robot/meshes/omni_barrel.stl"/>
      </geometry>
    </collision>
    <inertial>
      <mass value="0.002"/>
      <inertia ixx="0.000001" ixy="0" ixz="0" iyy="0.000001" iyz="0" izz="0.000001"/>
    </inertial>
  </link>
  <gazebo reference="wheel3_barrel_8_link">
    <mu1 value="2.5"/>
    <mu2 value="2.5"/>
    <kp value="5000"/>
    <kd value="10"/>
    <material>Gazebo/Black</material>
  </gazebo>
  <joint name="wheel3_barrel_8_mark_joint" type="fixed">
    <parent link="wheel3_barrel_8_link"/>
    <child link="wheel3_barrel_8_mark_link"/>
    <origin rpy="0 0 0" xyz="0.005 0 0"/>
  </joint>
  <link name="wheel3_barrel_8_mark_link">
    <visual>
      <geometry>
        <box size="0.005 0.005 0.005"/>
      </geometry>
      <material name="white"/>
    </visual>
  </link>
  <gazebo reference="wheel3_barrel_8_mark_link">
    <material>Gazebo/White</material>
  </gazebo>
  <!-- ros2_control plugin config (keep velocity interfaces compatible with existing controllers) -->
  <ros2_control name="GazeboSystem" type="system">
    <hardware>
      <plugin>gz_ros2_control/GazeboSimSystem</plugin>
    </hardware>
    <joint name="wheel0_motor_shaft_joint">
      <command_interface name="velocity"/>
      <state_interface name="position"/>
      <state_interface name="velocity"/>
    </joint>
    <joint name="wheel1_motor_shaft_joint">
      <command_interface name="velocity"/>
      <state_interface name="position"/>
      <state_interface name="velocity"/>
    </joint>
    <joint name="wheel2_motor_shaft_joint">
      <command_interface name="velocity"/>
      <state_interface name="position"/>
      <state_interface name="velocity"/>
    </joint>
    <joint name="wheel3_motor_shaft_joint">
      <command_interface name="velocity"/>
      <state_interface name="position"/>
      <state_interface name="velocity"/>
    </joint>
  </ros2_control>
  <gazebo>
    <plugin filename="libgz_ros2_control-system.so" name="gz_ros2_control::GazeboSimROS2ControlPlugin">
      <parameters>/home/hao/Ubuntu_3/Private/simulator/ros2_ws/install/gazebo_simulator/share/gazebo_simulator/config/controller_omni_robot.yaml</parameters>
    </plugin>
  </gazebo>
</robot>
