<?xml version="1.0"?>
<robot xmlns:xacro="http://ros.org/wiki/xacro">
    <!--barrel macro-->
    <xacro:macro name="barrel" params="prefix parent dir">
        <joint name="${prefix}_joint" type="continuous">
            <parent link="${parent}"/>
            <child link="${prefix}_link"/>
            <origin rpy="${pi/2} 0 ${dir}" xyz="${0.036842105*cos(dir)} ${0.036842105*sin(dir)} 0.015789474"/>
            <axis xyz="0 0 1"/>
            <dynamics damping="0.001"/>
        </joint>
        <link name="${prefix}_link">
            <visual>
                <geometry>
                    <mesh filename="model://omni_2024/meshes/omni_barrel100.stl" />
                </geometry>
            </visual>
            <collision>
                <geometry>
                    <mesh filename="model://omni_2024/meshes/omni_barrel100.stl" />
                </geometry>
            </collision>
            <inertial>
                <mass value="0.004"/>
                <inertia ixx="0.000001" ixy="0" ixz="0" iyy="0.000001" iyz="0" izz="0.000001"/>
            </inertial>
        </link>
        <gazebo reference="${prefix}_link">
            <mu1 value="5" />
            <mu2 value="5" />
            <kp value="7500" />
            <kd value="20" />
            <material>Gazebo/Black</material>
        </gazebo>
    </xacro:macro>

    <!--here-->
    <xacro:macro name="omni100" params="prefix parent xyz rpy">
        <joint name="${prefix}_base_joint" type="fixed">
            <parent link="${parent}"/>
            <child link="${prefix}_base_link"/>
            <origin xyz="${xyz}" rpy="${rpy}"/>
        </joint>
        <link name="${prefix}_base_link">
            <inertial>
                <mass value="0.010"/>
                <inertia ixx="0.0001" ixy="0" ixz="0" iyy="0.0001" iyz="0" izz="0.0001"/>
            </inertial>
        </link>

        <!--Suspension-->
        <joint name="${prefix}_sus_joint" type="prismatic">
            <parent link="${prefix}_base_link"/>
            <child link="${prefix}_sus_link"/>
            <limit lower="-0.04" upper="0.04" effort="100" velocity="1.0" />
            <axis xyz="0 0 1"/>
            <origin xyz="0 0 0" rpy="0 0 0"/>
            <dynamics damping="0.01"/>
        </joint>

        <gazebo reference="${prefix}_sus_joint">
            <kp>50000</kp>
            <kd>500</kd>
        </gazebo>
        <link name="${prefix}_sus_link">
            <inertial>
                <mass value="0.020"/>
                <inertia ixx="0.00001" ixy="0.0" ixz="0.0" iyy="0.00001" iyz="0.0" izz="0.00001"/>
            </inertial>
        </link>

        <joint name="${prefix}_joint" type="continuous">
            <origin xyz="0 0 0" rpy="0 ${radians(90)} 0"/>
            <parent link="${prefix}_sus_link"/>
            <child link="${prefix}_housing_link"/>
            <axis xyz="0 0 1" />
            <!--M3508 1:19-->
            <limit effort="4.6" velocity="61"/>
            <joint_properties damping="0.01" friction="0.01" />
        </joint>

        <link name="${prefix}_housing_link">
            <visual>
                <origin xyz="0 0 0" rpy="0 0 0"/>
                <geometry>
                    <mesh filename="model://omni_2024/meshes/omni_housing100.stl" />
                </geometry>
            </visual>
            <inertial>
                <mass value="0.05"/>
                <inertia ixx="0.00001" ixy="0" ixz="0" iyy="0.00001" iyz="0" izz="0.00001"/>
            </inertial>
        </link>
        <gazebo reference="${prefix}_housing_link">
            <material>Gazebo/Gray</material>
        </gazebo>

        <joint name="${prefix}_housing_s_joint" type="fixed">
            <parent link="${prefix}_housing_link"/>
            <child link="${prefix}_housing_s_link"/>
            <origin rpy="0 ${pi} ${pi/4}" xyz="0 0 0"/>
        </joint>
        <link name="${prefix}_housing_s_link">
            <inertial>
                <mass value="0.05"/>
                <inertia ixx="0.0001" ixy="0" ixz="0" iyy="0.0001" iyz="0" izz="0.0001"/>
            </inertial>
        </link>

        <xacro:barrel prefix="${prefix}_barrel_1" parent="${prefix}_housing_link" dir="0"/>
        <xacro:barrel prefix="${prefix}_barrel_2" parent="${prefix}_housing_link" dir="${pi/2}"/>
        <xacro:barrel prefix="${prefix}_barrel_3" parent="${prefix}_housing_link" dir="${pi}"/>
        <xacro:barrel prefix="${prefix}_barrel_4" parent="${prefix}_housing_link" dir="${-pi/2}"/>
        <xacro:barrel prefix="${prefix}_barrel_5" parent="${prefix}_housing_s_link" dir="0"/>
        <xacro:barrel prefix="${prefix}_barrel_6" parent="${prefix}_housing_s_link" dir="${pi/2}"/>
        <xacro:barrel prefix="${prefix}_barrel_7" parent="${prefix}_housing_s_link" dir="${pi}"/>
        <xacro:barrel prefix="${prefix}_barrel_8" parent="${prefix}_housing_s_link" dir="${-pi/2}"/>
    </xacro:macro>
</robot>
