<?xml version="1.0" ?>
<!-- =================================================================================== -->
<!-- |    This document was autogenerated by xacro from /home/hao/Ubuntu_3/Private/simulator/ros2_ws/src/gazebo_simulator/models/omni_2024/urdf/omni_2024.xacro | -->
<!-- |    EDITING THIS FILE BY HAND IS NOT RECOMMENDED                                 | -->
<!-- =================================================================================== -->
<robot name="omni_4wheel">
  <!--roslaunch urdf_tutorial display.launch model:=omni_4wheel.xacro-->
  <!--Don't write Japanese-->
  <link name="base_link"/>
  <joint name="body_joint" type="fixed">
    <parent link="base_link"/>
    <child link="func_link"/>
    <origin rpy="0 0 0" xyz="0 0 0.15"/>
  </joint>
  <link name="func_link">
    <inertial>
      <origin rpy="0 0 0" xyz="0 0 0"/>
      <mass value="15"/>
      <inertia ixx="0.425" ixy="0.0" ixz="0.0" iyy="0.425" iyz="0.0" izz="0.625"/>
    </inertial>
    <visual>
      <geometry>
        <box size="0.50 0.50 0.10"/>
      </geometry>
    </visual>
    <collision>
      <geometry>
        <box size="0.0 0.0 0.0"/>
      </geometry>
    </collision>
  </link>
  <gazebo reference="func_link">
    <material>Gazebo/OrangeTransparentOverlay</material>
  </gazebo>
  <joint name="imu_joint" type="fixed">
    <parent link="base_link"/>
    <child link="imu_link"/>
    <origin rpy="0 0 0" xyz="0 0 0"/>
  </joint>
  <link name="imu_link"/>
  <gazebo reference="imu_link">
    <sensor name="gazebo_imu" type="imu">
      <gravity>true</gravity>
      <visualize>true</visualize>
      <update_rate>60</update_rate>
      <always_on>true</always_on>
      <plugin filename="libgazebo_ros_imu_sensor.so" name="imu_plugin">
        <ros>
          <!--namespace>/robot</namespace-->
          <remapping>~/out:=imu</remapping>
        </ros>
        <initial_orientation_as_reference>false</initial_orientation_as_reference>
        <output_type>sensor_msgs/Imu</output_type>
        <frame_name>imu_link</frame_name>
      </plugin>
      <imu>
        <angular_velocity>
          <x>
            <noise type="gaussian">
              <mean>0.0</mean>
              <stddev>2e-04</stddev>
              <bias_mean>0.0000075</bias_mean>
              <bias_stddev>0.0000008</bias_stddev>
            </noise>
          </x>
          <y>
            <nosie type="gaussian">
              <mean>0.0</mean>
              <stddev>2e-04</stddev>
              <bias_mean>0.0000075</bias_mean>
              <bias_stddev>0.0000008</bias_stddev>
            </nosie>
          </y>
          <z>
            <nosie type="gaussian">
              <mean>0.0</mean>
              <stddev>2e-04</stddev>
              <bias_mean>0.0000075</bias_mean>
              <bias_stddev>0.0000008</bias_stddev>
            </nosie>
          </z>
        </angular_velocity>
        <linear_acceleration>
          <x>
            <nosie type="gaussian">
              <mean>0.0</mean>
              <stddev>1.7e-02</stddev>
              <bias_mean>0.001</bias_mean>
              <bias_stddev>0.001</bias_stddev>
            </nosie>
          </x>
          <y>
            <nosie type="gaussian">
              <mean>0.0</mean>
              <stddev>1.7e-02</stddev>
              <bias_mean>0.001</bias_mean>
              <bias_stddev>0.001</bias_stddev>
            </nosie>
          </y>
          <z>
            <nosie type="gaussian">
              <mean>0.0</mean>
              <stddev>1.7e-02</stddev>
              <bias_mean>0.001</bias_mean>
              <bias_stddev>0.001</bias_stddev>
            </nosie>
          </z>
        </linear_acceleration>
      </imu>
    </sensor>
  </gazebo>
  <joint name="laser_joint" type="fixed">
    <parent link="base_link"/>
    <child link="laser_link"/>
    <origin rpy="0 0 -3.141592653589793" xyz="0 -0.22 0.005"/>
  </joint>
  <link name="laser_link">
    <visual>
      <origin rpy="0 0 0" xyz="0 0 0.035"/>
      <geometry>
        <cylinder length="0.07" radius="0.02"/>
      </geometry>
    </visual>
    <collision>
      <origin rpy="0 0 0" xyz="0 0 0.035"/>
      <geometry>
        <cylinder length="0.0" radius="0.0"/>
      </geometry>
    </collision>
  </link>
  <gazebo reference="laser_link">
    <material>Gazebo/Red</material>
    <sensor name="laser" type="ray">
      <pose>0 0 0.0474 0 0 0</pose>
      <always_on>true</always_on>
      <visualize>true</visualize>
      <update_rate>60</update_rate>
      <plugin filename="libgazebo_ros_ray_sensor.so" name="gazebo_lidar">
        <ros>
          <remapping>~/out:=scan</remapping>
        </ros>
        <output_type>sensor_msgs/LaserScan</output_type>
        <frame_name>laser_link</frame_name>
      </plugin>
      <ray>
        <scan>
          <horizontal>
            <samples>1440</samples>
            <resolution>1</resolution>
            <min_angle>-1.4</min_angle>
            <max_angle>0</max_angle>
          </horizontal>
        </scan>
        <range>
          <min>0.10</min>
          <max>20.0</max>
          <resolution>0.01</resolution>
        </range>
        <noise>
          <type>gaussian</type>
          <mean>0.0</mean>
          <stddev>0.01</stddev>
        </noise>
      </ray>
    </sensor>
  </gazebo>
  <joint name="wheel0_base_joint" type="fixed">
    <parent link="base_link"/>
    <child link="wheel0_base_link"/>
    <origin rpy="0 0 0.7853981633974483" xyz="0.1364716087690037 0.13647160876900366 0.05"/>
  </joint>
  <link name="wheel0_base_link">
    <inertial>
      <mass value="0.010"/>
      <inertia ixx="0.0001" ixy="0" ixz="0" iyy="0.0001" iyz="0" izz="0.0001"/>
    </inertial>
  </link>
  <!--Suspension-->
  <joint name="wheel0_sus_joint" type="prismatic">
    <parent link="wheel0_base_link"/>
    <child link="wheel0_sus_link"/>
    <limit effort="100" lower="-0.04" upper="0.04" velocity="1.0"/>
    <axis xyz="0 0 1"/>
    <origin rpy="0 0 0" xyz="0 0 0"/>
    <dynamics damping="0.01"/>
  </joint>
  <gazebo reference="wheel0_sus_joint">
    <kp>50000</kp>
    <kd>500</kd>
  </gazebo>
  <link name="wheel0_sus_link">
    <inertial>
      <mass value="0.020"/>
      <inertia ixx="0.00001" ixy="0.0" ixz="0.0" iyy="0.00001" iyz="0.0" izz="0.00001"/>
    </inertial>
  </link>
  <joint name="wheel0_joint" type="continuous">
    <origin rpy="0 1.5707963267948966 0" xyz="0 0 0"/>
    <parent link="wheel0_sus_link"/>
    <child link="wheel0_housing_link"/>
    <axis xyz="0 0 1"/>
    <!--M3508 1:19-->
    <limit effort="4.6" velocity="61"/>
    <joint_properties damping="0.01" friction="0.01"/>
  </joint>
  <link name="wheel0_housing_link">
    <visual>
      <origin rpy="0 0 0" xyz="0 0 0"/>
      <geometry>
        <mesh filename="model://omni_2024/meshes/omni_housing100.stl"/>
      </geometry>
    </visual>
    <inertial>
      <mass value="0.05"/>
      <inertia ixx="0.00001" ixy="0" ixz="0" iyy="0.00001" iyz="0" izz="0.00001"/>
    </inertial>
  </link>
  <gazebo reference="wheel0_housing_link">
    <material>Gazebo/Gray</material>
  </gazebo>
  <joint name="wheel0_housing_s_joint" type="fixed">
    <parent link="wheel0_housing_link"/>
    <child link="wheel0_housing_s_link"/>
    <origin rpy="0 3.141592653589793 0.7853981633974483" xyz="0 0 0"/>
  </joint>
  <link name="wheel0_housing_s_link">
    <inertial>
      <mass value="0.05"/>
      <inertia ixx="0.0001" ixy="0" ixz="0" iyy="0.0001" iyz="0" izz="0.0001"/>
    </inertial>
  </link>
  <joint name="wheel0_barrel_1_joint" type="continuous">
    <parent link="wheel0_housing_link"/>
    <child link="wheel0_barrel_1_link"/>
    <origin rpy="1.5707963267948966 0 0" xyz="0.036842105 0.0 0.015789474"/>
    <axis xyz="0 0 1"/>
    <dynamics damping="0.001"/>
  </joint>
  <link name="wheel0_barrel_1_link">
    <visual>
      <geometry>
        <mesh filename="model://omni_2024/meshes/omni_barrel100.stl"/>
      </geometry>
    </visual>
    <collision>
      <geometry>
        <mesh filename="model://omni_2024/meshes/omni_barrel100.stl"/>
      </geometry>
    </collision>
    <inertial>
      <mass value="0.004"/>
      <inertia ixx="0.000001" ixy="0" ixz="0" iyy="0.000001" iyz="0" izz="0.000001"/>
    </inertial>
  </link>
  <gazebo reference="wheel0_barrel_1_link">
    <mu1 value="5"/>
    <mu2 value="5"/>
    <kp value="7500"/>
    <kd value="20"/>
    <material>Gazebo/Black</material>
  </gazebo>
  <joint name="wheel0_barrel_2_joint" type="continuous">
    <parent link="wheel0_housing_link"/>
    <child link="wheel0_barrel_2_link"/>
    <origin rpy="1.5707963267948966 0 1.5707963267948966" xyz="2.2559282981050347e-18 0.036842105 0.015789474"/>
    <axis xyz="0 0 1"/>
    <dynamics damping="0.001"/>
  </joint>
  <link name="wheel0_barrel_2_link">
    <visual>
      <geometry>
        <mesh filename="model://omni_2024/meshes/omni_barrel100.stl"/>
      </geometry>
    </visual>
    <collision>
      <geometry>
        <mesh filename="model://omni_2024/meshes/omni_barrel100.stl"/>
      </geometry>
    </collision>
    <inertial>
      <mass value="0.004"/>
      <inertia ixx="0.000001" ixy="0" ixz="0" iyy="0.000001" iyz="0" izz="0.000001"/>
    </inertial>
  </link>
  <gazebo reference="wheel0_barrel_2_link">
    <mu1 value="5"/>
    <mu2 value="5"/>
    <kp value="7500"/>
    <kd value="20"/>
    <material>Gazebo/Black</material>
  </gazebo>
  <joint name="wheel0_barrel_3_joint" type="continuous">
    <parent link="wheel0_housing_link"/>
    <child link="wheel0_barrel_3_link"/>
    <origin rpy="1.5707963267948966 0 3.141592653589793" xyz="-0.036842105 4.5118565962100695e-18 0.015789474"/>
    <axis xyz="0 0 1"/>
    <dynamics damping="0.001"/>
  </joint>
  <link name="wheel0_barrel_3_link">
    <visual>
      <geometry>
        <mesh filename="model://omni_2024/meshes/omni_barrel100.stl"/>
      </geometry>
    </visual>
    <collision>
      <geometry>
        <mesh filename="model://omni_2024/meshes/omni_barrel100.stl"/>
      </geometry>
    </collision>
    <inertial>
      <mass value="0.004"/>
      <inertia ixx="0.000001" ixy="0" ixz="0" iyy="0.000001" iyz="0" izz="0.000001"/>
    </inertial>
  </link>
  <gazebo reference="wheel0_barrel_3_link">
    <mu1 value="5"/>
    <mu2 value="5"/>
    <kp value="7500"/>
    <kd value="20"/>
    <material>Gazebo/Black</material>
  </gazebo>
  <joint name="wheel0_barrel_4_joint" type="continuous">
    <parent link="wheel0_housing_link"/>
    <child link="wheel0_barrel_4_link"/>
    <origin rpy="1.5707963267948966 0 -1.5707963267948966" xyz="2.2559282981050347e-18 -0.036842105 0.015789474"/>
    <axis xyz="0 0 1"/>
    <dynamics damping="0.001"/>
  </joint>
  <link name="wheel0_barrel_4_link">
    <visual>
      <geometry>
        <mesh filename="model://omni_2024/meshes/omni_barrel100.stl"/>
      </geometry>
    </visual>
    <collision>
      <geometry>
        <mesh filename="model://omni_2024/meshes/omni_barrel100.stl"/>
      </geometry>
    </collision>
    <inertial>
      <mass value="0.004"/>
      <inertia ixx="0.000001" ixy="0" ixz="0" iyy="0.000001" iyz="0" izz="0.000001"/>
    </inertial>
  </link>
  <gazebo reference="wheel0_barrel_4_link">
    <mu1 value="5"/>
    <mu2 value="5"/>
    <kp value="7500"/>
    <kd value="20"/>
    <material>Gazebo/Black</material>
  </gazebo>
  <joint name="wheel0_barrel_5_joint" type="continuous">
    <parent link="wheel0_housing_s_link"/>
    <child link="wheel0_barrel_5_link"/>
    <origin rpy="1.5707963267948966 0 0" xyz="0.036842105 0.0 0.015789474"/>
    <axis xyz="0 0 1"/>
    <dynamics damping="0.001"/>
  </joint>
  <link name="wheel0_barrel_5_link">
    <visual>
      <geometry>
        <mesh filename="model://omni_2024/meshes/omni_barrel100.stl"/>
      </geometry>
    </visual>
    <collision>
      <geometry>
        <mesh filename="model://omni_2024/meshes/omni_barrel100.stl"/>
      </geometry>
    </collision>
    <inertial>
      <mass value="0.004"/>
      <inertia ixx="0.000001" ixy="0" ixz="0" iyy="0.000001" iyz="0" izz="0.000001"/>
    </inertial>
  </link>
  <gazebo reference="wheel0_barrel_5_link">
    <mu1 value="5"/>
    <mu2 value="5"/>
    <kp value="7500"/>
    <kd value="20"/>
    <material>Gazebo/Black</material>
  </gazebo>
  <joint name="wheel0_barrel_6_joint" type="continuous">
    <parent link="wheel0_housing_s_link"/>
    <child link="wheel0_barrel_6_link"/>
    <origin rpy="1.5707963267948966 0 1.5707963267948966" xyz="2.2559282981050347e-18 0.036842105 0.015789474"/>
    <axis xyz="0 0 1"/>
    <dynamics damping="0.001"/>
  </joint>
  <link name="wheel0_barrel_6_link">
    <visual>
      <geometry>
        <mesh filename="model://omni_2024/meshes/omni_barrel100.stl"/>
      </geometry>
    </visual>
    <collision>
      <geometry>
        <mesh filename="model://omni_2024/meshes/omni_barrel100.stl"/>
      </geometry>
    </collision>
    <inertial>
      <mass value="0.004"/>
      <inertia ixx="0.000001" ixy="0" ixz="0" iyy="0.000001" iyz="0" izz="0.000001"/>
    </inertial>
  </link>
  <gazebo reference="wheel0_barrel_6_link">
    <mu1 value="5"/>
    <mu2 value="5"/>
    <kp value="7500"/>
    <kd value="20"/>
    <material>Gazebo/Black</material>
  </gazebo>
  <joint name="wheel0_barrel_7_joint" type="continuous">
    <parent link="wheel0_housing_s_link"/>
    <child link="wheel0_barrel_7_link"/>
    <origin rpy="1.5707963267948966 0 3.141592653589793" xyz="-0.036842105 4.5118565962100695e-18 0.015789474"/>
    <axis xyz="0 0 1"/>
    <dynamics damping="0.001"/>
  </joint>
  <link name="wheel0_barrel_7_link">
    <visual>
      <geometry>
        <mesh filename="model://omni_2024/meshes/omni_barrel100.stl"/>
      </geometry>
    </visual>
    <collision>
      <geometry>
        <mesh filename="model://omni_2024/meshes/omni_barrel100.stl"/>
      </geometry>
    </collision>
    <inertial>
      <mass value="0.004"/>
      <inertia ixx="0.000001" ixy="0" ixz="0" iyy="0.000001" iyz="0" izz="0.000001"/>
    </inertial>
  </link>
  <gazebo reference="wheel0_barrel_7_link">
    <mu1 value="5"/>
    <mu2 value="5"/>
    <kp value="7500"/>
    <kd value="20"/>
    <material>Gazebo/Black</material>
  </gazebo>
  <joint name="wheel0_barrel_8_joint" type="continuous">
    <parent link="wheel0_housing_s_link"/>
    <child link="wheel0_barrel_8_link"/>
    <origin rpy="1.5707963267948966 0 -1.5707963267948966" xyz="2.2559282981050347e-18 -0.036842105 0.015789474"/>
    <axis xyz="0 0 1"/>
    <dynamics damping="0.001"/>
  </joint>
  <link name="wheel0_barrel_8_link">
    <visual>
      <geometry>
        <mesh filename="model://omni_2024/meshes/omni_barrel100.stl"/>
      </geometry>
    </visual>
    <collision>
      <geometry>
        <mesh filename="model://omni_2024/meshes/omni_barrel100.stl"/>
      </geometry>
    </collision>
    <inertial>
      <mass value="0.004"/>
      <inertia ixx="0.000001" ixy="0" ixz="0" iyy="0.000001" iyz="0" izz="0.000001"/>
    </inertial>
  </link>
  <gazebo reference="wheel0_barrel_8_link">
    <mu1 value="5"/>
    <mu2 value="5"/>
    <kp value="7500"/>
    <kd value="20"/>
    <material>Gazebo/Black</material>
  </gazebo>
  <joint name="wheel1_base_joint" type="fixed">
    <parent link="base_link"/>
    <child link="wheel1_base_link"/>
    <origin rpy="0 0 2.356194490192345" xyz="-0.13647160876900366 0.1364716087690037 0.05"/>
  </joint>
  <link name="wheel1_base_link">
    <inertial>
      <mass value="0.010"/>
      <inertia ixx="0.0001" ixy="0" ixz="0" iyy="0.0001" iyz="0" izz="0.0001"/>
    </inertial>
  </link>
  <!--Suspension-->
  <joint name="wheel1_sus_joint" type="prismatic">
    <parent link="wheel1_base_link"/>
    <child link="wheel1_sus_link"/>
    <limit effort="100" lower="-0.04" upper="0.04" velocity="1.0"/>
    <axis xyz="0 0 1"/>
    <origin rpy="0 0 0" xyz="0 0 0"/>
    <dynamics damping="0.01"/>
  </joint>
  <gazebo reference="wheel1_sus_joint">
    <kp>50000</kp>
    <kd>500</kd>
  </gazebo>
  <link name="wheel1_sus_link">
    <inertial>
      <mass value="0.020"/>
      <inertia ixx="0.00001" ixy="0.0" ixz="0.0" iyy="0.00001" iyz="0.0" izz="0.00001"/>
    </inertial>
  </link>
  <joint name="wheel1_joint" type="continuous">
    <origin rpy="0 1.5707963267948966 0" xyz="0 0 0"/>
    <parent link="wheel1_sus_link"/>
    <child link="wheel1_housing_link"/>
    <axis xyz="0 0 1"/>
    <!--M3508 1:19-->
    <limit effort="4.6" velocity="61"/>
    <joint_properties damping="0.01" friction="0.01"/>
  </joint>
  <link name="wheel1_housing_link">
    <visual>
      <origin rpy="0 0 0" xyz="0 0 0"/>
      <geometry>
        <mesh filename="model://omni_2024/meshes/omni_housing100.stl"/>
      </geometry>
    </visual>
    <inertial>
      <mass value="0.05"/>
      <inertia ixx="0.00001" ixy="0" ixz="0" iyy="0.00001" iyz="0" izz="0.00001"/>
    </inertial>
  </link>
  <gazebo reference="wheel1_housing_link">
    <material>Gazebo/Gray</material>
  </gazebo>
  <joint name="wheel1_housing_s_joint" type="fixed">
    <parent link="wheel1_housing_link"/>
    <child link="wheel1_housing_s_link"/>
    <origin rpy="0 3.141592653589793 0.7853981633974483" xyz="0 0 0"/>
  </joint>
  <link name="wheel1_housing_s_link">
    <inertial>
      <mass value="0.05"/>
      <inertia ixx="0.0001" ixy="0" ixz="0" iyy="0.0001" iyz="0" izz="0.0001"/>
    </inertial>
  </link>
  <joint name="wheel1_barrel_1_joint" type="continuous">
    <parent link="wheel1_housing_link"/>
    <child link="wheel1_barrel_1_link"/>
    <origin rpy="1.5707963267948966 0 0" xyz="0.036842105 0.0 0.015789474"/>
    <axis xyz="0 0 1"/>
    <dynamics damping="0.001"/>
  </joint>
  <link name="wheel1_barrel_1_link">
    <visual>
      <geometry>
        <mesh filename="model://omni_2024/meshes/omni_barrel100.stl"/>
      </geometry>
    </visual>
    <collision>
      <geometry>
        <mesh filename="model://omni_2024/meshes/omni_barrel100.stl"/>
      </geometry>
    </collision>
    <inertial>
      <mass value="0.004"/>
      <inertia ixx="0.000001" ixy="0" ixz="0" iyy="0.000001" iyz="0" izz="0.000001"/>
    </inertial>
  </link>
  <gazebo reference="wheel1_barrel_1_link">
    <mu1 value="5"/>
    <mu2 value="5"/>
    <kp value="7500"/>
    <kd value="20"/>
    <material>Gazebo/Black</material>
  </gazebo>
  <joint name="wheel1_barrel_2_joint" type="continuous">
    <parent link="wheel1_housing_link"/>
    <child link="wheel1_barrel_2_link"/>
    <origin rpy="1.5707963267948966 0 1.5707963267948966" xyz="2.2559282981050347e-18 0.036842105 0.015789474"/>
    <axis xyz="0 0 1"/>
    <dynamics damping="0.001"/>
  </joint>
  <link name="wheel1_barrel_2_link">
    <visual>
      <geometry>
        <mesh filename="model://omni_2024/meshes/omni_barrel100.stl"/>
      </geometry>
    </visual>
    <collision>
      <geometry>
        <mesh filename="model://omni_2024/meshes/omni_barrel100.stl"/>
      </geometry>
    </collision>
    <inertial>
      <mass value="0.004"/>
      <inertia ixx="0.000001" ixy="0" ixz="0" iyy="0.000001" iyz="0" izz="0.000001"/>
    </inertial>
  </link>
  <gazebo reference="wheel1_barrel_2_link">
    <mu1 value="5"/>
    <mu2 value="5"/>
    <kp value="7500"/>
    <kd value="20"/>
    <material>Gazebo/Black</material>
  </gazebo>
  <joint name="wheel1_barrel_3_joint" type="continuous">
    <parent link="wheel1_housing_link"/>
    <child link="wheel1_barrel_3_link"/>
    <origin rpy="1.5707963267948966 0 3.141592653589793" xyz="-0.036842105 4.5118565962100695e-18 0.015789474"/>
    <axis xyz="0 0 1"/>
    <dynamics damping="0.001"/>
  </joint>
  <link name="wheel1_barrel_3_link">
    <visual>
      <geometry>
        <mesh filename="model://omni_2024/meshes/omni_barrel100.stl"/>
      </geometry>
    </visual>
    <collision>
      <geometry>
        <mesh filename="model://omni_2024/meshes/omni_barrel100.stl"/>
      </geometry>
    </collision>
    <inertial>
      <mass value="0.004"/>
      <inertia ixx="0.000001" ixy="0" ixz="0" iyy="0.000001" iyz="0" izz="0.000001"/>
    </inertial>
  </link>
  <gazebo reference="wheel1_barrel_3_link">
    <mu1 value="5"/>
    <mu2 value="5"/>
    <kp value="7500"/>
    <kd value="20"/>
    <material>Gazebo/Black</material>
  </gazebo>
  <joint name="wheel1_barrel_4_joint" type="continuous">
    <parent link="wheel1_housing_link"/>
    <child link="wheel1_barrel_4_link"/>
    <origin rpy="1.5707963267948966 0 -1.5707963267948966" xyz="2.2559282981050347e-18 -0.036842105 0.015789474"/>
    <axis xyz="0 0 1"/>
    <dynamics damping="0.001"/>
  </joint>
  <link name="wheel1_barrel_4_link">
    <visual>
      <geometry>
        <mesh filename="model://omni_2024/meshes/omni_barrel100.stl"/>
      </geometry>
    </visual>
    <collision>
      <geometry>
        <mesh filename="model://omni_2024/meshes/omni_barrel100.stl"/>
      </geometry>
    </collision>
    <inertial>
      <mass value="0.004"/>
      <inertia ixx="0.000001" ixy="0" ixz="0" iyy="0.000001" iyz="0" izz="0.000001"/>
    </inertial>
  </link>
  <gazebo reference="wheel1_barrel_4_link">
    <mu1 value="5"/>
    <mu2 value="5"/>
    <kp value="7500"/>
    <kd value="20"/>
    <material>Gazebo/Black</material>
  </gazebo>
  <joint name="wheel1_barrel_5_joint" type="continuous">
    <parent link="wheel1_housing_s_link"/>
    <child link="wheel1_barrel_5_link"/>
    <origin rpy="1.5707963267948966 0 0" xyz="0.036842105 0.0 0.015789474"/>
    <axis xyz="0 0 1"/>
    <dynamics damping="0.001"/>
  </joint>
  <link name="wheel1_barrel_5_link">
    <visual>
      <geometry>
        <mesh filename="model://omni_2024/meshes/omni_barrel100.stl"/>
      </geometry>
    </visual>
    <collision>
      <geometry>
        <mesh filename="model://omni_2024/meshes/omni_barrel100.stl"/>
      </geometry>
    </collision>
    <inertial>
      <mass value="0.004"/>
      <inertia ixx="0.000001" ixy="0" ixz="0" iyy="0.000001" iyz="0" izz="0.000001"/>
    </inertial>
  </link>
  <gazebo reference="wheel1_barrel_5_link">
    <mu1 value="5"/>
    <mu2 value="5"/>
    <kp value="7500"/>
    <kd value="20"/>
    <material>Gazebo/Black</material>
  </gazebo>
  <joint name="wheel1_barrel_6_joint" type="continuous">
    <parent link="wheel1_housing_s_link"/>
    <child link="wheel1_barrel_6_link"/>
    <origin rpy="1.5707963267948966 0 1.5707963267948966" xyz="2.2559282981050347e-18 0.036842105 0.015789474"/>
    <axis xyz="0 0 1"/>
    <dynamics damping="0.001"/>
  </joint>
  <link name="wheel1_barrel_6_link">
    <visual>
      <geometry>
        <mesh filename="model://omni_2024/meshes/omni_barrel100.stl"/>
      </geometry>
    </visual>
    <collision>
      <geometry>
        <mesh filename="model://omni_2024/meshes/omni_barrel100.stl"/>
      </geometry>
    </collision>
    <inertial>
      <mass value="0.004"/>
      <inertia ixx="0.000001" ixy="0" ixz="0" iyy="0.000001" iyz="0" izz="0.000001"/>
    </inertial>
  </link>
  <gazebo reference="wheel1_barrel_6_link">
    <mu1 value="5"/>
    <mu2 value="5"/>
    <kp value="7500"/>
    <kd value="20"/>
    <material>Gazebo/Black</material>
  </gazebo>
  <joint name="wheel1_barrel_7_joint" type="continuous">
    <parent link="wheel1_housing_s_link"/>
    <child link="wheel1_barrel_7_link"/>
    <origin rpy="1.5707963267948966 0 3.141592653589793" xyz="-0.036842105 4.5118565962100695e-18 0.015789474"/>
    <axis xyz="0 0 1"/>
    <dynamics damping="0.001"/>
  </joint>
  <link name="wheel1_barrel_7_link">
    <visual>
      <geometry>
        <mesh filename="model://omni_2024/meshes/omni_barrel100.stl"/>
      </geometry>
    </visual>
    <collision>
      <geometry>
        <mesh filename="model://omni_2024/meshes/omni_barrel100.stl"/>
      </geometry>
    </collision>
    <inertial>
      <mass value="0.004"/>
      <inertia ixx="0.000001" ixy="0" ixz="0" iyy="0.000001" iyz="0" izz="0.000001"/>
    </inertial>
  </link>
  <gazebo reference="wheel1_barrel_7_link">
    <mu1 value="5"/>
    <mu2 value="5"/>
    <kp value="7500"/>
    <kd value="20"/>
    <material>Gazebo/Black</material>
  </gazebo>
  <joint name="wheel1_barrel_8_joint" type="continuous">
    <parent link="wheel1_housing_s_link"/>
    <child link="wheel1_barrel_8_link"/>
    <origin rpy="1.5707963267948966 0 -1.5707963267948966" xyz="2.2559282981050347e-18 -0.036842105 0.015789474"/>
    <axis xyz="0 0 1"/>
    <dynamics damping="0.001"/>
  </joint>
  <link name="wheel1_barrel_8_link">
    <visual>
      <geometry>
        <mesh filename="model://omni_2024/meshes/omni_barrel100.stl"/>
      </geometry>
    </visual>
    <collision>
      <geometry>
        <mesh filename="model://omni_2024/meshes/omni_barrel100.stl"/>
      </geometry>
    </collision>
    <inertial>
      <mass value="0.004"/>
      <inertia ixx="0.000001" ixy="0" ixz="0" iyy="0.000001" iyz="0" izz="0.000001"/>
    </inertial>
  </link>
  <gazebo reference="wheel1_barrel_8_link">
    <mu1 value="5"/>
    <mu2 value="5"/>
    <kp value="7500"/>
    <kd value="20"/>
    <material>Gazebo/Black</material>
  </gazebo>
  <joint name="wheel2_base_joint" type="fixed">
    <parent link="base_link"/>
    <child link="wheel2_base_link"/>
    <origin rpy="0 0 -2.356194490192345" xyz="-0.13647160876900366 -0.1364716087690037 0.05"/>
  </joint>
  <link name="wheel2_base_link">
    <inertial>
      <mass value="0.010"/>
      <inertia ixx="0.0001" ixy="0" ixz="0" iyy="0.0001" iyz="0" izz="0.0001"/>
    </inertial>
  </link>
  <!--Suspension-->
  <joint name="wheel2_sus_joint" type="prismatic">
    <parent link="wheel2_base_link"/>
    <child link="wheel2_sus_link"/>
    <limit effort="100" lower="-0.04" upper="0.04" velocity="1.0"/>
    <axis xyz="0 0 1"/>
    <origin rpy="0 0 0" xyz="0 0 0"/>
    <dynamics damping="0.01"/>
  </joint>
  <gazebo reference="wheel2_sus_joint">
    <kp>50000</kp>
    <kd>500</kd>
  </gazebo>
  <link name="wheel2_sus_link">
    <inertial>
      <mass value="0.020"/>
      <inertia ixx="0.00001" ixy="0.0" ixz="0.0" iyy="0.00001" iyz="0.0" izz="0.00001"/>
    </inertial>
  </link>
  <joint name="wheel2_joint" type="continuous">
    <origin rpy="0 1.5707963267948966 0" xyz="0 0 0"/>
    <parent link="wheel2_sus_link"/>
    <child link="wheel2_housing_link"/>
    <axis xyz="0 0 1"/>
    <!--M3508 1:19-->
    <limit effort="4.6" velocity="61"/>
    <joint_properties damping="0.01" friction="0.01"/>
  </joint>
  <link name="wheel2_housing_link">
    <visual>
      <origin rpy="0 0 0" xyz="0 0 0"/>
      <geometry>
        <mesh filename="model://omni_2024/meshes/omni_housing100.stl"/>
      </geometry>
    </visual>
    <inertial>
      <mass value="0.05"/>
      <inertia ixx="0.00001" ixy="0" ixz="0" iyy="0.00001" iyz="0" izz="0.00001"/>
    </inertial>
  </link>
  <gazebo reference="wheel2_housing_link">
    <material>Gazebo/Gray</material>
  </gazebo>
  <joint name="wheel2_housing_s_joint" type="fixed">
    <parent link="wheel2_housing_link"/>
    <child link="wheel2_housing_s_link"/>
    <origin rpy="0 3.141592653589793 0.7853981633974483" xyz="0 0 0"/>
  </joint>
  <link name="wheel2_housing_s_link">
    <inertial>
      <mass value="0.05"/>
      <inertia ixx="0.0001" ixy="0" ixz="0" iyy="0.0001" iyz="0" izz="0.0001"/>
    </inertial>
  </link>
  <joint name="wheel2_barrel_1_joint" type="continuous">
    <parent link="wheel2_housing_link"/>
    <child link="wheel2_barrel_1_link"/>
    <origin rpy="1.5707963267948966 0 0" xyz="0.036842105 0.0 0.015789474"/>
    <axis xyz="0 0 1"/>
    <dynamics damping="0.001"/>
  </joint>
  <link name="wheel2_barrel_1_link">
    <visual>
      <geometry>
        <mesh filename="model://omni_2024/meshes/omni_barrel100.stl"/>
      </geometry>
    </visual>
    <collision>
      <geometry>
        <mesh filename="model://omni_2024/meshes/omni_barrel100.stl"/>
      </geometry>
    </collision>
    <inertial>
      <mass value="0.004"/>
      <inertia ixx="0.000001" ixy="0" ixz="0" iyy="0.000001" iyz="0" izz="0.000001"/>
    </inertial>
  </link>
  <gazebo reference="wheel2_barrel_1_link">
    <mu1 value="5"/>
    <mu2 value="5"/>
    <kp value="7500"/>
    <kd value="20"/>
    <material>Gazebo/Black</material>
  </gazebo>
  <joint name="wheel2_barrel_2_joint" type="continuous">
    <parent link="wheel2_housing_link"/>
    <child link="wheel2_barrel_2_link"/>
    <origin rpy="1.5707963267948966 0 1.5707963267948966" xyz="2.2559282981050347e-18 0.036842105 0.015789474"/>
    <axis xyz="0 0 1"/>
    <dynamics damping="0.001"/>
  </joint>
  <link name="wheel2_barrel_2_link">
    <visual>
      <geometry>
        <mesh filename="model://omni_2024/meshes/omni_barrel100.stl"/>
      </geometry>
    </visual>
    <collision>
      <geometry>
        <mesh filename="model://omni_2024/meshes/omni_barrel100.stl"/>
      </geometry>
    </collision>
    <inertial>
      <mass value="0.004"/>
      <inertia ixx="0.000001" ixy="0" ixz="0" iyy="0.000001" iyz="0" izz="0.000001"/>
    </inertial>
  </link>
  <gazebo reference="wheel2_barrel_2_link">
    <mu1 value="5"/>
    <mu2 value="5"/>
    <kp value="7500"/>
    <kd value="20"/>
    <material>Gazebo/Black</material>
  </gazebo>
  <joint name="wheel2_barrel_3_joint" type="continuous">
    <parent link="wheel2_housing_link"/>
    <child link="wheel2_barrel_3_link"/>
    <origin rpy="1.5707963267948966 0 3.141592653589793" xyz="-0.036842105 4.5118565962100695e-18 0.015789474"/>
    <axis xyz="0 0 1"/>
    <dynamics damping="0.001"/>
  </joint>
  <link name="wheel2_barrel_3_link">
    <visual>
      <geometry>
        <mesh filename="model://omni_2024/meshes/omni_barrel100.stl"/>
      </geometry>
    </visual>
    <collision>
      <geometry>
        <mesh filename="model://omni_2024/meshes/omni_barrel100.stl"/>
      </geometry>
    </collision>
    <inertial>
      <mass value="0.004"/>
      <inertia ixx="0.000001" ixy="0" ixz="0" iyy="0.000001" iyz="0" izz="0.000001"/>
    </inertial>
  </link>
  <gazebo reference="wheel2_barrel_3_link">
    <mu1 value="5"/>
    <mu2 value="5"/>
    <kp value="7500"/>
    <kd value="20"/>
    <material>Gazebo/Black</material>
  </gazebo>
  <joint name="wheel2_barrel_4_joint" type="continuous">
    <parent link="wheel2_housing_link"/>
    <child link="wheel2_barrel_4_link"/>
    <origin rpy="1.5707963267948966 0 -1.5707963267948966" xyz="2.2559282981050347e-18 -0.036842105 0.015789474"/>
    <axis xyz="0 0 1"/>
    <dynamics damping="0.001"/>
  </joint>
  <link name="wheel2_barrel_4_link">
    <visual>
      <geometry>
        <mesh filename="model://omni_2024/meshes/omni_barrel100.stl"/>
      </geometry>
    </visual>
    <collision>
      <geometry>
        <mesh filename="model://omni_2024/meshes/omni_barrel100.stl"/>
      </geometry>
    </collision>
    <inertial>
      <mass value="0.004"/>
      <inertia ixx="0.000001" ixy="0" ixz="0" iyy="0.000001" iyz="0" izz="0.000001"/>
    </inertial>
  </link>
  <gazebo reference="wheel2_barrel_4_link">
    <mu1 value="5"/>
    <mu2 value="5"/>
    <kp value="7500"/>
    <kd value="20"/>
    <material>Gazebo/Black</material>
  </gazebo>
  <joint name="wheel2_barrel_5_joint" type="continuous">
    <parent link="wheel2_housing_s_link"/>
    <child link="wheel2_barrel_5_link"/>
    <origin rpy="1.5707963267948966 0 0" xyz="0.036842105 0.0 0.015789474"/>
    <axis xyz="0 0 1"/>
    <dynamics damping="0.001"/>
  </joint>
  <link name="wheel2_barrel_5_link">
    <visual>
      <geometry>
        <mesh filename="model://omni_2024/meshes/omni_barrel100.stl"/>
      </geometry>
    </visual>
    <collision>
      <geometry>
        <mesh filename="model://omni_2024/meshes/omni_barrel100.stl"/>
      </geometry>
    </collision>
    <inertial>
      <mass value="0.004"/>
      <inertia ixx="0.000001" ixy="0" ixz="0" iyy="0.000001" iyz="0" izz="0.000001"/>
    </inertial>
  </link>
  <gazebo reference="wheel2_barrel_5_link">
    <mu1 value="5"/>
    <mu2 value="5"/>
    <kp value="7500"/>
    <kd value="20"/>
    <material>Gazebo/Black</material>
  </gazebo>
  <joint name="wheel2_barrel_6_joint" type="continuous">
    <parent link="wheel2_housing_s_link"/>
    <child link="wheel2_barrel_6_link"/>
    <origin rpy="1.5707963267948966 0 1.5707963267948966" xyz="2.2559282981050347e-18 0.036842105 0.015789474"/>
    <axis xyz="0 0 1"/>
    <dynamics damping="0.001"/>
  </joint>
  <link name="wheel2_barrel_6_link">
    <visual>
      <geometry>
        <mesh filename="model://omni_2024/meshes/omni_barrel100.stl"/>
      </geometry>
    </visual>
    <collision>
      <geometry>
        <mesh filename="model://omni_2024/meshes/omni_barrel100.stl"/>
      </geometry>
    </collision>
    <inertial>
      <mass value="0.004"/>
      <inertia ixx="0.000001" ixy="0" ixz="0" iyy="0.000001" iyz="0" izz="0.000001"/>
    </inertial>
  </link>
  <gazebo reference="wheel2_barrel_6_link">
    <mu1 value="5"/>
    <mu2 value="5"/>
    <kp value="7500"/>
    <kd value="20"/>
    <material>Gazebo/Black</material>
  </gazebo>
  <joint name="wheel2_barrel_7_joint" type="continuous">
    <parent link="wheel2_housing_s_link"/>
    <child link="wheel2_barrel_7_link"/>
    <origin rpy="1.5707963267948966 0 3.141592653589793" xyz="-0.036842105 4.5118565962100695e-18 0.015789474"/>
    <axis xyz="0 0 1"/>
    <dynamics damping="0.001"/>
  </joint>
  <link name="wheel2_barrel_7_link">
    <visual>
      <geometry>
        <mesh filename="model://omni_2024/meshes/omni_barrel100.stl"/>
      </geometry>
    </visual>
    <collision>
      <geometry>
        <mesh filename="model://omni_2024/meshes/omni_barrel100.stl"/>
      </geometry>
    </collision>
    <inertial>
      <mass value="0.004"/>
      <inertia ixx="0.000001" ixy="0" ixz="0" iyy="0.000001" iyz="0" izz="0.000001"/>
    </inertial>
  </link>
  <gazebo reference="wheel2_barrel_7_link">
    <mu1 value="5"/>
    <mu2 value="5"/>
    <kp value="7500"/>
    <kd value="20"/>
    <material>Gazebo/Black</material>
  </gazebo>
  <joint name="wheel2_barrel_8_joint" type="continuous">
    <parent link="wheel2_housing_s_link"/>
    <child link="wheel2_barrel_8_link"/>
    <origin rpy="1.5707963267948966 0 -1.5707963267948966" xyz="2.2559282981050347e-18 -0.036842105 0.015789474"/>
    <axis xyz="0 0 1"/>
    <dynamics damping="0.001"/>
  </joint>
  <link name="wheel2_barrel_8_link">
    <visual>
      <geometry>
        <mesh filename="model://omni_2024/meshes/omni_barrel100.stl"/>
      </geometry>
    </visual>
    <collision>
      <geometry>
        <mesh filename="model://omni_2024/meshes/omni_barrel100.stl"/>
      </geometry>
    </collision>
    <inertial>
      <mass value="0.004"/>
      <inertia ixx="0.000001" ixy="0" ixz="0" iyy="0.000001" iyz="0" izz="0.000001"/>
    </inertial>
  </link>
  <gazebo reference="wheel2_barrel_8_link">
    <mu1 value="5"/>
    <mu2 value="5"/>
    <kp value="7500"/>
    <kd value="20"/>
    <material>Gazebo/Black</material>
  </gazebo>
  <joint name="wheel3_base_joint" type="fixed">
    <parent link="base_link"/>
    <child link="wheel3_base_link"/>
    <origin rpy="0 0 -0.7853981633974483" xyz="0.1364716087690037 -0.13647160876900366 0.05"/>
  </joint>
  <link name="wheel3_base_link">
    <inertial>
      <mass value="0.010"/>
      <inertia ixx="0.0001" ixy="0" ixz="0" iyy="0.0001" iyz="0" izz="0.0001"/>
    </inertial>
  </link>
  <!--Suspension-->
  <joint name="wheel3_sus_joint" type="prismatic">
    <parent link="wheel3_base_link"/>
    <child link="wheel3_sus_link"/>
    <limit effort="100" lower="-0.04" upper="0.04" velocity="1.0"/>
    <axis xyz="0 0 1"/>
    <origin rpy="0 0 0" xyz="0 0 0"/>
    <dynamics damping="0.01"/>
  </joint>
  <gazebo reference="wheel3_sus_joint">
    <kp>50000</kp>
    <kd>500</kd>
  </gazebo>
  <link name="wheel3_sus_link">
    <inertial>
      <mass value="0.020"/>
      <inertia ixx="0.00001" ixy="0.0" ixz="0.0" iyy="0.00001" iyz="0.0" izz="0.00001"/>
    </inertial>
  </link>
  <joint name="wheel3_joint" type="continuous">
    <origin rpy="0 1.5707963267948966 0" xyz="0 0 0"/>
    <parent link="wheel3_sus_link"/>
    <child link="wheel3_housing_link"/>
    <axis xyz="0 0 1"/>
    <!--M3508 1:19-->
    <limit effort="4.6" velocity="61"/>
    <joint_properties damping="0.01" friction="0.01"/>
  </joint>
  <link name="wheel3_housing_link">
    <visual>
      <origin rpy="0 0 0" xyz="0 0 0"/>
      <geometry>
        <mesh filename="model://omni_2024/meshes/omni_housing100.stl"/>
      </geometry>
    </visual>
    <inertial>
      <mass value="0.05"/>
      <inertia ixx="0.00001" ixy="0" ixz="0" iyy="0.00001" iyz="0" izz="0.00001"/>
    </inertial>
  </link>
  <gazebo reference="wheel3_housing_link">
    <material>Gazebo/Gray</material>
  </gazebo>
  <joint name="wheel3_housing_s_joint" type="fixed">
    <parent link="wheel3_housing_link"/>
    <child link="wheel3_housing_s_link"/>
    <origin rpy="0 3.141592653589793 0.7853981633974483" xyz="0 0 0"/>
  </joint>
  <link name="wheel3_housing_s_link">
    <inertial>
      <mass value="0.05"/>
      <inertia ixx="0.0001" ixy="0" ixz="0" iyy="0.0001" iyz="0" izz="0.0001"/>
    </inertial>
  </link>
  <joint name="wheel3_barrel_1_joint" type="continuous">
    <parent link="wheel3_housing_link"/>
    <child link="wheel3_barrel_1_link"/>
    <origin rpy="1.5707963267948966 0 0" xyz="0.036842105 0.0 0.015789474"/>
    <axis xyz="0 0 1"/>
    <dynamics damping="0.001"/>
  </joint>
  <link name="wheel3_barrel_1_link">
    <visual>
      <geometry>
        <mesh filename="model://omni_2024/meshes/omni_barrel100.stl"/>
      </geometry>
    </visual>
    <collision>
      <geometry>
        <mesh filename="model://omni_2024/meshes/omni_barrel100.stl"/>
      </geometry>
    </collision>
    <inertial>
      <mass value="0.004"/>
      <inertia ixx="0.000001" ixy="0" ixz="0" iyy="0.000001" iyz="0" izz="0.000001"/>
    </inertial>
  </link>
  <gazebo reference="wheel3_barrel_1_link">
    <mu1 value="5"/>
    <mu2 value="5"/>
    <kp value="7500"/>
    <kd value="20"/>
    <material>Gazebo/Black</material>
  </gazebo>
  <joint name="wheel3_barrel_2_joint" type="continuous">
    <parent link="wheel3_housing_link"/>
    <child link="wheel3_barrel_2_link"/>
    <origin rpy="1.5707963267948966 0 1.5707963267948966" xyz="2.2559282981050347e-18 0.036842105 0.015789474"/>
    <axis xyz="0 0 1"/>
    <dynamics damping="0.001"/>
  </joint>
  <link name="wheel3_barrel_2_link">
    <visual>
      <geometry>
        <mesh filename="model://omni_2024/meshes/omni_barrel100.stl"/>
      </geometry>
    </visual>
    <collision>
      <geometry>
        <mesh filename="model://omni_2024/meshes/omni_barrel100.stl"/>
      </geometry>
    </collision>
    <inertial>
      <mass value="0.004"/>
      <inertia ixx="0.000001" ixy="0" ixz="0" iyy="0.000001" iyz="0" izz="0.000001"/>
    </inertial>
  </link>
  <gazebo reference="wheel3_barrel_2_link">
    <mu1 value="5"/>
    <mu2 value="5"/>
    <kp value="7500"/>
    <kd value="20"/>
    <material>Gazebo/Black</material>
  </gazebo>
  <joint name="wheel3_barrel_3_joint" type="continuous">
    <parent link="wheel3_housing_link"/>
    <child link="wheel3_barrel_3_link"/>
    <origin rpy="1.5707963267948966 0 3.141592653589793" xyz="-0.036842105 4.5118565962100695e-18 0.015789474"/>
    <axis xyz="0 0 1"/>
    <dynamics damping="0.001"/>
  </joint>
  <link name="wheel3_barrel_3_link">
    <visual>
      <geometry>
        <mesh filename="model://omni_2024/meshes/omni_barrel100.stl"/>
      </geometry>
    </visual>
    <collision>
      <geometry>
        <mesh filename="model://omni_2024/meshes/omni_barrel100.stl"/>
      </geometry>
    </collision>
    <inertial>
      <mass value="0.004"/>
      <inertia ixx="0.000001" ixy="0" ixz="0" iyy="0.000001" iyz="0" izz="0.000001"/>
    </inertial>
  </link>
  <gazebo reference="wheel3_barrel_3_link">
    <mu1 value="5"/>
    <mu2 value="5"/>
    <kp value="7500"/>
    <kd value="20"/>
    <material>Gazebo/Black</material>
  </gazebo>
  <joint name="wheel3_barrel_4_joint" type="continuous">
    <parent link="wheel3_housing_link"/>
    <child link="wheel3_barrel_4_link"/>
    <origin rpy="1.5707963267948966 0 -1.5707963267948966" xyz="2.2559282981050347e-18 -0.036842105 0.015789474"/>
    <axis xyz="0 0 1"/>
    <dynamics damping="0.001"/>
  </joint>
  <link name="wheel3_barrel_4_link">
    <visual>
      <geometry>
        <mesh filename="model://omni_2024/meshes/omni_barrel100.stl"/>
      </geometry>
    </visual>
    <collision>
      <geometry>
        <mesh filename="model://omni_2024/meshes/omni_barrel100.stl"/>
      </geometry>
    </collision>
    <inertial>
      <mass value="0.004"/>
      <inertia ixx="0.000001" ixy="0" ixz="0" iyy="0.000001" iyz="0" izz="0.000001"/>
    </inertial>
  </link>
  <gazebo reference="wheel3_barrel_4_link">
    <mu1 value="5"/>
    <mu2 value="5"/>
    <kp value="7500"/>
    <kd value="20"/>
    <material>Gazebo/Black</material>
  </gazebo>
  <joint name="wheel3_barrel_5_joint" type="continuous">
    <parent link="wheel3_housing_s_link"/>
    <child link="wheel3_barrel_5_link"/>
    <origin rpy="1.5707963267948966 0 0" xyz="0.036842105 0.0 0.015789474"/>
    <axis xyz="0 0 1"/>
    <dynamics damping="0.001"/>
  </joint>
  <link name="wheel3_barrel_5_link">
    <visual>
      <geometry>
        <mesh filename="model://omni_2024/meshes/omni_barrel100.stl"/>
      </geometry>
    </visual>
    <collision>
      <geometry>
        <mesh filename="model://omni_2024/meshes/omni_barrel100.stl"/>
      </geometry>
    </collision>
    <inertial>
      <mass value="0.004"/>
      <inertia ixx="0.000001" ixy="0" ixz="0" iyy="0.000001" iyz="0" izz="0.000001"/>
    </inertial>
  </link>
  <gazebo reference="wheel3_barrel_5_link">
    <mu1 value="5"/>
    <mu2 value="5"/>
    <kp value="7500"/>
    <kd value="20"/>
    <material>Gazebo/Black</material>
  </gazebo>
  <joint name="wheel3_barrel_6_joint" type="continuous">
    <parent link="wheel3_housing_s_link"/>
    <child link="wheel3_barrel_6_link"/>
    <origin rpy="1.5707963267948966 0 1.5707963267948966" xyz="2.2559282981050347e-18 0.036842105 0.015789474"/>
    <axis xyz="0 0 1"/>
    <dynamics damping="0.001"/>
  </joint>
  <link name="wheel3_barrel_6_link">
    <visual>
      <geometry>
        <mesh filename="model://omni_2024/meshes/omni_barrel100.stl"/>
      </geometry>
    </visual>
    <collision>
      <geometry>
        <mesh filename="model://omni_2024/meshes/omni_barrel100.stl"/>
      </geometry>
    </collision>
    <inertial>
      <mass value="0.004"/>
      <inertia ixx="0.000001" ixy="0" ixz="0" iyy="0.000001" iyz="0" izz="0.000001"/>
    </inertial>
  </link>
  <gazebo reference="wheel3_barrel_6_link">
    <mu1 value="5"/>
    <mu2 value="5"/>
    <kp value="7500"/>
    <kd value="20"/>
    <material>Gazebo/Black</material>
  </gazebo>
  <joint name="wheel3_barrel_7_joint" type="continuous">
    <parent link="wheel3_housing_s_link"/>
    <child link="wheel3_barrel_7_link"/>
    <origin rpy="1.5707963267948966 0 3.141592653589793" xyz="-0.036842105 4.5118565962100695e-18 0.015789474"/>
    <axis xyz="0 0 1"/>
    <dynamics damping="0.001"/>
  </joint>
  <link name="wheel3_barrel_7_link">
    <visual>
      <geometry>
        <mesh filename="model://omni_2024/meshes/omni_barrel100.stl"/>
      </geometry>
    </visual>
    <collision>
      <geometry>
        <mesh filename="model://omni_2024/meshes/omni_barrel100.stl"/>
      </geometry>
    </collision>
    <inertial>
      <mass value="0.004"/>
      <inertia ixx="0.000001" ixy="0" ixz="0" iyy="0.000001" iyz="0" izz="0.000001"/>
    </inertial>
  </link>
  <gazebo reference="wheel3_barrel_7_link">
    <mu1 value="5"/>
    <mu2 value="5"/>
    <kp value="7500"/>
    <kd value="20"/>
    <material>Gazebo/Black</material>
  </gazebo>
  <joint name="wheel3_barrel_8_joint" type="continuous">
    <parent link="wheel3_housing_s_link"/>
    <child link="wheel3_barrel_8_link"/>
    <origin rpy="1.5707963267948966 0 -1.5707963267948966" xyz="2.2559282981050347e-18 -0.036842105 0.015789474"/>
    <axis xyz="0 0 1"/>
    <dynamics damping="0.001"/>
  </joint>
  <link name="wheel3_barrel_8_link">
    <visual>
      <geometry>
        <mesh filename="model://omni_2024/meshes/omni_barrel100.stl"/>
      </geometry>
    </visual>
    <collision>
      <geometry>
        <mesh filename="model://omni_2024/meshes/omni_barrel100.stl"/>
      </geometry>
    </collision>
    <inertial>
      <mass value="0.004"/>
      <inertia ixx="0.000001" ixy="0" ixz="0" iyy="0.000001" iyz="0" izz="0.000001"/>
    </inertial>
  </link>
  <gazebo reference="wheel3_barrel_8_link">
    <mu1 value="5"/>
    <mu2 value="5"/>
    <kp value="7500"/>
    <kd value="20"/>
    <material>Gazebo/Black</material>
  </gazebo>
  <ros2_control name="GazeboSystem" type="system">
    <hardware>
      <plugin>gz_ros2_control/GazeboSimSystem</plugin>
    </hardware>
    <joint name="wheel0_joint">
      <command_interface name="velocity"/>
      <state_interface name="velocity"/>
      <state_interface name="effort"/>
    </joint>
    <joint name="wheel1_joint">
      <command_interface name="velocity"/>
      <state_interface name="velocity"/>
      <state_interface name="effort"/>
    </joint>
    <joint name="wheel2_joint">
      <command_interface name="velocity"/>
      <state_interface name="velocity"/>
      <state_interface name="effort"/>
    </joint>
    <joint name="wheel3_joint">
      <command_interface name="velocity"/>
      <state_interface name="velocity"/>
      <state_interface name="effort"/>
    </joint>
    <joint name="wheel0_sus_joint">
      <command_interface name="position"/>
      <state_interface name="position"/>
      <state_interface name="velocity"/>
      <state_interface name="effort"/>
    </joint>
    <joint name="wheel1_sus_joint">
      <command_interface name="position"/>
      <state_interface name="position"/>
      <state_interface name="velocity"/>
      <state_interface name="effort"/>
    </joint>
    <joint name="wheel2_sus_joint">
      <command_interface name="position"/>
      <state_interface name="position"/>
      <state_interface name="velocity"/>
      <state_interface name="effort"/>
    </joint>
    <joint name="wheel3_sus_joint">
      <command_interface name="position"/>
      <state_interface name="position"/>
      <state_interface name="velocity"/>
      <state_interface name="effort"/>
    </joint>
  </ros2_control>
  <gazebo>
    <plugin filename="libgz_ros2_control-system.so" name="gz_ros2_control::GazeboSimROS2ControlPlugin">
      <parameters>/home/hao/Ubuntu_3/Private/simulator/ros2_ws/install/gazebo_simulator/share/gazebo_simulator/config/controller_omni_2024.yaml</parameters>
    </plugin>
  </gazebo>
  <gazebo>
    <plugin filename="libgz-sim-pose-publisher-system.so" name="gz::sim::systems::PosePublisher">
      <publish_link_pose>true</publish_link_pose>
      <publish_model_pose>true</publish_model_pose>
      <use_pose_vector_msg>true</use_pose_vector_msg>
      <update_frequency>50</update_frequency>
    </plugin>
  </gazebo>
</robot>
