<sdf version='1.11'>
  <model name='omni4_robot'>
    <link name='base_link'>
      <inertial>
        <pose>0 0 0 0 0 0</pose>
        <mass>2</mass>
        <inertia>
          <ixx>0.01</ixx>
          <ixy>0</ixy>
          <ixz>0</ixz>
          <iyy>0.01</iyy>
          <iyz>0</iyz>
          <izz>0.02</izz>
        </inertia>
      </inertial>
      <collision name='base_link_collision'>
        <pose>0 0 0 0 0 0</pose>
        <geometry>
          <box>
            <size>0.29999999999999999 0.20000000000000001 0.059999999999999998</size>
          </box>
        </geometry>
      </collision>
      <visual name='base_link_visual'>
        <pose>0 0 0 0 0 0</pose>
        <geometry>
          <box>
            <size>0.29999999999999999 0.20000000000000001 0.059999999999999998</size>
          </box>
        </geometry>
        <material>
          <diffuse>1 1 1 0</diffuse>
          <ambient>1 1 1 0</ambient>
        </material>
      </visual>
    </link>
    <joint name='wheel_front_left_joint' type='revolute'>
      <pose relative_to='base_link'>0.12 0.095000000000000001 0.02 3.1415926535746808 -1.5707926536662187 0.78549265361487708</pose>
      <parent>base_link</parent>
      <child>wheel_front_left_link</child>
      <axis>
        <xyz>0 0 1</xyz>
        <limit>
          <effort>10</effort>
          <velocity>20</velocity>
          <lower>-inf</lower>
          <upper>inf</upper>
        </limit>
        <dynamics>
          <damping>0</damping>
          <friction>0</friction>
          <spring_reference>0</spring_reference>
          <spring_stiffness>0</spring_stiffness>
        </dynamics>
      </axis>
    </joint>
    <link name='wheel_front_left_link'>
      <pose relative_to='wheel_front_left_joint'>0 0 0 0 0 0</pose>
      <inertial>
        <pose>0 0 0 0 0 0</pose>
        <mass>0.10000000000000001</mass>
        <inertia>
          <ixx>1.0000000000000001e-05</ixx>
          <ixy>0</ixy>
          <ixz>0</ixz>
          <iyy>1.0000000000000001e-05</iyy>
          <iyz>0</iyz>
          <izz>2.0000000000000002e-05</izz>
        </inertia>
      </inertial>
      <collision name='wheel_front_left_link_collision'>
        <pose>0 0 0 -2.3561000000000001 -1.5707963267948966 0</pose>
        <geometry>
          <cylinder>
            <length>0.017999999999999999</length>
            <radius>0.033000000000000002</radius>
          </cylinder>
        </geometry>
        <surface>
          <contact>
            <ode/>
          </contact>
          <friction>
            <ode/>
          </friction>
        </surface>
      </collision>
      <visual name='wheel_front_left_link_visual'>
        <pose>0 0 0 -2.3561000000000001 -1.5707963267948966 0</pose>
        <geometry>
          <mesh>
            <scale>1 1 1</scale>
            <uri>model://omni4/meshes/omni_housing.stl</uri>
          </mesh>
        </geometry>
        <material>
          <script>
            <name>Gazebo/Grey</name>
            <uri>file://media/materials/scripts/gazebo.material</uri>
          </script>
        </material>
      </visual>
    </link>
    <joint name='wheel_front_right_joint' type='revolute'>
      <pose relative_to='base_link'>0.12 -0.095000000000000001 0.02 0 0 0</pose>
      <parent>base_link</parent>
      <child>wheel_front_right_link</child>
      <axis>
        <xyz>0 0 1</xyz>
        <limit>
          <effort>10</effort>
          <velocity>20</velocity>
          <lower>-inf</lower>
          <upper>inf</upper>
        </limit>
        <dynamics>
          <damping>0</damping>
          <friction>0</friction>
          <spring_reference>0</spring_reference>
          <spring_stiffness>0</spring_stiffness>
        </dynamics>
      </axis>
    </joint>
    <link name='wheel_front_right_link'>
      <pose relative_to='wheel_front_right_joint'>0 0 0 0 0 0</pose>
      <inertial>
        <pose>0 0 0 0 0 0</pose>
        <mass>0.10000000000000001</mass>
        <inertia>
          <ixx>1.0000000000000001e-05</ixx>
          <ixy>0</ixy>
          <ixz>0</ixz>
          <iyy>1.0000000000000001e-05</iyy>
          <iyz>0</iyz>
          <izz>2.0000000000000002e-05</izz>
        </inertia>
      </inertial>
      <collision name='wheel_front_right_link_collision'>
        <pose>0 0 0 0 0 0</pose>
        <geometry>
          <cylinder>
            <length>0.017999999999999999</length>
            <radius>0.033000000000000002</radius>
          </cylinder>
        </geometry>
        <surface>
          <contact>
            <ode/>
          </contact>
          <friction>
            <ode/>
          </friction>
        </surface>
      </collision>
      <visual name='wheel_front_right_link_visual'>
        <pose>0 0 0 0 0 0</pose>
        <geometry>
          <mesh>
            <scale>1 1 1</scale>
            <uri>model://omni4/meshes/omni_housing.stl</uri>
          </mesh>
        </geometry>
        <material>
          <script>
            <name>Gazebo/Grey</name>
            <uri>file://media/materials/scripts/gazebo.material</uri>
          </script>
        </material>
      </visual>
    </link>
    <joint name='wheel_rear_left_joint' type='revolute'>
      <pose relative_to='base_link'>-0.12 0.095000000000000001 0.02 0 0 0</pose>
      <parent>base_link</parent>
      <child>wheel_rear_left_link</child>
      <axis>
        <xyz>0 0 1</xyz>
        <limit>
          <effort>10</effort>
          <velocity>20</velocity>
          <lower>-inf</lower>
          <upper>inf</upper>
        </limit>
        <dynamics>
          <damping>0</damping>
          <friction>0</friction>
          <spring_reference>0</spring_reference>
          <spring_stiffness>0</spring_stiffness>
        </dynamics>
      </axis>
    </joint>
    <link name='wheel_rear_left_link'>
      <pose relative_to='wheel_rear_left_joint'>0 0 0 0 0 0</pose>
      <inertial>
        <pose>0 0 0 0 0 0</pose>
        <mass>0.10000000000000001</mass>
        <inertia>
          <ixx>1.0000000000000001e-05</ixx>
          <ixy>0</ixy>
          <ixz>0</ixz>
          <iyy>1.0000000000000001e-05</iyy>
          <iyz>0</iyz>
          <izz>2.0000000000000002e-05</izz>
        </inertia>
      </inertial>
      <collision name='wheel_rear_left_link_collision'>
        <pose>0 0 0 0 0 0</pose>
        <geometry>
          <cylinder>
            <length>0.017999999999999999</length>
            <radius>0.033000000000000002</radius>
          </cylinder>
        </geometry>
        <surface>
          <contact>
            <ode/>
          </contact>
          <friction>
            <ode/>
          </friction>
        </surface>
      </collision>
      <visual name='wheel_rear_left_link_visual'>
        <pose>0 0 0 0 0 0</pose>
        <geometry>
          <mesh>
            <scale>1 1 1</scale>
            <uri>model://omni4/meshes/omni_housing.stl</uri>
          </mesh>
        </geometry>
        <material>
          <script>
            <name>Gazebo/Grey</name>
            <uri>file://media/materials/scripts/gazebo.material</uri>
          </script>
        </material>
      </visual>
    </link>
    <joint name='wheel_rear_right_joint' type='revolute'>
      <pose relative_to='base_link'>-0.12 -0.095000000000000001 0.02 0 0 0</pose>
      <parent>base_link</parent>
      <child>wheel_rear_right_link</child>
      <axis>
        <xyz>0 0 1</xyz>
        <limit>
          <effort>10</effort>
          <velocity>20</velocity>
          <lower>-inf</lower>
          <upper>inf</upper>
        </limit>
        <dynamics>
          <damping>0</damping>
          <friction>0</friction>
          <spring_reference>0</spring_reference>
          <spring_stiffness>0</spring_stiffness>
        </dynamics>
      </axis>
    </joint>
    <link name='wheel_rear_right_link'>
      <pose relative_to='wheel_rear_right_joint'>0 0 0 0 0 0</pose>
      <inertial>
        <pose>0 0 0 0 0 0</pose>
        <mass>0.10000000000000001</mass>
        <inertia>
          <ixx>1.0000000000000001e-05</ixx>
          <ixy>0</ixy>
          <ixz>0</ixz>
          <iyy>1.0000000000000001e-05</iyy>
          <iyz>0</iyz>
          <izz>2.0000000000000002e-05</izz>
        </inertia>
      </inertial>
      <collision name='wheel_rear_right_link_collision'>
        <pose>0 0 0 0 0 0</pose>
        <geometry>
          <cylinder>
            <length>0.017999999999999999</length>
            <radius>0.033000000000000002</radius>
          </cylinder>
        </geometry>
        <surface>
          <contact>
            <ode/>
          </contact>
          <friction>
            <ode/>
          </friction>
        </surface>
      </collision>
      <visual name='wheel_rear_right_link_visual'>
        <pose>0 0 0 0 0 0</pose>
        <geometry>
          <mesh>
            <scale>1 1 1</scale>
            <uri>model://omni4/meshes/omni_housing.stl</uri>
          </mesh>
        </geometry>
        <material>
          <script>
            <name>Gazebo/Grey</name>
            <uri>file://media/materials/scripts/gazebo.material</uri>
          </script>
        </material>
      </visual>
    </link>
    <plugin name='gz_ros2_control::GazeboSimROS2ControlPlugin' filename='libgz_ros2_control-system.so'>
      <parameters>/home/hao/Ubuntu_3/Private/simulator/ros2_ws/install/gazebo_simulator/share/gazebo_simulator/config/controller_omni4.yaml</parameters>
    </plugin>
  </model>
</sdf>
