<?xml version="1.0" ?>
<!-- =================================================================================== -->
<!-- |    This document was autogenerated by xacro from /home/hao/Ubuntu_3/Private/simulator/ros2_ws/src/gazebo_simulator/urdf/omni4.urdf.xacro | -->
<!-- |    EDITING THIS FILE BY HAND IS NOT RECOMMENDED                                 | -->
<!-- =================================================================================== -->
<robot name="omni4_robot">
  <!-- Base link -->
  <link name="base_link">
    <inertial>
      <mass value="2.0"/>
      <inertia ixx="0.01" ixy="0" ixz="0" iyy="0.01" iyz="0" izz="0.02"/>
    </inertial>
    <visual>
      <geometry>
        <box size="0.3 0.2 0.06"/>
      </geometry>
      <material name="base_material">
        <!-- <color rgba="0.8 0.8 0.8 1"/> -->
        <!-- ↓透明化↑普通 -->
        <color rgba="1 1 1 0"/>
      </material>
    </visual>
    <collision>
      <geometry>
        <box size="0.3 0.2 0.06"/>
      </geometry>
    </collision>
  </link>
  <!-- controlled rotor link -->
  <link name="wheel_front_left_link">
    <inertial>
      <mass value="0.1"/>
      <inertia ixx="0.00001" ixy="0" ixz="0" iyy="0.00001" iyz="0" izz="0.00002"/>
    </inertial>
    <visual>
      <origin rpy="-0.7071 0 -0.5" xyz="0 0 0"/>
      <geometry>
        <!-- main housing mesh (optional) -->
        <mesh filename="model://omni4/meshes/omni_housing.stl"/>
      </geometry>
    </visual>
    <collision>
      <!-- keep simple cylinder collision for performance -->
      <origin rpy="-0.7071 0 -0.5" xyz="0 0 0"/>
      <geometry>
        <cylinder length="0.018" radius="0.033"/>
      </geometry>
    </collision>
  </link>
  <!-- 色 -->
  <gazebo reference="wheel_front_left_link">
    <material>Gazebo/Grey</material>
  </gazebo>
  <joint name="wheel_front_left_joint" type="continuous">
    <parent link="base_link"/>
    <child link="wheel_front_left_link"/>
    <origin rpy="-0.7071 0 -0.5" xyz="0.12 0.095 0.02"/>
    <axis xyz="0.7071 0.7071 1"/>
    <limit effort="10" velocity="20"/>
    <dynamics damping="0.0" friction="0.0"/>
  </joint>
  <!-- controlled rotor link -->
  <link name="wheel_front_right_link">
    <inertial>
      <mass value="0.1"/>
      <inertia ixx="0.00001" ixy="0" ixz="0" iyy="0.00001" iyz="0" izz="0.00002"/>
    </inertial>
    <visual>
      <origin rpy="0 0 0" xyz="0 0 0"/>
      <geometry>
        <!-- main housing mesh (optional) -->
        <mesh filename="model://omni4/meshes/omni_housing.stl"/>
      </geometry>
    </visual>
    <collision>
      <!-- keep simple cylinder collision for performance -->
      <origin rpy="0 0 0" xyz="0 0 0"/>
      <geometry>
        <cylinder length="0.018" radius="0.033"/>
      </geometry>
    </collision>
  </link>
  <!-- 色 -->
  <gazebo reference="wheel_front_right_link">
    <material>Gazebo/Grey</material>
  </gazebo>
  <joint name="wheel_front_right_joint" type="continuous">
    <parent link="base_link"/>
    <child link="wheel_front_right_link"/>
    <origin rpy="0 0 0" xyz="0.12 -0.095 0.02"/>
    <axis xyz="0 0 1"/>
    <limit effort="10" velocity="20"/>
    <dynamics damping="0.0" friction="0.0"/>
  </joint>
  <!-- controlled rotor link -->
  <link name="wheel_rear_left_link">
    <inertial>
      <mass value="0.1"/>
      <inertia ixx="0.00001" ixy="0" ixz="0" iyy="0.00001" iyz="0" izz="0.00002"/>
    </inertial>
    <visual>
      <origin rpy="0 0 0" xyz="0 0 0"/>
      <geometry>
        <!-- main housing mesh (optional) -->
        <mesh filename="model://omni4/meshes/omni_housing.stl"/>
      </geometry>
    </visual>
    <collision>
      <!-- keep simple cylinder collision for performance -->
      <origin rpy="0 0 0" xyz="0 0 0"/>
      <geometry>
        <cylinder length="0.018" radius="0.033"/>
      </geometry>
    </collision>
  </link>
  <!-- 色 -->
  <gazebo reference="wheel_rear_left_link">
    <material>Gazebo/Grey</material>
  </gazebo>
  <joint name="wheel_rear_left_joint" type="continuous">
    <parent link="base_link"/>
    <child link="wheel_rear_left_link"/>
    <origin rpy="0 0 0" xyz="-0.12 0.095 0.02"/>
    <axis xyz="0 0 1"/>
    <limit effort="10" velocity="20"/>
    <dynamics damping="0.0" friction="0.0"/>
  </joint>
  <!-- controlled rotor link -->
  <link name="wheel_rear_right_link">
    <inertial>
      <mass value="0.1"/>
      <inertia ixx="0.00001" ixy="0" ixz="0" iyy="0.00001" iyz="0" izz="0.00002"/>
    </inertial>
    <visual>
      <origin rpy="0 0 0" xyz="0 0 0"/>
      <geometry>
        <!-- main housing mesh (optional) -->
        <mesh filename="model://omni4/meshes/omni_housing.stl"/>
      </geometry>
    </visual>
    <collision>
      <!-- keep simple cylinder collision for performance -->
      <origin rpy="0 0 0" xyz="0 0 0"/>
      <geometry>
        <cylinder length="0.018" radius="0.033"/>
      </geometry>
    </collision>
  </link>
  <!-- 色 -->
  <gazebo reference="wheel_rear_right_link">
    <material>Gazebo/Grey</material>
  </gazebo>
  <joint name="wheel_rear_right_joint" type="continuous">
    <parent link="base_link"/>
    <child link="wheel_rear_right_link"/>
    <origin rpy="0 0 0" xyz="-0.12 -0.095 0.02"/>
    <axis xyz="0 0 1"/>
    <limit effort="10" velocity="20"/>
    <dynamics damping="0.0" friction="0.0"/>
  </joint>
  <!-- まずはwheel_front_leftについてのみ考える -->
  <!-- 目標：車輪とモーターの接続部分が最初(-1,-1,0)方向(ベクトル)を向いて、(-1,-1,0)軸回転。 -->
  <!-- (r, p, yaw, axis_x, axis_y, axis_z) = (0, 0, 0, 0, 0, 1)のとき、接続部分が最初(0, 0, -1)方向を向いて、(0, 0, 1)軸回転 -->
  <!-- (r, p, yaw, axis_x, axis_y, axis_z) = (1.570796, 0, 0, 0, 0, 1)のとき、接続部分が最初(0, 0, 1)方向を向いて、(0, -1, 0)軸回転 -->
  <!-- (r, p, yaw, axis_x, axis_y, axis_z) = (0.785398, 0, 0, 0, 0, 1)のとき、接続部分が最初(0, 1, 0)方向を向いて、(0, -1, 1)軸回転 -->
  <!-- (r, p, yaw, axis_x, axis_y, axis_z) = (-0.785398, 0, -0.5, 0, 0, 1)のとき、接続部分が最初(-1, -1, 0)方向を向いて、(1, 1, 1)軸回転 -->
  <!-- (r, p, yaw, axis_x, axis_y, axis_z) = (1.5708, 0, -2.35619, 0, 0, 1)のとき、接続部分が最初(-1, -1, -1)方向を向いて、(-1, 1, 0)軸回転 -->
  <!-- r="0" p="1.5708" yaw="-2.35619" axis_x="-0.7071" axis_y="-0.7071" axis_z="0"のとき、接続部分が最初(1, -1, -1)方向を向いて、(-1, 1, 1)を軸に回転 -->
  <!-- r="0" p="1.5708" yaw="-2.3561" axis_x="0" axis_y="0" axis_z="1"のとき、接続部分が最初(1, -1, -1)方向を向いて、(-1, -1, 0)を軸に回転 -->
  <!-- r="0" p="0" yaw="-2.3561" axis_x="0" axis_y="0" axis_z="1"のとき、接続部分が最初(0, 0, -1)方向を向いて、(0, 0, 1)を軸に回転 -->
  <!-- r="0" p="-1.5708" yaw="-2.3561" axis_x="0" axis_y="0" axis_z="1"のとき、接続部分が最初(-1, 1, -1)方向を向いて、(-1, -1, 0)を軸に回転 -->
  <!-- Create four wheels using meshes from sim2_lecture if available
  <xacro:odm_visual_wheel name="wheel_front_left" x="${wheel_x}" y="${wheel_y}" r="1.570796" p="0" yaw="0.7854" mesh_housing="model://omni4/meshes/omni_housing.stl" mesh_barrel="model://omni4/meshes/omni_barrel.stl"/>
  <xacro:odm_visual_wheel name="wheel_front_right" x="${wheel_x}" y="-${wheel_y}" r="1.570796" p="0" yaw="-0.7854" mesh_housing="model://omni4/meshes/omni_housing.stl" mesh_barrel="model://omni4/meshes/omni_barrel.stl"/>
  <xacro:odm_visual_wheel name="wheel_rear_left" x="-${wheel_x}" y="${wheel_y}" r="-1.570796" p="0" yaw="2.3562" mesh_housing="model://omni4/meshes/omni_housing.stl" mesh_barrel="model://omni4/meshes/omni_barrel.stl"/>
  <xacro:odm_visual_wheel name="wheel_rear_right" x="-${wheel_x}" y="-${wheel_y}" r="-1.570796" p="0" yaw="-2.3562" mesh_housing="model://omni4/meshes/omni_housing.stl" mesh_barrel="model://omni4/meshes/omni_barrel.stl"/> -->
  <!-- ros2_control plugin config (keep velocity interfaces compatible with existing controllers) -->
  <ros2_control name="GazeboSystem" type="system">
    <hardware>
      <plugin>gz_ros2_control/GazeboSimSystem</plugin>
    </hardware>
    <joint name="wheel_front_left_joint">
      <command_interface name="velocity"/>
      <state_interface name="position"/>
      <state_interface name="velocity"/>
    </joint>
    <joint name="wheel_front_right_joint">
      <command_interface name="velocity"/>
      <state_interface name="position"/>
      <state_interface name="velocity"/>
    </joint>
    <joint name="wheel_rear_left_joint">
      <command_interface name="velocity"/>
      <state_interface name="position"/>
      <state_interface name="velocity"/>
    </joint>
    <joint name="wheel_rear_right_joint">
      <command_interface name="velocity"/>
      <state_interface name="position"/>
      <state_interface name="velocity"/>
    </joint>
  </ros2_control>
  <gazebo>
    <plugin filename="libgz_ros2_control-system.so" name="gz_ros2_control::GazeboSimROS2ControlPlugin">
      <parameters>/home/hao/Ubuntu_3/Private/simulator/ros2_ws/install/gazebo_simulator/share/gazebo_simulator/config/controller_omni4.yaml</parameters>
    </plugin>
  </gazebo>
</robot>
