<?xml version="1.0" ?>
<!-- =================================================================================== -->
<!-- |    This document was autogenerated by xacro from /home/hao/Ubuntu_3/Private/simulator/ros2_ws/src/gazebo_simulator/urdf/omni4.urdf.xacro | -->
<!-- |    EDITING THIS FILE BY HAND IS NOT RECOMMENDED                                 | -->
<!-- =================================================================================== -->
<robot name="omni4_robot">
  <!-- Base link -->
  <link name="base_link">
    <inertial>
      <mass value="2.0"/>
      <inertia ixx="0.01" ixy="0" ixz="0" iyy="0.01" iyz="0" izz="0.02"/>
    </inertial>
    <visual>
      <geometry>
        <box size="0.3 0.2 0.06"/>
      </geometry>
      <material name="base_material">
        <color rgba="0.8 0.8 0.8 1"/>
      </material>
    </visual>
    <collision>
      <geometry>
        <box size="0.3 0.2 0.06"/>
      </geometry>
    </collision>
  </link>
  <link name="wheel_front_left_link">
    <inertial>
      <mass value="0.1"/>
      <inertia ixx="0.00001" ixy="0" ixz="0" iyy="0.00001" iyz="0" izz="0.00002"/>
    </inertial>
    <visual>
      <origin rpy="0 0 0" xyz="0 0 0"/>
      <geometry>
        <cylinder length="0.018" radius="0.033"/>
      </geometry>
      <material name="wheel_material">
        <color rgba="0.1 0.1 0.1 1"/>
      </material>
    </visual>
    <collision>
      <geometry>
        <cylinder length="0.018" radius="0.033"/>
      </geometry>
    </collision>
  </link>
  <joint name="wheel_front_left_joint" type="continuous">
    <parent link="base_link"/>
    <child link="wheel_front_left_link"/>
    <origin rpy="0 0 1.5708" xyz="0.12 0.095 0.02"/>
    <axis xyz="0 0 1"/>
    <limit effort="10" velocity="20"/>
    <dynamics damping="0.0" friction="0.0"/>
  </joint>
  <link name="wheel_front_right_link">
    <inertial>
      <mass value="0.1"/>
      <inertia ixx="0.00001" ixy="0" ixz="0" iyy="0.00001" iyz="0" izz="0.00002"/>
    </inertial>
    <visual>
      <origin rpy="0 0 0" xyz="0 0 0"/>
      <geometry>
        <cylinder length="0.018" radius="0.033"/>
      </geometry>
      <material name="wheel_material">
        <color rgba="0.1 0.1 0.1 1"/>
      </material>
    </visual>
    <collision>
      <geometry>
        <cylinder length="0.018" radius="0.033"/>
      </geometry>
    </collision>
  </link>
  <joint name="wheel_front_right_joint" type="continuous">
    <parent link="base_link"/>
    <child link="wheel_front_right_link"/>
    <origin rpy="0 0 1.5708" xyz="0.12 -0.095 0.02"/>
    <axis xyz="0 0 1"/>
    <limit effort="10" velocity="20"/>
    <dynamics damping="0.0" friction="0.0"/>
  </joint>
  <link name="wheel_rear_left_link">
    <inertial>
      <mass value="0.1"/>
      <inertia ixx="0.00001" ixy="0" ixz="0" iyy="0.00001" iyz="0" izz="0.00002"/>
    </inertial>
    <visual>
      <origin rpy="0 0 0" xyz="0 0 0"/>
      <geometry>
        <cylinder length="0.018" radius="0.033"/>
      </geometry>
      <material name="wheel_material">
        <color rgba="0.1 0.1 0.1 1"/>
      </material>
    </visual>
    <collision>
      <geometry>
        <cylinder length="0.018" radius="0.033"/>
      </geometry>
    </collision>
  </link>
  <joint name="wheel_rear_left_joint" type="continuous">
    <parent link="base_link"/>
    <child link="wheel_rear_left_link"/>
    <origin rpy="0 0 1.5708" xyz="-0.12 0.095 0.02"/>
    <axis xyz="0 0 1"/>
    <limit effort="10" velocity="20"/>
    <dynamics damping="0.0" friction="0.0"/>
  </joint>
  <link name="wheel_rear_right_link">
    <inertial>
      <mass value="0.1"/>
      <inertia ixx="0.00001" ixy="0" ixz="0" iyy="0.00001" iyz="0" izz="0.00002"/>
    </inertial>
    <visual>
      <origin rpy="0 0 0" xyz="0 0 0"/>
      <geometry>
        <cylinder length="0.018" radius="0.033"/>
      </geometry>
      <material name="wheel_material">
        <color rgba="0.1 0.1 0.1 1"/>
      </material>
    </visual>
    <collision>
      <geometry>
        <cylinder length="0.018" radius="0.033"/>
      </geometry>
    </collision>
  </link>
  <joint name="wheel_rear_right_joint" type="continuous">
    <parent link="base_link"/>
    <child link="wheel_rear_right_link"/>
    <origin rpy="0 0 1.5708" xyz="-0.12 -0.095 0.02"/>
    <axis xyz="0 0 1"/>
    <limit effort="10" velocity="20"/>
    <dynamics damping="0.0" friction="0.0"/>
  </joint>
  <!-- ros2_control plugin config -->
  <ros2_control name="GazeboSystem" type="system">
    <hardware>
      <plugin>gz_ros2_control/GazeboSimSystem</plugin>
    </hardware>
    <joint name="wheel_front_left_joint">
      <!-- ここ↓をpositionにすると位置制御 -->
      <command_interface name="velocity"/>
      <!-- ここ↓は返す値の種類 -->
      <state_interface name="position"/>
      <state_interface name="velocity"/>
    </joint>
    <joint name="wheel_front_right_joint">
      <command_interface name="velocity"/>
      <state_interface name="position"/>
      <state_interface name="velocity"/>
    </joint>
    <joint name="wheel_rear_left_joint">
      <command_interface name="velocity"/>
      <state_interface name="position"/>
      <state_interface name="velocity"/>
    </joint>
    <joint name="wheel_rear_right_joint">
      <command_interface name="velocity"/>
      <state_interface name="position"/>
      <state_interface name="velocity"/>
    </joint>
  </ros2_control>
  <gazebo>
    <plugin filename="libgz_ros2_control-system.so" name="gz_ros2_control::GazeboSimROS2ControlPlugin">
      <parameters>/home/hao/Ubuntu_3/Private/simulator/ros2_ws/install/gazebo_simulator/share/gazebo_simulator/config/controller.yaml</parameters>
    </plugin>
  </gazebo>
</robot>
