<?xml version="1.0" ?>
<!-- =================================================================================== -->
<!-- |    This document was autogenerated by xacro from /home/hao/Ubuntu_2/ROS_practice/ros2_ws/src/gazebo_simulator/models/arm_2_v10/urdf/arm_2_v10.xacro | -->
<!-- |    EDITING THIS FILE BY HAND IS NOT RECOMMENDED                                 | -->
<!-- =================================================================================== -->
<robot name="arm_2_v10">
  <material name="silver_default">
    <color rgba="0.700 0.700 0.700 1.000"/>
  </material>
  <material name="_">
    <color rgba="0.6274509803921569 0.6274509803921569 0.6274509803921569 1.0"/>
  </material>
  <transmission name="motor_1_tran">
    <type>transmission_interface/SimpleTransmission</type>
    <joint name="motor_1">
      <hardwareInterface>hardware_interface/EffortJointInterface</hardwareInterface>
    </joint>
    <actuator name="motor_1_actr">
      <hardwareInterface>hardware_interface/EffortJointInterface</hardwareInterface>
      <mechanicalReduction>1</mechanicalReduction>
    </actuator>
  </transmission>
  <transmission name="motor_2_tran">
    <type>transmission_interface/SimpleTransmission</type>
    <joint name="motor_2">
      <hardwareInterface>hardware_interface/EffortJointInterface</hardwareInterface>
    </joint>
    <actuator name="motor_2_actr">
      <hardwareInterface>hardware_interface/EffortJointInterface</hardwareInterface>
      <mechanicalReduction>1</mechanicalReduction>
    </actuator>
  </transmission>
  <transmission name="motor_3_tran">
    <type>transmission_interface/SimpleTransmission</type>
    <joint name="motor_3">
      <hardwareInterface>hardware_interface/EffortJointInterface</hardwareInterface>
    </joint>
    <actuator name="motor_3_actr">
      <hardwareInterface>hardware_interface/EffortJointInterface</hardwareInterface>
      <mechanicalReduction>1</mechanicalReduction>
    </actuator>
  </transmission>
  <link name="base_link">
    <inertial>
      <origin rpy="0 0 0" xyz="0.0 0.0 0.0025"/>
      <mass value="9.8125"/>
      <inertia ixx="0.204448" ixy="0.0" ixz="0.0" iyy="0.204448" iyz="0.0" izz="0.408854"/>
    </inertial>
    <visual>
      <origin rpy="0 0 0" xyz="0 0 0"/>
      <geometry>
        <mesh filename="package://arm_2_v10/meshes/base_link.stl" scale="0.001 0.001 0.001"/>
      </geometry>
      <material name="_"/>
    </visual>
    <collision>
      <origin rpy="0 0 0" xyz="0 0 0"/>
      <geometry>
        <mesh filename="package://arm_2_v10/meshes/base_link.stl" scale="0.001 0.001 0.001"/>
      </geometry>
    </collision>
  </link>
  <link name="arm_link_1_v2_1">
    <inertial>
      <origin rpy="0 0 0" xyz="-4.964936414250037e-18 -3.7238716991499854e-18 0.014999999999999996"/>
      <mass value="0.9063102106524854"/>
      <inertia ixx="0.000346" ixy="0.0" ixz="-0.0" iyy="0.000346" iyz="-0.0" izz="0.000555"/>
    </inertial>
    <visual>
      <origin rpy="0 0 0" xyz="-0.0 -0.0 -0.005"/>
      <geometry>
        <mesh filename="package://arm_2_v10/meshes/arm_link_1_v2_1.stl" scale="0.001 0.001 0.001"/>
      </geometry>
      <material name="_"/>
    </visual>
    <collision>
      <origin rpy="0 0 0" xyz="-0.0 -0.0 -0.005"/>
      <geometry>
        <mesh filename="package://arm_2_v10/meshes/arm_link_1_v2_1.stl" scale="0.001 0.001 0.001"/>
      </geometry>
    </collision>
  </link>
  <link name="arm_link_2_v5_1">
    <inertial>
      <origin rpy="0 0 0" xyz="-0.024950311282444234 -0.04260141994558462 0.05841732248118084"/>
      <mass value="0.8323257036604458"/>
      <inertia ixx="0.001579" ixy="-0.000127" ixz="0.000162" iyy="0.001041" iyz="0.000721" izz="0.000689"/>
    </inertial>
    <visual>
      <origin rpy="0 0 0" xyz="-0.034148 0.007676 -0.035"/>
      <geometry>
        <mesh filename="package://arm_2_v10/meshes/arm_link_2_v5_1.stl" scale="0.001 0.001 0.001"/>
      </geometry>
      <material name="_"/>
    </visual>
    <collision>
      <origin rpy="0 0 0" xyz="-0.034148 0.007676 -0.035"/>
      <geometry>
        <mesh filename="package://arm_2_v10/meshes/arm_link_2_v5_1.stl" scale="0.001 0.001 0.001"/>
      </geometry>
    </collision>
  </link>
  <link name="arm_link_3_v3_1">
    <inertial>
      <origin rpy="0 0 0" xyz="0.0012654354833639293 -0.06276936981888555 -0.043685765516444916"/>
      <mass value="0.8323257036604458"/>
      <inertia ixx="0.001559" ixy="-0.000214" ixz="-0.000157" iyy="0.000655" iyz="-0.000699" izz="0.001094"/>
    </inertial>
    <visual>
      <origin rpy="0 0 0" xyz="0.015753 0.092879 -0.151835"/>
      <geometry>
        <mesh filename="package://arm_2_v10/meshes/arm_link_3_v3_1.stl" scale="0.001 0.001 0.001"/>
      </geometry>
      <material name="_"/>
    </visual>
    <collision>
      <origin rpy="0 0 0" xyz="0.015753 0.092879 -0.151835"/>
      <geometry>
        <mesh filename="package://arm_2_v10/meshes/arm_link_3_v3_1.stl" scale="0.001 0.001 0.001"/>
      </geometry>
    </collision>
  </link>
  <joint name="motor_1" type="continuous">
    <origin rpy="0 0 0" xyz="0.0 0.0 0.005"/>
    <parent link="base_link"/>
    <child link="arm_link_1_v2_1"/>
    <axis xyz="-0.0 0.0 -1.0"/>
  </joint>
  <joint name="motor_2" type="continuous">
    <origin rpy="0 0 0" xyz="0.034148 -0.007676 0.03"/>
    <parent link="arm_link_1_v2_1"/>
    <child link="arm_link_2_v5_1"/>
    <axis xyz="0.975656 -0.219308 -0.0"/>
  </joint>
  <joint name="motor_3" type="continuous">
    <origin rpy="0 0 0" xyz="-0.049901 -0.085203 0.116835"/>
    <parent link="arm_link_2_v5_1"/>
    <child link="arm_link_3_v3_1"/>
    <axis xyz="-0.975656 0.219308 0.0"/>
  </joint>
  <!-- ros2_control plugin config (keep velocity interfaces compatible with existing controllers) -->
  <ros2_control name="GazeboSystem" type="system">
    <hardware>
      <plugin>gz_ros2_control/GazeboSimSystem</plugin>
    </hardware>
    <joint name="motor_1">
      <command_interface name="velocity"/>
      <state_interface name="position"/>
      <state_interface name="velocity"/>
    </joint>
    <joint name="motor_2">
      <command_interface name="velocity"/>
      <state_interface name="position"/>
      <state_interface name="velocity"/>
    </joint>
    <joint name="motor_3">
      <command_interface name="velocity"/>
      <state_interface name="position"/>
      <state_interface name="velocity"/>
    </joint>
  </ros2_control>
  <gazebo>
    <plugin filename="libgz_ros2_control-system.so" name="gz_ros2_control::GazeboSimROS2ControlPlugin">
      <parameters>/home/hao/Ubuntu_2/ROS_practice/ros2_ws/install/gazebo_simulator/share/gazebo_simulator/config/controller_arm_2_v10.yaml</parameters>
    </plugin>
  </gazebo>
  <gazebo>
    <plugin filename="libgz-sim-pose-publisher-system.so" name="gz::sim::systems::PosePublisher">
      <publish_link_pose>true</publish_link_pose>
      <publish_model_pose>true</publish_model_pose>
      <use_pose_vector_msg>true</use_pose_vector_msg>
      <update_frequency>50</update_frequency>
    </plugin>
  </gazebo>
</robot>
