<sdf version='1.11'>
  <model name='arm_2_v10'>
    <link name='base_link'>
      <inertial>
        <pose>0 0 0.0025000000000000001 0 0 0</pose>
        <mass>9.8125</mass>
        <inertia>
          <ixx>0.20444799999999999</ixx>
          <ixy>0</ixy>
          <ixz>0</ixz>
          <iyy>0.20444799999999999</iyy>
          <iyz>0</iyz>
          <izz>0.408854</izz>
        </inertia>
      </inertial>
      <collision name='base_link_collision'>
        <pose>0 0 0 0 0 0</pose>
        <geometry>
          <mesh>
            <scale>0.001 0.001 0.001</scale>
            <uri>meshes/base_link.stl</uri>
          </mesh>
        </geometry>
      </collision>
      <visual name='base_link_visual'>
        <pose>0 0 0 0 0 0</pose>
        <geometry>
          <mesh>
            <scale>0.001 0.001 0.001</scale>
            <uri>meshes/base_link.stl</uri>
          </mesh>
        </geometry>
        <material>
          <diffuse>0.784313738 0.784313738 0.784313738 1</diffuse>
          <ambient>0.784313738 0.784313738 0.784313738 1</ambient>
        </material>
      </visual>
    </link>
    <joint name='motor_1' type='revolute'>
      <pose relative_to='base_link'>0 0 0.0050000000000000001 0 0 0</pose>
      <parent>base_link</parent>
      <child>arm_link_1_v2_1</child>
      <axis>
        <xyz>0 0 -1</xyz>
        <limit>
          <lower>-inf</lower>
          <upper>inf</upper>
        </limit>
        <dynamics>
          <spring_reference>0</spring_reference>
          <spring_stiffness>0</spring_stiffness>
        </dynamics>
      </axis>
    </joint>
    <link name='arm_link_1_v2_1'>
      <pose relative_to='motor_1'>0 0 0 0 0 0</pose>
      <inertial>
        <pose>-4.9649364142500372e-18 -3.7238716991499846e-18 0.014999999999999999 0 0 0</pose>
        <mass>0.9063102106524854</mass>
        <inertia>
          <ixx>0.00034600000000000001</ixx>
          <ixy>0</ixy>
          <ixz>0</ixz>
          <iyy>0.00034600000000000001</iyy>
          <iyz>0</iyz>
          <izz>0.00055500000000000005</izz>
        </inertia>
      </inertial>
      <collision name='arm_link_1_v2_1_collision'>
        <pose>0 0 -0.0050000000000000001 0 0 0</pose>
        <geometry>
          <mesh>
            <scale>0.001 0.001 0.001</scale>
            <uri>meshes/arm_link_1_v2_1.stl</uri>
          </mesh>
        </geometry>
      </collision>
      <visual name='arm_link_1_v2_1_visual'>
        <pose>0 0 -0.0050000000000000001 0 0 0</pose>
        <geometry>
          <mesh>
            <scale>0.001 0.001 0.001</scale>
            <uri>meshes/arm_link_1_v2_1.stl</uri>
          </mesh>
        </geometry>
        <material>
          <diffuse>0.784313738 0.784313738 0.784313738 1</diffuse>
          <ambient>0.784313738 0.784313738 0.784313738 1</ambient>
        </material>
      </visual>
    </link>
    <joint name='motor_2' type='revolute'>
      <pose relative_to='arm_link_1_v2_1'>0.034147999999999998 -0.0076759999999999997 0.029999999999999999 0 0 0</pose>
      <parent>arm_link_1_v2_1</parent>
      <child>arm_link_2_v5_1</child>
      <axis>
        <xyz>0.97565599999999997 -0.219308 0</xyz>
        <limit>
          <lower>-inf</lower>
          <upper>inf</upper>
        </limit>
        <dynamics>
          <spring_reference>0</spring_reference>
          <spring_stiffness>0</spring_stiffness>
        </dynamics>
      </axis>
    </joint>
    <link name='arm_link_2_v5_1'>
      <pose relative_to='motor_2'>0 0 0 0 0 0</pose>
      <inertial>
        <pose>-0.024950311282444231 -0.042601419945584619 0.058417322481180839 0 0 0</pose>
        <mass>0.83232570366044578</mass>
        <inertia>
          <ixx>0.0015790000000000001</ixx>
          <ixy>-0.000127</ixy>
          <ixz>0.00016200000000000001</ixz>
          <iyy>0.001041</iyy>
          <iyz>0.00072099999999999996</iyz>
          <izz>0.00068900000000000005</izz>
        </inertia>
      </inertial>
      <collision name='arm_link_2_v5_1_collision'>
        <pose>-0.034147999999999998 0.0076759999999999997 -0.035000000000000003 0 0 0</pose>
        <geometry>
          <mesh>
            <scale>0.001 0.001 0.001</scale>
            <uri>meshes/arm_link_2_v5_1.stl</uri>
          </mesh>
        </geometry>
      </collision>
      <visual name='arm_link_2_v5_1_visual'>
        <pose>-0.034147999999999998 0.0076759999999999997 -0.035000000000000003 0 0 0</pose>
        <geometry>
          <mesh>
            <scale>0.001 0.001 0.001</scale>
            <uri>meshes/arm_link_2_v5_1.stl</uri>
          </mesh>
        </geometry>
        <material>
          <diffuse>0.784313738 0.784313738 0.784313738 1</diffuse>
          <ambient>0.784313738 0.784313738 0.784313738 1</ambient>
        </material>
      </visual>
    </link>
    <joint name='motor_3' type='revolute'>
      <pose relative_to='arm_link_2_v5_1'>-0.049901000000000001 -0.085203000000000001 0.11683499999999999 0 0 0</pose>
      <parent>arm_link_2_v5_1</parent>
      <child>arm_link_3_v3_1</child>
      <axis>
        <xyz>-0.97565599999999997 0.219308 0</xyz>
        <limit>
          <lower>-inf</lower>
          <upper>inf</upper>
        </limit>
        <dynamics>
          <spring_reference>0</spring_reference>
          <spring_stiffness>0</spring_stiffness>
        </dynamics>
      </axis>
    </joint>
    <link name='arm_link_3_v3_1'>
      <pose relative_to='motor_3'>0 0 0 0 0 0</pose>
      <inertial>
        <pose>0.001265435483363929 -0.062769369818885548 -0.043685765516444923 0 0 0</pose>
        <mass>0.83232570366044578</mass>
        <inertia>
          <ixx>0.0015590000000000001</ixx>
          <ixy>-0.000214</ixy>
          <ixz>-0.00015699999999999999</ixz>
          <iyy>0.00065499999999999998</iyy>
          <iyz>-0.00069899999999999997</iyz>
          <izz>0.0010939999999999999</izz>
        </inertia>
      </inertial>
      <collision name='arm_link_3_v3_1_collision'>
        <pose>0.015753 0.092879000000000003 -0.151835 0 0 0</pose>
        <geometry>
          <mesh>
            <scale>0.001 0.001 0.001</scale>
            <uri>meshes/arm_link_3_v3_1.stl</uri>
          </mesh>
        </geometry>
      </collision>
      <visual name='arm_link_3_v3_1_visual'>
        <pose>0.015753 0.092879000000000003 -0.151835 0 0 0</pose>
        <geometry>
          <mesh>
            <scale>0.001 0.001 0.001</scale>
            <uri>meshes/arm_link_3_v3_1.stl</uri>
          </mesh>
        </geometry>
        <material>
          <diffuse>0.784313738 0.784313738 0.784313738 1</diffuse>
          <ambient>0.784313738 0.784313738 0.784313738 1</ambient>
        </material>
      </visual>
    </link>
    <plugin name='gz_ros2_control::GazeboSimROS2ControlPlugin' filename='libgz_ros2_control-system.so'>
      <parameters>/home/hao/Ubuntu_3/Private/simulator/ros2_ws/install/gazebo_simulator/share/gazebo_simulator/config/controller_arm_2_v10.yaml</parameters>
    </plugin>
    <plugin name='gz::sim::systems::PosePublisher' filename='libgz-sim-pose-publisher-system.so'>
      <publish_link_pose>true</publish_link_pose>
      <publish_model_pose>true</publish_model_pose>
      <use_pose_vector_msg>true</use_pose_vector_msg>
      <update_frequency>50</update_frequency>
    </plugin>
  </model>
</sdf>
