<sdf version='1.11'>
  <model name='arm_1'>
    <link name='base_link'>
      <inertial>
        <pose>-0.023998948872794981 -0.0073878631826703456 0.066611085690124638 0 0 0</pose>
        <mass>3.0210340355082841</mass>
        <inertia>
          <ixx>0.0034429999999999999</ixx>
          <ixy>0</ixy>
          <ixz>0</ixz>
          <iyy>0.0034429999999999999</iyy>
          <iyz>0</iyz>
          <izz>0.0018500000000000001</izz>
        </inertia>
      </inertial>
      <collision name='base_link_collision'>
        <pose>0 0 0 0 0 0</pose>
        <geometry>
          <mesh>
            <scale>0.001 0.001 0.001</scale>
            <uri>meshes/base_link.stl</uri>
          </mesh>
        </geometry>
      </collision>
      <visual name='base_link_visual'>
        <pose>0 0 0 0 0 0</pose>
        <geometry>
          <mesh>
            <scale>0.001 0.001 0.001</scale>
            <uri>meshes/base_link.stl</uri>
          </mesh>
        </geometry>
        <material>
          <diffuse>0.784313738 0.784313738 0.784313738 1</diffuse>
          <ambient>0.784313738 0.784313738 0.784313738 1</ambient>
        </material>
      </visual>
    </link>
    <joint name='motor_1' type='revolute'>
      <pose relative_to='base_link'>-0.023998999999999999 -0.0073879999999999996 0.11661100000000001 0 0 0</pose>
      <parent>base_link</parent>
      <child>arm_link_1_v2_2</child>
      <axis>
        <xyz>0 0 -1</xyz>
        <limit>
          <lower>-inf</lower>
          <upper>inf</upper>
        </limit>
        <dynamics>
          <spring_reference>0</spring_reference>
          <spring_stiffness>0</spring_stiffness>
        </dynamics>
      </axis>
    </joint>
    <link name='arm_link_1_v2_2'>
      <pose relative_to='motor_1'>0 0 0 0 0 0</pose>
      <inertial>
        <pose>-0.069436060346146133 0.028348442295090402 0.050000085690124582 0 0 0</pose>
        <mass>9.2480633740049534</mass>
        <inertia>
          <ixx>0.013212</ixx>
          <ixy>0.004045</ixy>
          <ixz>0</ixz>
          <iyy>0.021468999999999999</iyy>
          <iyz>0</iyz>
          <izz>0.023120000000000002</izz>
        </inertia>
      </inertial>
      <collision name='arm_link_1_v2_2_collision'>
        <pose>0.023998999999999999 0.0073879999999999996 -0.11661100000000001 0 0 0</pose>
        <geometry>
          <mesh>
            <scale>0.001 0.001 0.001</scale>
            <uri>meshes/arm_link_1_v2_2.stl</uri>
          </mesh>
        </geometry>
      </collision>
      <visual name='arm_link_1_v2_2_visual'>
        <pose>0.023998999999999999 0.0073879999999999996 -0.11661100000000001 0 0 0</pose>
        <geometry>
          <mesh>
            <scale>0.001 0.001 0.001</scale>
            <uri>meshes/arm_link_1_v2_2.stl</uri>
          </mesh>
        </geometry>
        <material>
          <diffuse>0.784313738 0.784313738 0.784313738 1</diffuse>
          <ambient>0.784313738 0.784313738 0.784313738 1</ambient>
        </material>
      </visual>
    </link>
  </model>
</sdf>
