<?xml version="1.0" ?>
<robot name="arm_2_v10" xmlns:xacro="http://www.ros.org/wiki/xacro">

<xacro:property name="robot_name" value="$(arg robot_name)"/>

<xacro:include filename="$(find gazebo_simulator)/models/${robot_name}/urdf/materials.xacro" />

<xacro:include filename="$(find gazebo_simulator)/models/${robot_name}/urdf/${robot_name}.trans" />

<link name="base_link">
  <inertial>
    <origin xyz="0.0 0.0 0.0025" rpy="0 0 0"/>
    <mass value="9.8125"/>
    <inertia ixx="0.204448" iyy="0.204448" izz="0.408854" ixy="0.0" iyz="0.0" ixz="0.0"/>
  </inertial>
  <visual>
    <origin xyz="0 0 0" rpy="0 0 0"/>
    <geometry>
      <mesh filename="package://arm_2_v10/meshes/base_link.stl" scale="0.001 0.001 0.001"/>
    </geometry>
    <material name="_"/>
  </visual>
  <collision>
    <origin xyz="0 0 0" rpy="0 0 0"/>
    <geometry>
      <mesh filename="package://arm_2_v10/meshes/base_link.stl" scale="0.001 0.001 0.001"/>
    </geometry>
  </collision>
</link>

<link name="arm_link_1_v2_1">
  <inertial>
    <origin xyz="-4.964936414250037e-18 -3.7238716991499854e-18 0.014999999999999996" rpy="0 0 0"/>
    <mass value="0.9063102106524854"/>
    <inertia ixx="0.000346" iyy="0.000346" izz="0.000555" ixy="0.0" iyz="-0.0" ixz="-0.0"/>
  </inertial>
  <visual>
    <origin xyz="-0.0 -0.0 -0.005" rpy="0 0 0"/>
    <geometry>
      <mesh filename="package://arm_2_v10/meshes/arm_link_1_v2_1.stl" scale="0.001 0.001 0.001"/>
    </geometry>
    <material name="_"/>
  </visual>
  <collision>
    <origin xyz="-0.0 -0.0 -0.005" rpy="0 0 0"/>
    <geometry>
      <mesh filename="package://arm_2_v10/meshes/arm_link_1_v2_1.stl" scale="0.001 0.001 0.001"/>
    </geometry>
  </collision>
</link>

<link name="arm_link_2_v5_1">
  <inertial>
    <origin xyz="-0.024950311282444234 -0.04260141994558462 0.05841732248118084" rpy="0 0 0"/>
    <mass value="0.8323257036604458"/>
    <inertia ixx="0.001579" iyy="0.001041" izz="0.000689" ixy="-0.000127" iyz="0.000721" ixz="0.000162"/>
  </inertial>
  <visual>
    <origin xyz="-0.034148 0.007676 -0.035" rpy="0 0 0"/>
    <geometry>
      <mesh filename="package://arm_2_v10/meshes/arm_link_2_v5_1.stl" scale="0.001 0.001 0.001"/>
    </geometry>
    <material name="_"/>
  </visual>
  <collision>
    <origin xyz="-0.034148 0.007676 -0.035" rpy="0 0 0"/>
    <geometry>
      <mesh filename="package://arm_2_v10/meshes/arm_link_2_v5_1.stl" scale="0.001 0.001 0.001"/>
    </geometry>
  </collision>
</link>

<link name="arm_link_3_v3_1">
  <inertial>
    <origin xyz="0.0012654354833639293 -0.06276936981888555 -0.043685765516444916" rpy="0 0 0"/>
    <mass value="0.8323257036604458"/>
    <inertia ixx="0.001559" iyy="0.000655" izz="0.001094" ixy="-0.000214" iyz="-0.000699" ixz="-0.000157"/>
  </inertial>
  <visual>
    <origin xyz="0.015753 0.092879 -0.151835" rpy="0 0 0"/>
    <geometry>
      <mesh filename="package://arm_2_v10/meshes/arm_link_3_v3_1.stl" scale="0.001 0.001 0.001"/>
    </geometry>
    <material name="_"/>
  </visual>
  <collision>
    <origin xyz="0.015753 0.092879 -0.151835" rpy="0 0 0"/>
    <geometry>
      <mesh filename="package://arm_2_v10/meshes/arm_link_3_v3_1.stl" scale="0.001 0.001 0.001"/>
    </geometry>
  </collision>
</link>

<joint name="motor_1" type="continuous">
  <origin xyz="0.0 0.0 0.005" rpy="0 0 0"/>
  <parent link="base_link"/>
  <child link="arm_link_1_v2_1"/>
  <axis xyz="-0.0 0.0 -1.0"/>
</joint>

<joint name="motor_2" type="continuous">
  <origin xyz="0.034148 -0.007676 0.03" rpy="0 0 0"/>
  <parent link="arm_link_1_v2_1"/>
  <child link="arm_link_2_v5_1"/>
  <axis xyz="0.975656 -0.219308 -0.0"/>
</joint>

<joint name="motor_3" type="continuous">
  <origin xyz="-0.049901 -0.085203 0.116835" rpy="0 0 0"/>
  <parent link="arm_link_2_v5_1"/>
  <child link="arm_link_3_v3_1"/>
  <axis xyz="-0.975656 0.219308 0.0"/>
</joint>


<!-- ros2_control plugin config (keep velocity interfaces compatible with existing controllers) -->
<ros2_control name="GazeboSystem" type="system">
  <hardware>
    <plugin>gz_ros2_control/GazeboSimSystem</plugin>
  </hardware>

  <joint name="motor_1">
    <command_interface name="velocity"/>
    <state_interface name="position"/>
    <state_interface name="velocity"/>
  </joint>

  <joint name="motor_2">
    <command_interface name="velocity"/>
    <state_interface name="position"/>
    <state_interface name="velocity"/>
  </joint>

  <joint name="motor_3">
    <command_interface name="velocity"/>
    <state_interface name="position"/>
    <state_interface name="velocity"/>
  </joint>


</ros2_control>

<gazebo>
  <plugin filename="libgz_ros2_control-system.so" name="gz_ros2_control::GazeboSimROS2ControlPlugin">
    <parameters>$(find gazebo_simulator)/config/controller_${robot_name}.yaml</parameters>
  </plugin>
</gazebo>

<gazebo>
  <plugin
    filename="libgz-sim-pose-publisher-system.so"
    name="gz::sim::systems::PosePublisher">
    <publish_link_pose>true</publish_link_pose>
    <publish_model_pose>true</publish_model_pose>
    <use_pose_vector_msg>true</use_pose_vector_msg>
    <update_frequency>50</update_frequency>
  </plugin>
</gazebo>

</robot>
