<?xml version="1.0" ?>
<!-- =================================================================================== -->
<!-- |    This document was autogenerated by xacro from /home/hao/Ubuntu_3/Private/simulator/ros2_ws/src/gazebo_simulator/urdf/demorobot.urdf.xacro | -->
<!-- |    EDITING THIS FILE BY HAND IS NOT RECOMMENDED                                 | -->
<!-- =================================================================================== -->
<robot name="demorobot">
  <!-- Base link -->
  <link name="base_link">
    <inertial>
      <pose>0.1 0 0 0 0 0</pose>
      <mass value="1.3729096"/>
      <inertia ixx="4.2111447e-02" ixy="0" ixz="0" iyy="4.2111447e-02" iyz="0" izz="7.5254874e-02"/>
    </inertial>
    <collision name="base_collision">
      <origin rpy="0 0 -1.57" xyz="-0.064 0.08 0.06"/>
      <geometry>
        <mesh filename="model://demorobot/meshes/2DRoboPrac.stl"/>
      </geometry>
    </collision>
    <visual name="base_visual">
      <origin rpy="0 0 -1.57" xyz="-0.064 0.08 0.06"/>
      <geometry>
        <mesh filename="model://demorobot/meshes/2DRoboPrac.dae"/>
      </geometry>
      <material name="base_material">
        <color rgba="0.921568627 0.925490196 0.941176471 1"/>
      </material>
    </visual>
  </link>
  <!-- Left wheel -->
  <link name="wheel_left_link">
    <inertial>
      <mass value="0.1"/>
      <inertia ixx="1.1175580e-05" ixy="-4.2369783e-11" ixz="-5.9381719e-09" iyy="1.1192413e-05" iyz="-1.4400107e-11" izz="2.0712558e-05"/>
    </inertial>
    <collision name="wheel_left_collision">
      <geometry>
        <cylinder length="0.018" radius="0.03  <joint name="wheel3_attach_joint" type="fixed">
    <parent link="base_link"/>
    <child  link="wheel3_attach_link"/>
    <origin xyz="${0.07*cos(radians(wheel3_angle_deg))} ${0.07*sin(radians(wheel3_angle_deg))} 0.019" rpy="0 0 ${radians(wheel3_angle_deg)}"/>
  </joint>
  <link name="wheel3_attach_link" />
  <xacro:omni_wheel_set prefix="wheel3" parent="wheel3_attach_link" />3"/>
      </geometry>
    </collision>
    <visual name="wheel_left_visual">
      <geometry>
        <cylinder length="0.018" radius="0.033"/>
      </geometry>
      <material name="wheel_material">
        <color rgba="1.0 0.0 0.0 1"/>
      </material>
    </visual>
  </link>
  <joint name="wheel_left_joint" type="continuous">
    <parent link="base_link"/>
    <child link="wheel_left_link"/>
    <origin rpy="-1.57 0 0" xyz="0.0 0.095 0.023"/>
    <axis xyz="0 0 1"/>
    <limit effort="10" velocity="10"/>
    <dynamics damping="0.0" friction="0.0"/>
  </joint>
  <!-- Right wheel -->
  <link name="wheel_right_link">
    <inertial>
      <mass value="0.1"/>
      <inertia ixx="1.1175580e-05" ixy="-4.2369783e-11" ixz="-5.9381719e-09" iyy="1.1192413e-05" iyz="-1.4400107e-11" izz="2.0712558e-05"/>
    </inertial>
    <collision name="wheel_right_collision">
      <geometry>
        <cylinder length="0.018" radius="0.033"/>
      </geometry>
    </collision>
    <visual name="wheel_right_visual">
      <geometry>
        <cylinder length="0.018" radius="0.033"/>
      </geometry>
      <material name="wheel_material">
        <color rgba="1.0 0.0 0.0 1"/>
      </material>
    </visual>
  </link>
  <joint name="wheel_right_joint" type="continuous">
    <parent link="base_link"/>
    <child link="wheel_right_link"/>
    <origin rpy="-1.57 0 0" xyz="0.0 -0.095 0.023"/>
    <axis xyz="0 0 1"/>
    <limit effort="10" velocity="10"/>
    <dynamics damping="0.0" friction="0.0"/>
  </joint>
  <!-- Caster wheels (back right) -->
  <link name="caster_back_right_link">
    <inertial>
      <mass value="0.001"/>
      <inertia ixx="0.00001" ixy="0.000" ixz="0.000" iyy="0.00001" iyz="0.000" izz="0.00001"/>
    </inertial>
    <collision name="caster_back_right_collision">
      <geometry>
        <sphere radius="0.005"/>
      </geometry>
    </collision>
    <visual name="caster_back_right_visual">
      <geometry>
        <sphere radius="0.005"/>
      </geometry>
      <material name="caster_material">
        <color rgba="0.0 1.0 0.0 1"/>
      </material>
    </visual>
  </link>
  <joint name="caster_back_right_joint" type="fixed">
    <parent link="base_link"/>
    <child link="caster_back_right_link"/>
    <origin rpy="-1.57 0 0" xyz="0.15 -0.05 -0.004"/>
    <axis xyz="0 0 1"/>
    <limit effort="10" lower="-30.14159" upper="30.14159" velocity="100"/>
  </joint>
  <!-- Caster wheels (back left) -->
  <link name="caster_back_left_link">
    <inertial>
      <mass value="0.001"/>
      <inertia ixx="0.00001" ixy="0.000" ixz="0.000" iyy="0.00001" iyz="0.000" izz="0.00001"/>
    </inertial>
    <collision name="caster_back_left_collision">
      <geometry>
        <sphere radius="0.005"/>
      </geometry>
    </collision>
    <visual name="caster_back_left_visual">
      <geometry>
        <sphere radius="0.005"/>
      </geometry>
      <material name="caster_material">
        <color rgba="0.0 1.0 0.0 1"/>
      </material>
    </visual>
  </link>
  <joint name="caster_back_left_joint" type="fixed">
    <parent link="base_link"/>
    <child link="caster_back_left_link"/>
    <origin rpy="-1.57 0 0" xyz="0.15 0.05 -0.004"/>
    <axis xyz="0 0 1"/>
    <limit effort="10" lower="-30.14159" upper="30.14159" velocity="100"/>
  </joint>
  <!-- ros2_control plugin config -->
  <ros2_control name="GazeboSystem" type="system">
    <hardware>
      <plugin>gz_ros2_control/GazeboSimSystem</plugin>
    </hardware>
    <joint name="wheel_left_joint">
      <command_interface name="velocity">
        <!-- これ↓いみない制限やわ -->
        <!-- <param name="min">-10</param>
        <param name="max">10</param> -->
      </command_interface>
      <state_interface name="position"/>
      <state_interface name="velocity"/>
    </joint>
    <joint name="wheel_right_joint">
      <command_interface name="velocity">
        <!-- これ↓いみない制限やわ -->
        <!-- <param name="min">-10</param>
        <param name="max">10</param> -->
      </command_interface>
      <state_interface name="position"/>
      <state_interface name="velocity"/>
    </joint>
  </ros2_control>
  <gazebo>
    <plugin filename="libgz_ros2_control-system.so" name="gz_ros2_control::GazeboSimROS2ControlPlugin">
      <parameters>/home/hao/Ubuntu_3/Private/simulator/ros2_ws/install/gazebo_simulator/share/gazebo_simulator/config/controller_demorobot.yaml</parameters>
    </plugin>
  </gazebo>
</robot>
